2025-06-01 19:34:36,383 ERROR Exception in Tkinter callback
Traceback (most recent call last):
  File "C:\Users\lewka\miniconda3\envs\deep_learning\Lib\tkinter\__init__.py", line 1968, in __call__
    return self.func(*args)
           ^^^^^^^^^^^^^^^^
  File "C:\Users\lewka\miniconda3\envs\deep_learning\Lib\tkinter\__init__.py", line 862, in callit
    func(*args)
  File "c:\Users\lewka\deep_learning\image_labelling\image_labelling\editor.py", line 1684, in <lambda>
    except Exception as e: self.root.after(0, lambda: messagebox.showerror("Error", f"Annotation failed: {str(e)}"))
                                                                                                              ^
NameError: cannot access free variable 'e' where it is not associated with a value in enclosing scope
