2025-05-30 14:52:03,291 ERROR Exception in Tkinter callback
Traceback (most recent call last):
  File "C:\Users\lewka\miniconda3\envs\deep_learning\Lib\tkinter\__init__.py", line 1968, in __call__
    return self.func(*args)
           ^^^^^^^^^^^^^^^^
  File "c:\Users\lewka\deep_learning\image_labelling\image labelling v9.py", line 1504, in on_canvas_resize
    self.display_image()
  File "c:\Users\lewka\deep_learning\image_labelling\image labelling v9.py", line 1086, in display_image
    self.tk_image = ImageTk.PhotoImage(image=Image.fromarray(self.image))
                                             ^^^^^^^^^^^^^^^^^^^^^^^^^^^
  File "C:\Users\lewka\miniconda3\envs\deep_learning\Lib\site-packages\PIL\Image.py", line 3300, in fromarray
    arr = obj.__array_interface__
          ^^^^^^^^^^^^^^^^^^^^^^^
AttributeError: 'NoneType' object has no attribute '__array_interface__'
2025-05-30 15:13:04,441 ERROR Exception in Tkinter callback
Traceback (most recent call last):
  File "C:\Users\lewka\miniconda3\envs\deep_learning\Lib\tkinter\__init__.py", line 1968, in __call__
    return self.func(*args)
           ^^^^^^^^^^^^^^^^
  File "C:\Users\lewka\deep_learning\image_labelling\image labelling v9.py", line 1512, in on_canvas_resize
    self.display_image()
  File "C:\Users\lewka\deep_learning\image_labelling\image labelling v9.py", line 1086, in display_image
    self.tk_image = ImageTk.PhotoImage(image=Image.fromarray(self.image))
                                             ^^^^^^^^^^^^^^^^^^^^^^^^^^^
  File "C:\Users\lewka\miniconda3\envs\deep_learning\Lib\site-packages\PIL\Image.py", line 3300, in fromarray
    arr = obj.__array_interface__
          ^^^^^^^^^^^^^^^^^^^^^^^
AttributeError: 'NoneType' object has no attribute '__array_interface__'
2025-05-30 15:13:25,823 ERROR Exception in Tkinter callback
Traceback (most recent call last):
  File "C:\Users\lewka\miniconda3\envs\deep_learning\Lib\tkinter\__init__.py", line 1968, in __call__
    return self.func(*args)
           ^^^^^^^^^^^^^^^^
  File "c:\Users\lewka\deep_learning\image_labelling\image labelling v9.py", line 1512, in on_canvas_resize
    self.display_image()
  File "c:\Users\lewka\deep_learning\image_labelling\image labelling v9.py", line 1086, in display_image
    self.tk_image = ImageTk.PhotoImage(image=Image.fromarray(self.image))
                                             ^^^^^^^^^^^^^^^^^^^^^^^^^^^
  File "C:\Users\lewka\miniconda3\envs\deep_learning\Lib\site-packages\PIL\Image.py", line 3300, in fromarray
    arr = obj.__array_interface__
          ^^^^^^^^^^^^^^^^^^^^^^^
AttributeError: 'NoneType' object has no attribute '__array_interface__'
2025-05-30 21:27:14,752 ERROR Exception in Tkinter callback
Traceback (most recent call last):
  File "C:\Users\lewka\miniconda3\envs\deep_learning\Lib\tkinter\__init__.py", line 1968, in __call__
    return self.func(*args)
           ^^^^^^^^^^^^^^^^
  File "c:\Users\lewka\deep_learning\image_labelling\image_labelling\editor.py", line 930, in on_image_select
    self.load_image(image_path)
  File "c:\Users\lewka\deep_learning\image_labelling\image_labelling\editor.py", line 1015, in load_image
    self.update_status_labels()
  File "c:\Users\lewka\deep_learning\image_labelling\image_labelling\editor.py", line 676, in update_status_labels
    self.status_labels[display_name].config(text=f"{display_name}: {counts[display_name]}")
  File "C:\Users\lewka\miniconda3\envs\deep_learning\Lib\tkinter\__init__.py", line 1722, in configure
    return self._configure('configure', cnf, kw)
           ^^^^^^^^^^^^^^^^^^^^^^^^^^^^^^^^^^^^^
  File "C:\Users\lewka\miniconda3\envs\deep_learning\Lib\tkinter\__init__.py", line 1712, in _configure
    self.tk.call(_flatten((self._w, cmd)) + self._options(cnf))
KeyboardInterrupt
2025-05-30 21:27:14,937 ERROR Exception in Tkinter callback
Traceback (most recent call last):
  File "C:\Users\lewka\miniconda3\envs\deep_learning\Lib\tkinter\__init__.py", line 1968, in __call__
    return self.func(*args)
           ^^^^^^^^^^^^^^^^
  File "c:\Users\lewka\deep_learning\image_labelling\image_labelling\editor.py", line 930, in on_image_select
    self.load_image(image_path)
  File "c:\Users\lewka\deep_learning\image_labelling\image_labelling\editor.py", line 1015, in load_image
    self.update_status_labels()
  File "c:\Users\lewka\deep_learning\image_labelling\image_labelling\editor.py", line 676, in update_status_labels
    self.status_labels[display_name].config(text=f"{display_name}: {counts[display_name]}")
  File "C:\Users\lewka\miniconda3\envs\deep_learning\Lib\tkinter\__init__.py", line 1722, in configure
    return self._configure('configure', cnf, kw)
           ^^^^^^^^^^^^^^^^^^^^^^^^^^^^^^^^^^^^^
  File "C:\Users\lewka\miniconda3\envs\deep_learning\Lib\tkinter\__init__.py", line 1712, in _configure
    self.tk.call(_flatten((self._w, cmd)) + self._options(cnf))
KeyboardInterrupt

During handling of the above exception, another exception occurred:

Traceback (most recent call last):
  File "C:\Users\lewka\miniconda3\envs\deep_learning\Lib\tkinter\__init__.py", line 1968, in __call__
    return self.func(*args)
           ^^^^^^^^^^^^^^^^
  File "c:\Users\lewka\deep_learning\image_labelling\image_labelling\editor.py", line 930, in on_image_select
    self.load_image(image_path)
  File "c:\Users\lewka\deep_learning\image_labelling\image_labelling\editor.py", line 1006, in load_image
    self.display_annotations()
  File "c:\Users\lewka\deep_learning\image_labelling\image_labelling\editor.py", line 1367, in display_annotations
    widget.destroy()
  File "C:\Users\lewka\miniconda3\envs\deep_learning\Lib\tkinter\__init__.py", line 2668, in destroy
    for c in list(self.children.values()): c.destroy()
                                           ^^^^^^^^^^^
  File "C:\Users\lewka\miniconda3\envs\deep_learning\Lib\tkinter\__init__.py", line 2669, in destroy
    self.tk.call('destroy', self._w)
KeyboardInterrupt
2025-05-30 21:51:19,461 ERROR Exception in Tkinter callback
Traceback (most recent call last):
  File "c:\Users\lewka\deep_learning\image_labelling\image_labelling\project_manager.py", line 144, in _open_selected_project_action
    self.open_editor(project)
  File "c:\Users\lewka\deep_learning\image_labelling\image_labelling\project_manager.py", line 258, in open_editor
    BoundingBoxEditor(editor_root, project, splash=splash)
TypeError: BoundingBoxEditor.__init__() got an unexpected keyword argument 'splash'

During handling of the above exception, another exception occurred:

Traceback (most recent call last):
  File "C:\Users\lewka\miniconda3\envs\deep_learning\Lib\tkinter\__init__.py", line 1968, in __call__
    return self.func(*args)
           ^^^^^^^^^^^^^^^^
  File "c:\Users\lewka\deep_learning\image_labelling\image_labelling\project_manager.py", line 147, in _open_selected_project_action
    self._populate_project_list()
  File "c:\Users\lewka\deep_learning\image_labelling\image_labelling\project_manager.py", line 80, in _populate_project_list
    for item in self.project_tree.get_children():
                ^^^^^^^^^^^^^^^^^^^^^^^^^^^^^^^^
  File "C:\Users\lewka\miniconda3\envs\deep_learning\Lib\tkinter\ttk.py", line 1198, in get_children
    self.tk.call(self._w, "children", item or '') or ())
    ^^^^^^^^^^^^^^^^^^^^^^^^^^^^^^^^^^^^^^^^^^^^^
_tkinter.TclError: invalid command name ".!frame.!panedwindow.!labelframe2.!treeview"
2025-05-30 21:58:54,418 ERROR Exception in Tkinter callback
Traceback (most recent call last):
  File "C:\Users\lewka\miniconda3\envs\deep_learning\Lib\tkinter\__init__.py", line 1968, in __call__
    return self.func(*args)
           ^^^^^^^^^^^^^^^^
  File "c:\Users\lewka\deep_learning\image_labelling\image_labelling\project_manager.py", line 144, in _open_selected_project_action
    self.open_editor(project)
  File "c:\Users\lewka\deep_learning\image_labelling\image_labelling\project_manager.py", line 259, in open_editor
    editor_root.mainloop()
  File "C:\Users\lewka\miniconda3\envs\deep_learning\Lib\tkinter\__init__.py", line 1505, in mainloop
    self.tk.mainloop(n)
KeyboardInterrupt
2025-05-31 09:06:47,688 ERROR Exception in Tkinter callback
Traceback (most recent call last):
  File "C:\Users\lewka\miniconda3\envs\deep_learning\Lib\tkinter\__init__.py", line 1968, in __call__
    return self.func(*args)
           ^^^^^^^^^^^^^^^^
  File "c:\Users\lewka\deep_learning\image_labelling\image_labelling\project_manager.py", line 144, in _open_selected_project_action
    self.open_editor(project)
  File "c:\Users\lewka\deep_learning\image_labelling\image_labelling\project_manager.py", line 259, in open_editor
    editor_root.mainloop()
  File "C:\Users\lewka\miniconda3\envs\deep_learning\Lib\tkinter\__init__.py", line 1505, in mainloop
    self.tk.mainloop(n)
KeyboardInterrupt
2025-05-31 09:07:08,761 ERROR Exception in Tkinter callback
Traceback (most recent call last):
  File "C:\Users\lewka\miniconda3\envs\deep_learning\Lib\tkinter\__init__.py", line 1968, in __call__
    return self.func(*args)
           ^^^^^^^^^^^^^^^^
  File "c:\Users\lewka\deep_learning\image_labelling\image_labelling\editor.py", line 1047, in on_image_select
    self.load_image(image_path)
  File "c:\Users\lewka\deep_learning\image_labelling\image_labelling\editor.py", line 1094, in load_image
    self.display_image()
  File "c:\Users\lewka\deep_learning\image_labelling\image_labelling\editor.py", line 1191, in display_image
    self.tk_image = ImageTk.PhotoImage(image=Image.fromarray(self.image))
                                             ^^^^^^^^^^^^^^^^^^^^^^^^^^^
  File "C:\Users\lewka\miniconda3\envs\deep_learning\Lib\site-packages\PIL\Image.py", line 3338, in fromarray
    return frombuffer(mode, size, obj, "raw", rawmode, 0, 1)
           ^^^^^^^^^^^^^^^^^^^^^^^^^^^^^^^^^^^^^^^^^^^^^^^^^
  File "C:\Users\lewka\miniconda3\envs\deep_learning\Lib\site-packages\PIL\Image.py", line 3240, in frombuffer
    return frombytes(mode, size, data, decoder_name, args)
           ^^^^^^^^^^^^^^^^^^^^^^^^^^^^^^^^^^^^^^^^^^^^^^^
  File "C:\Users\lewka\miniconda3\envs\deep_learning\Lib\site-packages\PIL\Image.py", line 3177, in frombytes
    im.frombytes(data, decoder_name, decoder_args)
  File "C:\Users\lewka\miniconda3\envs\deep_learning\Lib\site-packages\PIL\Image.py", line 873, in frombytes
    s = d.decode(data)
        ^^^^^^^^^^^^^^
KeyboardInterrupt
2025-05-31 09:07:11,225 ERROR Exception in Tkinter callback
Traceback (most recent call last):
  File "C:\Users\lewka\miniconda3\envs\deep_learning\Lib\tkinter\__init__.py", line 1968, in __call__
    return self.func(*args)
           ^^^^^^^^^^^^^^^^
  File "c:\Users\lewka\deep_learning\image_labelling\image_labelling\editor.py", line 1047, in on_image_select
    self.load_image(image_path)
  File "c:\Users\lewka\deep_learning\image_labelling\image_labelling\editor.py", line 1094, in load_image
    self.display_image()
  File "c:\Users\lewka\deep_learning\image_labelling\image_labelling\editor.py", line 1191, in display_image
    self.tk_image = ImageTk.PhotoImage(image=Image.fromarray(self.image))
                                             ^^^^^^^^^^^^^^^^^^^^^^^^^^^
  File "C:\Users\lewka\miniconda3\envs\deep_learning\Lib\site-packages\PIL\Image.py", line 3338, in fromarray
    return frombuffer(mode, size, obj, "raw", rawmode, 0, 1)
           ^^^^^^^^^^^^^^^^^^^^^^^^^^^^^^^^^^^^^^^^^^^^^^^^^
  File "C:\Users\lewka\miniconda3\envs\deep_learning\Lib\site-packages\PIL\Image.py", line 3240, in frombuffer
    return frombytes(mode, size, data, decoder_name, args)
           ^^^^^^^^^^^^^^^^^^^^^^^^^^^^^^^^^^^^^^^^^^^^^^^
  File "C:\Users\lewka\miniconda3\envs\deep_learning\Lib\site-packages\PIL\Image.py", line 3177, in frombytes
    im.frombytes(data, decoder_name, decoder_args)
  File "C:\Users\lewka\miniconda3\envs\deep_learning\Lib\site-packages\PIL\Image.py", line 873, in frombytes
    s = d.decode(data)
        ^^^^^^^^^^^^^^
KeyboardInterrupt

During handling of the above exception, another exception occurred:

Traceback (most recent call last):
  File "C:\Users\lewka\miniconda3\envs\deep_learning\Lib\tkinter\__init__.py", line 1968, in __call__
    return self.func(*args)
           ^^^^^^^^^^^^^^^^
  File "c:\Users\lewka\deep_learning\image_labelling\image_labelling\editor.py", line 1047, in on_image_select
    self.load_image(image_path)
  File "c:\Users\lewka\deep_learning\image_labelling\image_labelling\editor.py", line 1094, in load_image
    self.display_image()
  File "c:\Users\lewka\deep_learning\image_labelling\image_labelling\editor.py", line 1192, in display_image
    self.canvas.create_image(0, 0, anchor=tk.NW, image=self.tk_image)
  File "C:\Users\lewka\miniconda3\envs\deep_learning\Lib\tkinter\__init__.py", line 2877, in create_image
    return self._create('image', args, kw)
           ^^^^^^^^^^^^^^^^^^^^^^^^^^^^^^^
  File "C:\Users\lewka\miniconda3\envs\deep_learning\Lib\tkinter\__init__.py", line 2863, in _create
    return self.tk.getint(self.tk.call(
                          ^^^^^^^^^^^^^
KeyboardInterrupt
2025-05-31 09:07:15,733 ERROR Exception in Tkinter callback
Traceback (most recent call last):
  File "C:\Users\lewka\miniconda3\envs\deep_learning\Lib\tkinter\__init__.py", line 1968, in __call__
    return self.func(*args)
           ^^^^^^^^^^^^^^^^
  File "c:\Users\lewka\deep_learning\image_labelling\image_labelling\project_manager.py", line 144, in _open_selected_project_action
    self.open_editor(project)
  File "c:\Users\lewka\deep_learning\image_labelling\image_labelling\project_manager.py", line 259, in open_editor
    editor_root.mainloop()
  File "C:\Users\lewka\miniconda3\envs\deep_learning\Lib\tkinter\__init__.py", line 1505, in mainloop
    self.tk.mainloop(n)
KeyboardInterrupt
2025-05-31 09:07:43,016 ERROR Exception in Tkinter callback
Traceback (most recent call last):
  File "C:\Users\lewka\miniconda3\envs\deep_learning\Lib\tkinter\__init__.py", line 1968, in __call__
    return self.func(*args)
           ^^^^^^^^^^^^^^^^
  File "c:\Users\lewka\deep_learning\image_labelling\image_labelling\editor.py", line 1047, in on_image_select
    self.load_image(image_path)
  File "c:\Users\lewka\deep_learning\image_labelling\image_labelling\editor.py", line 1094, in load_image
    self.display_image()
  File "c:\Users\lewka\deep_learning\image_labelling\image_labelling\editor.py", line 1192, in display_image
    self.canvas.create_image(0, 0, anchor=tk.NW, image=self.tk_image)
  File "C:\Users\lewka\miniconda3\envs\deep_learning\Lib\tkinter\__init__.py", line 2877, in create_image
    return self._create('image', args, kw)
           ^^^^^^^^^^^^^^^^^^^^^^^^^^^^^^^
  File "C:\Users\lewka\miniconda3\envs\deep_learning\Lib\tkinter\__init__.py", line 2863, in _create
    return self.tk.getint(self.tk.call(
                          ^^^^^^^^^^^^^
KeyboardInterrupt
2025-05-31 09:07:45,924 ERROR Exception in Tkinter callback
Traceback (most recent call last):
  File "C:\Users\lewka\miniconda3\envs\deep_learning\Lib\tkinter\__init__.py", line 1968, in __call__
    return self.func(*args)
           ^^^^^^^^^^^^^^^^
  File "c:\Users\lewka\deep_learning\image_labelling\image_labelling\editor.py", line 1047, in on_image_select
    self.load_image(image_path)
  File "c:\Users\lewka\deep_learning\image_labelling\image_labelling\editor.py", line 1094, in load_image
    self.display_image()
  File "c:\Users\lewka\deep_learning\image_labelling\image_labelling\editor.py", line 1192, in display_image
    self.canvas.create_image(0, 0, anchor=tk.NW, image=self.tk_image)
  File "C:\Users\lewka\miniconda3\envs\deep_learning\Lib\tkinter\__init__.py", line 2877, in create_image
    return self._create('image', args, kw)
           ^^^^^^^^^^^^^^^^^^^^^^^^^^^^^^^
  File "C:\Users\lewka\miniconda3\envs\deep_learning\Lib\tkinter\__init__.py", line 2863, in _create
    return self.tk.getint(self.tk.call(
                          ^^^^^^^^^^^^^
KeyboardInterrupt

During handling of the above exception, another exception occurred:

Traceback (most recent call last):
  File "C:\Users\lewka\miniconda3\envs\deep_learning\Lib\tkinter\__init__.py", line 1968, in __call__
    return self.func(*args)
           ^^^^^^^^^^^^^^^^
  File "c:\Users\lewka\deep_learning\image_labelling\image_labelling\editor.py", line 1047, in on_image_select
    self.load_image(image_path)
  File "c:\Users\lewka\deep_learning\image_labelling\image_labelling\editor.py", line 1094, in load_image
    self.display_image()
  File "c:\Users\lewka\deep_learning\image_labelling\image_labelling\editor.py", line 1192, in display_image
    self.canvas.create_image(0, 0, anchor=tk.NW, image=self.tk_image)
  File "C:\Users\lewka\miniconda3\envs\deep_learning\Lib\tkinter\__init__.py", line 2877, in create_image
    return self._create('image', args, kw)
           ^^^^^^^^^^^^^^^^^^^^^^^^^^^^^^^
  File "C:\Users\lewka\miniconda3\envs\deep_learning\Lib\tkinter\__init__.py", line 2863, in _create
    return self.tk.getint(self.tk.call(
                          ^^^^^^^^^^^^^
KeyboardInterrupt
2025-05-31 09:08:22,976 ERROR Exception in Tkinter callback
Traceback (most recent call last):
  File "C:\Users\lewka\miniconda3\envs\deep_learning\Lib\tkinter\__init__.py", line 1968, in __call__
    return self.func(*args)
           ^^^^^^^^^^^^^^^^
  File "c:\Users\lewka\deep_learning\image_labelling\image_labelling\project_manager.py", line 144, in _open_selected_project_action
    self.root.after_idle(self._destroy_root_and_open_editor, project)
    ^^^^^^^^^^^^^^^^^^^^^^^^^
  File "c:\Users\lewka\deep_learning\image_labelling\image_labelling\project_manager.py", line 259, in open_editor
    except Exception as e:
  File "C:\Users\lewka\miniconda3\envs\deep_learning\Lib\tkinter\__init__.py", line 1505, in mainloop
    self.tk.mainloop(n)
KeyboardInterrupt
2025-05-31 09:08:54,288 ERROR Exception in Tkinter callback
Traceback (most recent call last):
  File "C:\Users\lewka\miniconda3\envs\deep_learning\Lib\tkinter\__init__.py", line 1968, in __call__
    return self.func(*args)
           ^^^^^^^^^^^^^^^^
  File "c:\Users\lewka\deep_learning\image_labelling\image_labelling\editor.py", line 1047, in on_image_select
    self.load_image(image_path)
  File "c:\Users\lewka\deep_learning\image_labelling\image_labelling\editor.py", line 1094, in load_image
    self.display_image()
  File "c:\Users\lewka\deep_learning\image_labelling\image_labelling\editor.py", line 1192, in display_image
    self.canvas.create_image(0, 0, anchor=tk.NW, image=self.tk_image)
  File "C:\Users\lewka\miniconda3\envs\deep_learning\Lib\tkinter\__init__.py", line 2877, in create_image
    return self._create('image', args, kw)
           ^^^^^^^^^^^^^^^^^^^^^^^^^^^^^^^
  File "C:\Users\lewka\miniconda3\envs\deep_learning\Lib\tkinter\__init__.py", line 2863, in _create
    return self.tk.getint(self.tk.call(
                          ^^^^^^^^^^^^^
KeyboardInterrupt
2025-05-31 09:08:54,516 ERROR Exception in Tkinter callback
Traceback (most recent call last):
  File "C:\Users\lewka\miniconda3\envs\deep_learning\Lib\tkinter\__init__.py", line 1968, in __call__
    return self.func(*args)
           ^^^^^^^^^^^^^^^^
  File "c:\Users\lewka\deep_learning\image_labelling\image_labelling\editor.py", line 1047, in on_image_select
    self.load_image(image_path)
  File "c:\Users\lewka\deep_learning\image_labelling\image_labelling\editor.py", line 1094, in load_image
    self.display_image()
  File "c:\Users\lewka\deep_learning\image_labelling\image_labelling\editor.py", line 1192, in display_image
    self.canvas.create_image(0, 0, anchor=tk.NW, image=self.tk_image)
  File "C:\Users\lewka\miniconda3\envs\deep_learning\Lib\tkinter\__init__.py", line 2877, in create_image
    return self._create('image', args, kw)
           ^^^^^^^^^^^^^^^^^^^^^^^^^^^^^^^
  File "C:\Users\lewka\miniconda3\envs\deep_learning\Lib\tkinter\__init__.py", line 2863, in _create
    return self.tk.getint(self.tk.call(
                          ^^^^^^^^^^^^^
KeyboardInterrupt

During handling of the above exception, another exception occurred:

Traceback (most recent call last):
  File "C:\Users\lewka\miniconda3\envs\deep_learning\Lib\tkinter\__init__.py", line 1968, in __call__
    return self.func(*args)
           ^^^^^^^^^^^^^^^^
  File "c:\Users\lewka\deep_learning\image_labelling\image_labelling\editor.py", line 1047, in on_image_select
    self.load_image(image_path)
  File "c:\Users\lewka\deep_learning\image_labelling\image_labelling\editor.py", line 1094, in load_image
    self.display_image()
  File "c:\Users\lewka\deep_learning\image_labelling\image_labelling\editor.py", line 1173, in display_image
    def display_image(self):
    
KeyboardInterrupt
2025-05-31 09:09:23,454 ERROR Exception in Tkinter callback
Traceback (most recent call last):
  File "C:\Users\lewka\miniconda3\envs\deep_learning\Lib\tkinter\__init__.py", line 1968, in __call__
    return self.func(*args)
           ^^^^^^^^^^^^^^^^
  File "C:\Users\lewka\miniconda3\envs\deep_learning\Lib\tkinter\__init__.py", line 862, in callit
    func(*args)
  File "c:\Users\lewka\deep_learning\image_labelling\image_labelling\project_manager.py", line 166, in _destroy_root_and_open_editor
    messagebox.showerror("Error Opening Project", f"Could not load project \'{project_file_iid}\':\\n{e}")
    ^^^^^^^^^^^^^^^^^^^^^^^^^
  File "c:\Users\lewka\deep_learning\image_labelling\image_labelling\project_manager.py", line 278, in open_editor
    """
  File "C:\Users\lewka\miniconda3\envs\deep_learning\Lib\tkinter\__init__.py", line 1505, in mainloop
    self.tk.mainloop(n)
KeyboardInterrupt
2025-05-31 09:09:34,607 ERROR Error opening project 'authentic logo.json'
Traceback (most recent call last):
  File "c:\Users\lewka\deep_learning\image_labelling\image_labelling\editor.py", line 297, in __init__
    self.load_image(last_image_full_path)                   # Load the image
    ^^^^^^^^^^^^^^^^^^^^^^^^^^^^^^^^^^^^^
  File "c:\Users\lewka\deep_learning\image_labelling\image_labelling\editor.py", line 1094, in load_image
    self.display_image()
  File "c:\Users\lewka\deep_learning\image_labelling\image_labelling\editor.py", line 1192, in display_image
    self.canvas.create_image(0, 0, anchor=tk.NW, image=self.tk_image)
  File "C:\Users\lewka\miniconda3\envs\deep_learning\Lib\tkinter\__init__.py", line 2877, in create_image
    return self._create('image', args, kw)
           ^^^^^^^^^^^^^^^^^^^^^^^^^^^^^^^
  File "C:\Users\lewka\miniconda3\envs\deep_learning\Lib\tkinter\__init__.py", line 2863, in _create
    return self.tk.getint(self.tk.call(
                          ^^^^^^^^^^^^^
_tkinter.TclError: image "pyimage1" doesn't exist

During handling of the above exception, another exception occurred:

Traceback (most recent call last):
  File "c:\Users\lewka\deep_learning\image_labelling\image_labelling\project_manager.py", line 149, in _open_selected_project_action
    self.open_editor(project)
  File "c:\Users\lewka\deep_learning\image_labelling\image_labelling\project_manager.py", line 283, in open_editor
    BoundingBoxEditor(editor_root, project) # Removed splash=splash
    ^^^^^^^^^^^^^^^^^^^^^^^^^^^^^^^^^^^^^^^
  File "c:\Users\lewka\deep_learning\image_labelling\image_labelling\editor.py", line 303, in __init__
    self.load_image(os.path.join(self.folder_path, self.image_files[0]))
  File "c:\Users\lewka\deep_learning\image_labelling\image_labelling\editor.py", line 1094, in load_image
    self.display_image()
  File "c:\Users\lewka\deep_learning\image_labelling\image_labelling\editor.py", line 1192, in display_image
    self.canvas.create_image(0, 0, anchor=tk.NW, image=self.tk_image)
  File "C:\Users\lewka\miniconda3\envs\deep_learning\Lib\tkinter\__init__.py", line 2877, in create_image
    return self._create('image', args, kw)
           ^^^^^^^^^^^^^^^^^^^^^^^^^^^^^^^
  File "C:\Users\lewka\miniconda3\envs\deep_learning\Lib\tkinter\__init__.py", line 2863, in _create
    return self.tk.getint(self.tk.call(
                          ^^^^^^^^^^^^^
_tkinter.TclError: image "pyimage2" doesn't exist
2025-05-31 09:09:34,616 ERROR Exception in Tkinter callback
Traceback (most recent call last):
  File "c:\Users\lewka\deep_learning\image_labelling\image_labelling\editor.py", line 297, in __init__
    self.load_image(last_image_full_path)                   # Load the image
    ^^^^^^^^^^^^^^^^^^^^^^^^^^^^^^^^^^^^^
  File "c:\Users\lewka\deep_learning\image_labelling\image_labelling\editor.py", line 1094, in load_image
    self.display_image()
  File "c:\Users\lewka\deep_learning\image_labelling\image_labelling\editor.py", line 1192, in display_image
    self.canvas.create_image(0, 0, anchor=tk.NW, image=self.tk_image)
  File "C:\Users\lewka\miniconda3\envs\deep_learning\Lib\tkinter\__init__.py", line 2877, in create_image
    return self._create('image', args, kw)
           ^^^^^^^^^^^^^^^^^^^^^^^^^^^^^^^
  File "C:\Users\lewka\miniconda3\envs\deep_learning\Lib\tkinter\__init__.py", line 2863, in _create
    return self.tk.getint(self.tk.call(
                          ^^^^^^^^^^^^^
_tkinter.TclError: image "pyimage1" doesn't exist

During handling of the above exception, another exception occurred:

Traceback (most recent call last):
  File "c:\Users\lewka\deep_learning\image_labelling\image_labelling\project_manager.py", line 149, in _open_selected_project_action
    self.open_editor(project)
  File "c:\Users\lewka\deep_learning\image_labelling\image_labelling\project_manager.py", line 283, in open_editor
    BoundingBoxEditor(editor_root, project) # Removed splash=splash
    ^^^^^^^^^^^^^^^^^^^^^^^^^^^^^^^^^^^^^^^
  File "c:\Users\lewka\deep_learning\image_labelling\image_labelling\editor.py", line 303, in __init__
    self.load_image(os.path.join(self.folder_path, self.image_files[0]))
  File "c:\Users\lewka\deep_learning\image_labelling\image_labelling\editor.py", line 1094, in load_image
    self.display_image()
  File "c:\Users\lewka\deep_learning\image_labelling\image_labelling\editor.py", line 1192, in display_image
    self.canvas.create_image(0, 0, anchor=tk.NW, image=self.tk_image)
  File "C:\Users\lewka\miniconda3\envs\deep_learning\Lib\tkinter\__init__.py", line 2877, in create_image
    return self._create('image', args, kw)
           ^^^^^^^^^^^^^^^^^^^^^^^^^^^^^^^
  File "C:\Users\lewka\miniconda3\envs\deep_learning\Lib\tkinter\__init__.py", line 2863, in _create
    return self.tk.getint(self.tk.call(
                          ^^^^^^^^^^^^^
_tkinter.TclError: image "pyimage2" doesn't exist

During handling of the above exception, another exception occurred:

Traceback (most recent call last):
  File "C:\Users\lewka\miniconda3\envs\deep_learning\Lib\tkinter\__init__.py", line 1968, in __call__
    return self.func(*args)
           ^^^^^^^^^^^^^^^^
  File "c:\Users\lewka\deep_learning\image_labelling\image_labelling\editor.py", line 1047, in on_image_select
    self.load_image(image_path)
  File "c:\Users\lewka\deep_learning\image_labelling\image_labelling\editor.py", line 1094, in load_image
    self.display_image()
  File "c:\Users\lewka\deep_learning\image_labelling\image_labelling\editor.py", line 1192, in display_image
    self.canvas.create_image(0, 0, anchor=tk.NW, image=self.tk_image)
  File "C:\Users\lewka\miniconda3\envs\deep_learning\Lib\tkinter\__init__.py", line 2877, in create_image
    return self._create('image', args, kw)
           ^^^^^^^^^^^^^^^^^^^^^^^^^^^^^^^
  File "C:\Users\lewka\miniconda3\envs\deep_learning\Lib\tkinter\__init__.py", line 2863, in _create
    return self.tk.getint(self.tk.call(
                          ^^^^^^^^^^^^^
_tkinter.TclError: image "pyimage3" doesn't exist
2025-05-31 09:09:34,705 ERROR Exception in Tkinter callback
Traceback (most recent call last):
  File "c:\Users\lewka\deep_learning\image_labelling\image_labelling\editor.py", line 297, in __init__
    self.load_image(last_image_full_path)                   # Load the image
    ^^^^^^^^^^^^^^^^^^^^^^^^^^^^^^^^^^^^^
  File "c:\Users\lewka\deep_learning\image_labelling\image_labelling\editor.py", line 1094, in load_image
    self.display_image()
  File "c:\Users\lewka\deep_learning\image_labelling\image_labelling\editor.py", line 1192, in display_image
    self.canvas.create_image(0, 0, anchor=tk.NW, image=self.tk_image)
  File "C:\Users\lewka\miniconda3\envs\deep_learning\Lib\tkinter\__init__.py", line 2877, in create_image
    return self._create('image', args, kw)
           ^^^^^^^^^^^^^^^^^^^^^^^^^^^^^^^
  File "C:\Users\lewka\miniconda3\envs\deep_learning\Lib\tkinter\__init__.py", line 2863, in _create
    return self.tk.getint(self.tk.call(
                          ^^^^^^^^^^^^^
_tkinter.TclError: image "pyimage1" doesn't exist

During handling of the above exception, another exception occurred:

Traceback (most recent call last):
  File "c:\Users\lewka\deep_learning\image_labelling\image_labelling\project_manager.py", line 149, in _open_selected_project_action
    self.open_editor(project)
  File "c:\Users\lewka\deep_learning\image_labelling\image_labelling\project_manager.py", line 283, in open_editor
    BoundingBoxEditor(editor_root, project) # Removed splash=splash
    ^^^^^^^^^^^^^^^^^^^^^^^^^^^^^^^^^^^^^^^
  File "c:\Users\lewka\deep_learning\image_labelling\image_labelling\editor.py", line 303, in __init__
    self.load_image(os.path.join(self.folder_path, self.image_files[0]))
  File "c:\Users\lewka\deep_learning\image_labelling\image_labelling\editor.py", line 1094, in load_image
    self.display_image()
  File "c:\Users\lewka\deep_learning\image_labelling\image_labelling\editor.py", line 1192, in display_image
    self.canvas.create_image(0, 0, anchor=tk.NW, image=self.tk_image)
  File "C:\Users\lewka\miniconda3\envs\deep_learning\Lib\tkinter\__init__.py", line 2877, in create_image
    return self._create('image', args, kw)
           ^^^^^^^^^^^^^^^^^^^^^^^^^^^^^^^
  File "C:\Users\lewka\miniconda3\envs\deep_learning\Lib\tkinter\__init__.py", line 2863, in _create
    return self.tk.getint(self.tk.call(
                          ^^^^^^^^^^^^^
_tkinter.TclError: image "pyimage2" doesn't exist

During handling of the above exception, another exception occurred:

Traceback (most recent call last):
  File "C:\Users\lewka\miniconda3\envs\deep_learning\Lib\tkinter\__init__.py", line 1968, in __call__
    return self.func(*args)
           ^^^^^^^^^^^^^^^^
  File "c:\Users\lewka\deep_learning\image_labelling\image_labelling\editor.py", line 1047, in on_image_select
    self.load_image(image_path)
  File "c:\Users\lewka\deep_learning\image_labelling\image_labelling\editor.py", line 1094, in load_image
    self.display_image()
  File "c:\Users\lewka\deep_learning\image_labelling\image_labelling\editor.py", line 1192, in display_image
    self.canvas.create_image(0, 0, anchor=tk.NW, image=self.tk_image)
  File "C:\Users\lewka\miniconda3\envs\deep_learning\Lib\tkinter\__init__.py", line 2877, in create_image
    return self._create('image', args, kw)
           ^^^^^^^^^^^^^^^^^^^^^^^^^^^^^^^
  File "C:\Users\lewka\miniconda3\envs\deep_learning\Lib\tkinter\__init__.py", line 2863, in _create
    return self.tk.getint(self.tk.call(
                          ^^^^^^^^^^^^^
_tkinter.TclError: image "pyimage3" doesn't exist

During handling of the above exception, another exception occurred:

Traceback (most recent call last):
  File "C:\Users\lewka\miniconda3\envs\deep_learning\Lib\tkinter\__init__.py", line 1968, in __call__
    return self.func(*args)
           ^^^^^^^^^^^^^^^^
  File "c:\Users\lewka\deep_learning\image_labelling\image_labelling\editor.py", line 1631, in on_canvas_resize
    self.display_image()
  File "c:\Users\lewka\deep_learning\image_labelling\image_labelling\editor.py", line 1192, in display_image
    self.canvas.create_image(0, 0, anchor=tk.NW, image=self.tk_image)
  File "C:\Users\lewka\miniconda3\envs\deep_learning\Lib\tkinter\__init__.py", line 2877, in create_image
    return self._create('image', args, kw)
           ^^^^^^^^^^^^^^^^^^^^^^^^^^^^^^^
  File "C:\Users\lewka\miniconda3\envs\deep_learning\Lib\tkinter\__init__.py", line 2863, in _create
    return self.tk.getint(self.tk.call(
                          ^^^^^^^^^^^^^
_tkinter.TclError: image "pyimage4" doesn't exist
2025-05-31 09:09:49,432 ERROR Exception in Tkinter callback
Traceback (most recent call last):
  File "c:\Users\lewka\deep_learning\image_labelling\image_labelling\editor.py", line 297, in __init__
    self.load_image(last_image_full_path)                   # Load the image
    ^^^^^^^^^^^^^^^^^^^^^^^^^^^^^^^^^^^^^
  File "c:\Users\lewka\deep_learning\image_labelling\image_labelling\editor.py", line 1094, in load_image
    self.display_image()
  File "c:\Users\lewka\deep_learning\image_labelling\image_labelling\editor.py", line 1192, in display_image
    self.canvas.create_image(0, 0, anchor=tk.NW, image=self.tk_image)
  File "C:\Users\lewka\miniconda3\envs\deep_learning\Lib\tkinter\__init__.py", line 2877, in create_image
    return self._create('image', args, kw)
           ^^^^^^^^^^^^^^^^^^^^^^^^^^^^^^^
  File "C:\Users\lewka\miniconda3\envs\deep_learning\Lib\tkinter\__init__.py", line 2863, in _create
    return self.tk.getint(self.tk.call(
                          ^^^^^^^^^^^^^
_tkinter.TclError: image "pyimage1" doesn't exist

During handling of the above exception, another exception occurred:

Traceback (most recent call last):
  File "c:\Users\lewka\deep_learning\image_labelling\image_labelling\project_manager.py", line 149, in _open_selected_project_action
    self.open_editor(project)
  File "c:\Users\lewka\deep_learning\image_labelling\image_labelling\project_manager.py", line 283, in open_editor
    BoundingBoxEditor(editor_root, project) # Removed splash=splash
    ^^^^^^^^^^^^^^^^^^^^^^^^^^^^^^^^^^^^^^^
  File "c:\Users\lewka\deep_learning\image_labelling\image_labelling\editor.py", line 303, in __init__
    self.load_image(os.path.join(self.folder_path, self.image_files[0]))
  File "c:\Users\lewka\deep_learning\image_labelling\image_labelling\editor.py", line 1094, in load_image
    self.display_image()
  File "c:\Users\lewka\deep_learning\image_labelling\image_labelling\editor.py", line 1192, in display_image
    self.canvas.create_image(0, 0, anchor=tk.NW, image=self.tk_image)
  File "C:\Users\lewka\miniconda3\envs\deep_learning\Lib\tkinter\__init__.py", line 2877, in create_image
    return self._create('image', args, kw)
           ^^^^^^^^^^^^^^^^^^^^^^^^^^^^^^^
  File "C:\Users\lewka\miniconda3\envs\deep_learning\Lib\tkinter\__init__.py", line 2863, in _create
    return self.tk.getint(self.tk.call(
                          ^^^^^^^^^^^^^
_tkinter.TclError: image "pyimage2" doesn't exist

During handling of the above exception, another exception occurred:

Traceback (most recent call last):
  File "C:\Users\lewka\miniconda3\envs\deep_learning\Lib\tkinter\__init__.py", line 1968, in __call__
    return self.func(*args)
           ^^^^^^^^^^^^^^^^
  File "c:\Users\lewka\deep_learning\image_labelling\image_labelling\editor.py", line 1047, in on_image_select
    self.load_image(image_path)
  File "c:\Users\lewka\deep_learning\image_labelling\image_labelling\editor.py", line 1094, in load_image
    self.display_image()
  File "c:\Users\lewka\deep_learning\image_labelling\image_labelling\editor.py", line 1192, in display_image
    self.canvas.create_image(0, 0, anchor=tk.NW, image=self.tk_image)
  File "C:\Users\lewka\miniconda3\envs\deep_learning\Lib\tkinter\__init__.py", line 2877, in create_image
    return self._create('image', args, kw)
           ^^^^^^^^^^^^^^^^^^^^^^^^^^^^^^^
  File "C:\Users\lewka\miniconda3\envs\deep_learning\Lib\tkinter\__init__.py", line 2863, in _create
    return self.tk.getint(self.tk.call(
                          ^^^^^^^^^^^^^
_tkinter.TclError: image "pyimage3" doesn't exist

During handling of the above exception, another exception occurred:

Traceback (most recent call last):
  File "C:\Users\lewka\miniconda3\envs\deep_learning\Lib\tkinter\__init__.py", line 1968, in __call__
    return self.func(*args)
           ^^^^^^^^^^^^^^^^
  File "c:\Users\lewka\deep_learning\image_labelling\image_labelling\editor.py", line 1631, in on_canvas_resize
    self.display_image()
  File "c:\Users\lewka\deep_learning\image_labelling\image_labelling\editor.py", line 1192, in display_image
    self.canvas.create_image(0, 0, anchor=tk.NW, image=self.tk_image)
  File "C:\Users\lewka\miniconda3\envs\deep_learning\Lib\tkinter\__init__.py", line 2877, in create_image
    return self._create('image', args, kw)
           ^^^^^^^^^^^^^^^^^^^^^^^^^^^^^^^
  File "C:\Users\lewka\miniconda3\envs\deep_learning\Lib\tkinter\__init__.py", line 2863, in _create
    return self.tk.getint(self.tk.call(
                          ^^^^^^^^^^^^^
_tkinter.TclError: image "pyimage4" doesn't exist

During handling of the above exception, another exception occurred:

Traceback (most recent call last):
  File "C:\Users\lewka\miniconda3\envs\deep_learning\Lib\tkinter\__init__.py", line 1968, in __call__
    return self.func(*args)
           ^^^^^^^^^^^^^^^^
  File "c:\Users\lewka\deep_learning\image_labelling\image_labelling\editor.py", line 1047, in on_image_select
    self.load_image(image_path)
  File "c:\Users\lewka\deep_learning\image_labelling\image_labelling\editor.py", line 1094, in load_image
    self.display_image()
  File "c:\Users\lewka\deep_learning\image_labelling\image_labelling\editor.py", line 1192, in display_image
    self.canvas.create_image(0, 0, anchor=tk.NW, image=self.tk_image)
  File "C:\Users\lewka\miniconda3\envs\deep_learning\Lib\tkinter\__init__.py", line 2877, in create_image
    return self._create('image', args, kw)
           ^^^^^^^^^^^^^^^^^^^^^^^^^^^^^^^
  File "C:\Users\lewka\miniconda3\envs\deep_learning\Lib\tkinter\__init__.py", line 2863, in _create
    return self.tk.getint(self.tk.call(
                          ^^^^^^^^^^^^^
_tkinter.TclError: image "pyimage5" doesn't exist
2025-05-31 09:17:22,511 ERROR Error opening project 'authentic logo.json'
Traceback (most recent call last):
  File "c:\Users\lewka\deep_learning\image_labelling\image_labelling\editor.py", line 297, in __init__
    self.load_image(last_image_full_path)                   # Load the image
    ^^^^^^^^^^^^^^^^^^^^^^^^^^^^^^^^^^^^^
  File "c:\Users\lewka\deep_learning\image_labelling\image_labelling\editor.py", line 1094, in load_image
    self.display_image()
  File "c:\Users\lewka\deep_learning\image_labelling\image_labelling\editor.py", line 1192, in display_image
    self.canvas.create_image(0, 0, anchor=tk.NW, image=self.tk_image)
  File "C:\Users\lewka\miniconda3\envs\deep_learning\Lib\tkinter\__init__.py", line 2877, in create_image
    return self._create('image', args, kw)
           ^^^^^^^^^^^^^^^^^^^^^^^^^^^^^^^
  File "C:\Users\lewka\miniconda3\envs\deep_learning\Lib\tkinter\__init__.py", line 2863, in _create
    return self.tk.getint(self.tk.call(
                          ^^^^^^^^^^^^^
_tkinter.TclError: image "pyimage1" doesn't exist

During handling of the above exception, another exception occurred:

Traceback (most recent call last):
  File "c:\Users\lewka\deep_learning\image_labelling\image_labelling\project_manager.py", line 149, in _open_selected_project_action
    self.open_editor(project)
  File "c:\Users\lewka\deep_learning\image_labelling\image_labelling\project_manager.py", line 283, in open_editor
    BoundingBoxEditor(editor_root, project) # Removed splash=splash
    ^^^^^^^^^^^^^^^^^^^^^^^^^^^^^^^^^^^^^^^
  File "c:\Users\lewka\deep_learning\image_labelling\image_labelling\editor.py", line 303, in __init__
    self.load_image(os.path.join(self.folder_path, self.image_files[0]))
  File "c:\Users\lewka\deep_learning\image_labelling\image_labelling\editor.py", line 1094, in load_image
    self.display_image()
  File "c:\Users\lewka\deep_learning\image_labelling\image_labelling\editor.py", line 1192, in display_image
    self.canvas.create_image(0, 0, anchor=tk.NW, image=self.tk_image)
  File "C:\Users\lewka\miniconda3\envs\deep_learning\Lib\tkinter\__init__.py", line 2877, in create_image
    return self._create('image', args, kw)
           ^^^^^^^^^^^^^^^^^^^^^^^^^^^^^^^
  File "C:\Users\lewka\miniconda3\envs\deep_learning\Lib\tkinter\__init__.py", line 2863, in _create
    return self.tk.getint(self.tk.call(
                          ^^^^^^^^^^^^^
_tkinter.TclError: image "pyimage2" doesn't exist
2025-05-31 09:17:22,520 ERROR Exception in Tkinter callback
Traceback (most recent call last):
  File "c:\Users\lewka\deep_learning\image_labelling\image_labelling\editor.py", line 297, in __init__
    self.load_image(last_image_full_path)                   # Load the image
    ^^^^^^^^^^^^^^^^^^^^^^^^^^^^^^^^^^^^^
  File "c:\Users\lewka\deep_learning\image_labelling\image_labelling\editor.py", line 1094, in load_image
    self.display_image()
  File "c:\Users\lewka\deep_learning\image_labelling\image_labelling\editor.py", line 1192, in display_image
    self.canvas.create_image(0, 0, anchor=tk.NW, image=self.tk_image)
  File "C:\Users\lewka\miniconda3\envs\deep_learning\Lib\tkinter\__init__.py", line 2877, in create_image
    return self._create('image', args, kw)
           ^^^^^^^^^^^^^^^^^^^^^^^^^^^^^^^
  File "C:\Users\lewka\miniconda3\envs\deep_learning\Lib\tkinter\__init__.py", line 2863, in _create
    return self.tk.getint(self.tk.call(
                          ^^^^^^^^^^^^^
_tkinter.TclError: image "pyimage1" doesn't exist

During handling of the above exception, another exception occurred:

Traceback (most recent call last):
  File "c:\Users\lewka\deep_learning\image_labelling\image_labelling\project_manager.py", line 149, in _open_selected_project_action
    self.open_editor(project)
  File "c:\Users\lewka\deep_learning\image_labelling\image_labelling\project_manager.py", line 283, in open_editor
    BoundingBoxEditor(editor_root, project) # Removed splash=splash
    ^^^^^^^^^^^^^^^^^^^^^^^^^^^^^^^^^^^^^^^
  File "c:\Users\lewka\deep_learning\image_labelling\image_labelling\editor.py", line 303, in __init__
    self.load_image(os.path.join(self.folder_path, self.image_files[0]))
  File "c:\Users\lewka\deep_learning\image_labelling\image_labelling\editor.py", line 1094, in load_image
    self.display_image()
  File "c:\Users\lewka\deep_learning\image_labelling\image_labelling\editor.py", line 1192, in display_image
    self.canvas.create_image(0, 0, anchor=tk.NW, image=self.tk_image)
  File "C:\Users\lewka\miniconda3\envs\deep_learning\Lib\tkinter\__init__.py", line 2877, in create_image
    return self._create('image', args, kw)
           ^^^^^^^^^^^^^^^^^^^^^^^^^^^^^^^
  File "C:\Users\lewka\miniconda3\envs\deep_learning\Lib\tkinter\__init__.py", line 2863, in _create
    return self.tk.getint(self.tk.call(
                          ^^^^^^^^^^^^^
_tkinter.TclError: image "pyimage2" doesn't exist

During handling of the above exception, another exception occurred:

Traceback (most recent call last):
  File "C:\Users\lewka\miniconda3\envs\deep_learning\Lib\tkinter\__init__.py", line 1968, in __call__
    return self.func(*args)
           ^^^^^^^^^^^^^^^^
  File "c:\Users\lewka\deep_learning\image_labelling\image_labelling\editor.py", line 1047, in on_image_select
    self.load_image(image_path)
  File "c:\Users\lewka\deep_learning\image_labelling\image_labelling\editor.py", line 1094, in load_image
    self.display_image()
  File "c:\Users\lewka\deep_learning\image_labelling\image_labelling\editor.py", line 1192, in display_image
    self.canvas.create_image(0, 0, anchor=tk.NW, image=self.tk_image)
  File "C:\Users\lewka\miniconda3\envs\deep_learning\Lib\tkinter\__init__.py", line 2877, in create_image
    return self._create('image', args, kw)
           ^^^^^^^^^^^^^^^^^^^^^^^^^^^^^^^
  File "C:\Users\lewka\miniconda3\envs\deep_learning\Lib\tkinter\__init__.py", line 2863, in _create
    return self.tk.getint(self.tk.call(
                          ^^^^^^^^^^^^^
_tkinter.TclError: image "pyimage3" doesn't exist
2025-05-31 09:17:22,595 ERROR Exception in Tkinter callback
Traceback (most recent call last):
  File "c:\Users\lewka\deep_learning\image_labelling\image_labelling\editor.py", line 297, in __init__
    self.load_image(last_image_full_path)                   # Load the image
    ^^^^^^^^^^^^^^^^^^^^^^^^^^^^^^^^^^^^^
  File "c:\Users\lewka\deep_learning\image_labelling\image_labelling\editor.py", line 1094, in load_image
    self.display_image()
  File "c:\Users\lewka\deep_learning\image_labelling\image_labelling\editor.py", line 1192, in display_image
    self.canvas.create_image(0, 0, anchor=tk.NW, image=self.tk_image)
  File "C:\Users\lewka\miniconda3\envs\deep_learning\Lib\tkinter\__init__.py", line 2877, in create_image
    return self._create('image', args, kw)
           ^^^^^^^^^^^^^^^^^^^^^^^^^^^^^^^
  File "C:\Users\lewka\miniconda3\envs\deep_learning\Lib\tkinter\__init__.py", line 2863, in _create
    return self.tk.getint(self.tk.call(
                          ^^^^^^^^^^^^^
_tkinter.TclError: image "pyimage1" doesn't exist

During handling of the above exception, another exception occurred:

Traceback (most recent call last):
  File "c:\Users\lewka\deep_learning\image_labelling\image_labelling\project_manager.py", line 149, in _open_selected_project_action
    self.open_editor(project)
  File "c:\Users\lewka\deep_learning\image_labelling\image_labelling\project_manager.py", line 283, in open_editor
    BoundingBoxEditor(editor_root, project) # Removed splash=splash
    ^^^^^^^^^^^^^^^^^^^^^^^^^^^^^^^^^^^^^^^
  File "c:\Users\lewka\deep_learning\image_labelling\image_labelling\editor.py", line 303, in __init__
    self.load_image(os.path.join(self.folder_path, self.image_files[0]))
  File "c:\Users\lewka\deep_learning\image_labelling\image_labelling\editor.py", line 1094, in load_image
    self.display_image()
  File "c:\Users\lewka\deep_learning\image_labelling\image_labelling\editor.py", line 1192, in display_image
    self.canvas.create_image(0, 0, anchor=tk.NW, image=self.tk_image)
  File "C:\Users\lewka\miniconda3\envs\deep_learning\Lib\tkinter\__init__.py", line 2877, in create_image
    return self._create('image', args, kw)
           ^^^^^^^^^^^^^^^^^^^^^^^^^^^^^^^
  File "C:\Users\lewka\miniconda3\envs\deep_learning\Lib\tkinter\__init__.py", line 2863, in _create
    return self.tk.getint(self.tk.call(
                          ^^^^^^^^^^^^^
_tkinter.TclError: image "pyimage2" doesn't exist

During handling of the above exception, another exception occurred:

Traceback (most recent call last):
  File "C:\Users\lewka\miniconda3\envs\deep_learning\Lib\tkinter\__init__.py", line 1968, in __call__
    return self.func(*args)
           ^^^^^^^^^^^^^^^^
  File "c:\Users\lewka\deep_learning\image_labelling\image_labelling\editor.py", line 1047, in on_image_select
    self.load_image(image_path)
  File "c:\Users\lewka\deep_learning\image_labelling\image_labelling\editor.py", line 1094, in load_image
    self.display_image()
  File "c:\Users\lewka\deep_learning\image_labelling\image_labelling\editor.py", line 1192, in display_image
    self.canvas.create_image(0, 0, anchor=tk.NW, image=self.tk_image)
  File "C:\Users\lewka\miniconda3\envs\deep_learning\Lib\tkinter\__init__.py", line 2877, in create_image
    return self._create('image', args, kw)
           ^^^^^^^^^^^^^^^^^^^^^^^^^^^^^^^
  File "C:\Users\lewka\miniconda3\envs\deep_learning\Lib\tkinter\__init__.py", line 2863, in _create
    return self.tk.getint(self.tk.call(
                          ^^^^^^^^^^^^^
_tkinter.TclError: image "pyimage3" doesn't exist

During handling of the above exception, another exception occurred:

Traceback (most recent call last):
  File "C:\Users\lewka\miniconda3\envs\deep_learning\Lib\tkinter\__init__.py", line 1968, in __call__
    return self.func(*args)
           ^^^^^^^^^^^^^^^^
  File "c:\Users\lewka\deep_learning\image_labelling\image_labelling\editor.py", line 1631, in on_canvas_resize
    self.display_image()
  File "c:\Users\lewka\deep_learning\image_labelling\image_labelling\editor.py", line 1192, in display_image
    self.canvas.create_image(0, 0, anchor=tk.NW, image=self.tk_image)
  File "C:\Users\lewka\miniconda3\envs\deep_learning\Lib\tkinter\__init__.py", line 2877, in create_image
    return self._create('image', args, kw)
           ^^^^^^^^^^^^^^^^^^^^^^^^^^^^^^^
  File "C:\Users\lewka\miniconda3\envs\deep_learning\Lib\tkinter\__init__.py", line 2863, in _create
    return self.tk.getint(self.tk.call(
                          ^^^^^^^^^^^^^
_tkinter.TclError: image "pyimage4" doesn't exist
2025-05-31 09:17:48,884 ERROR Error opening project 'authentic logo.json'
Traceback (most recent call last):
  File "c:\Users\lewka\deep_learning\image_labelling\image_labelling\editor.py", line 297, in __init__
    self.load_image(last_image_full_path)                   # Load the image
    ^^^^^^^^^^^^^^^^^^^^^^^^^^^^^^^^^^^^^
  File "c:\Users\lewka\deep_learning\image_labelling\image_labelling\editor.py", line 1094, in load_image
    self.display_image()
  File "c:\Users\lewka\deep_learning\image_labelling\image_labelling\editor.py", line 1192, in display_image
    self.canvas.create_image(0, 0, anchor=tk.NW, image=self.tk_image)
  File "C:\Users\lewka\miniconda3\envs\deep_learning\Lib\tkinter\__init__.py", line 2877, in create_image
    return self._create('image', args, kw)
           ^^^^^^^^^^^^^^^^^^^^^^^^^^^^^^^
  File "C:\Users\lewka\miniconda3\envs\deep_learning\Lib\tkinter\__init__.py", line 2863, in _create
    return self.tk.getint(self.tk.call(
                          ^^^^^^^^^^^^^
_tkinter.TclError: image "pyimage1" doesn't exist

During handling of the above exception, another exception occurred:

Traceback (most recent call last):
  File "c:\Users\lewka\deep_learning\image_labelling\image_labelling\project_manager.py", line 149, in _open_selected_project_action
    self.open_editor(project)
  File "c:\Users\lewka\deep_learning\image_labelling\image_labelling\project_manager.py", line 283, in open_editor
    BoundingBoxEditor(editor_root, project) # Removed splash=splash
    ^^^^^^^^^^^^^^^^^^^^^^^^^^^^^^^^^^^^^^^
  File "c:\Users\lewka\deep_learning\image_labelling\image_labelling\editor.py", line 303, in __init__
    self.load_image(os.path.join(self.folder_path, self.image_files[0]))
  File "c:\Users\lewka\deep_learning\image_labelling\image_labelling\editor.py", line 1094, in load_image
    self.display_image()
  File "c:\Users\lewka\deep_learning\image_labelling\image_labelling\editor.py", line 1192, in display_image
    self.canvas.create_image(0, 0, anchor=tk.NW, image=self.tk_image)
  File "C:\Users\lewka\miniconda3\envs\deep_learning\Lib\tkinter\__init__.py", line 2877, in create_image
    return self._create('image', args, kw)
           ^^^^^^^^^^^^^^^^^^^^^^^^^^^^^^^
  File "C:\Users\lewka\miniconda3\envs\deep_learning\Lib\tkinter\__init__.py", line 2863, in _create
    return self.tk.getint(self.tk.call(
                          ^^^^^^^^^^^^^
_tkinter.TclError: image "pyimage2" doesn't exist
2025-05-31 09:17:48,896 ERROR Exception in Tkinter callback
Traceback (most recent call last):
  File "c:\Users\lewka\deep_learning\image_labelling\image_labelling\editor.py", line 297, in __init__
    self.load_image(last_image_full_path)                   # Load the image
    ^^^^^^^^^^^^^^^^^^^^^^^^^^^^^^^^^^^^^
  File "c:\Users\lewka\deep_learning\image_labelling\image_labelling\editor.py", line 1094, in load_image
    self.display_image()
  File "c:\Users\lewka\deep_learning\image_labelling\image_labelling\editor.py", line 1192, in display_image
    self.canvas.create_image(0, 0, anchor=tk.NW, image=self.tk_image)
  File "C:\Users\lewka\miniconda3\envs\deep_learning\Lib\tkinter\__init__.py", line 2877, in create_image
    return self._create('image', args, kw)
           ^^^^^^^^^^^^^^^^^^^^^^^^^^^^^^^
  File "C:\Users\lewka\miniconda3\envs\deep_learning\Lib\tkinter\__init__.py", line 2863, in _create
    return self.tk.getint(self.tk.call(
                          ^^^^^^^^^^^^^
_tkinter.TclError: image "pyimage1" doesn't exist

During handling of the above exception, another exception occurred:

Traceback (most recent call last):
  File "c:\Users\lewka\deep_learning\image_labelling\image_labelling\project_manager.py", line 149, in _open_selected_project_action
    self.open_editor(project)
  File "c:\Users\lewka\deep_learning\image_labelling\image_labelling\project_manager.py", line 283, in open_editor
    BoundingBoxEditor(editor_root, project) # Removed splash=splash
    ^^^^^^^^^^^^^^^^^^^^^^^^^^^^^^^^^^^^^^^
  File "c:\Users\lewka\deep_learning\image_labelling\image_labelling\editor.py", line 303, in __init__
    self.load_image(os.path.join(self.folder_path, self.image_files[0]))
  File "c:\Users\lewka\deep_learning\image_labelling\image_labelling\editor.py", line 1094, in load_image
    self.display_image()
  File "c:\Users\lewka\deep_learning\image_labelling\image_labelling\editor.py", line 1192, in display_image
    self.canvas.create_image(0, 0, anchor=tk.NW, image=self.tk_image)
  File "C:\Users\lewka\miniconda3\envs\deep_learning\Lib\tkinter\__init__.py", line 2877, in create_image
    return self._create('image', args, kw)
           ^^^^^^^^^^^^^^^^^^^^^^^^^^^^^^^
  File "C:\Users\lewka\miniconda3\envs\deep_learning\Lib\tkinter\__init__.py", line 2863, in _create
    return self.tk.getint(self.tk.call(
                          ^^^^^^^^^^^^^
_tkinter.TclError: image "pyimage2" doesn't exist

During handling of the above exception, another exception occurred:

Traceback (most recent call last):
  File "C:\Users\lewka\miniconda3\envs\deep_learning\Lib\tkinter\__init__.py", line 1968, in __call__
    return self.func(*args)
           ^^^^^^^^^^^^^^^^
  File "c:\Users\lewka\deep_learning\image_labelling\image_labelling\editor.py", line 1047, in on_image_select
    self.load_image(image_path)
  File "c:\Users\lewka\deep_learning\image_labelling\image_labelling\editor.py", line 1094, in load_image
    self.display_image()
  File "c:\Users\lewka\deep_learning\image_labelling\image_labelling\editor.py", line 1192, in display_image
    self.canvas.create_image(0, 0, anchor=tk.NW, image=self.tk_image)
  File "C:\Users\lewka\miniconda3\envs\deep_learning\Lib\tkinter\__init__.py", line 2877, in create_image
    return self._create('image', args, kw)
           ^^^^^^^^^^^^^^^^^^^^^^^^^^^^^^^
  File "C:\Users\lewka\miniconda3\envs\deep_learning\Lib\tkinter\__init__.py", line 2863, in _create
    return self.tk.getint(self.tk.call(
                          ^^^^^^^^^^^^^
_tkinter.TclError: image "pyimage3" doesn't exist
2025-05-31 09:17:48,989 ERROR Exception in Tkinter callback
Traceback (most recent call last):
  File "c:\Users\lewka\deep_learning\image_labelling\image_labelling\editor.py", line 297, in __init__
    self.load_image(last_image_full_path)                   # Load the image
    ^^^^^^^^^^^^^^^^^^^^^^^^^^^^^^^^^^^^^
  File "c:\Users\lewka\deep_learning\image_labelling\image_labelling\editor.py", line 1094, in load_image
    self.display_image()
  File "c:\Users\lewka\deep_learning\image_labelling\image_labelling\editor.py", line 1192, in display_image
    self.canvas.create_image(0, 0, anchor=tk.NW, image=self.tk_image)
  File "C:\Users\lewka\miniconda3\envs\deep_learning\Lib\tkinter\__init__.py", line 2877, in create_image
    return self._create('image', args, kw)
           ^^^^^^^^^^^^^^^^^^^^^^^^^^^^^^^
  File "C:\Users\lewka\miniconda3\envs\deep_learning\Lib\tkinter\__init__.py", line 2863, in _create
    return self.tk.getint(self.tk.call(
                          ^^^^^^^^^^^^^
_tkinter.TclError: image "pyimage1" doesn't exist

During handling of the above exception, another exception occurred:

Traceback (most recent call last):
  File "c:\Users\lewka\deep_learning\image_labelling\image_labelling\project_manager.py", line 149, in _open_selected_project_action
    self.open_editor(project)
  File "c:\Users\lewka\deep_learning\image_labelling\image_labelling\project_manager.py", line 283, in open_editor
    BoundingBoxEditor(editor_root, project) # Removed splash=splash
    ^^^^^^^^^^^^^^^^^^^^^^^^^^^^^^^^^^^^^^^
  File "c:\Users\lewka\deep_learning\image_labelling\image_labelling\editor.py", line 303, in __init__
    self.load_image(os.path.join(self.folder_path, self.image_files[0]))
  File "c:\Users\lewka\deep_learning\image_labelling\image_labelling\editor.py", line 1094, in load_image
    self.display_image()
  File "c:\Users\lewka\deep_learning\image_labelling\image_labelling\editor.py", line 1192, in display_image
    self.canvas.create_image(0, 0, anchor=tk.NW, image=self.tk_image)
  File "C:\Users\lewka\miniconda3\envs\deep_learning\Lib\tkinter\__init__.py", line 2877, in create_image
    return self._create('image', args, kw)
           ^^^^^^^^^^^^^^^^^^^^^^^^^^^^^^^
  File "C:\Users\lewka\miniconda3\envs\deep_learning\Lib\tkinter\__init__.py", line 2863, in _create
    return self.tk.getint(self.tk.call(
                          ^^^^^^^^^^^^^
_tkinter.TclError: image "pyimage2" doesn't exist

During handling of the above exception, another exception occurred:

Traceback (most recent call last):
  File "C:\Users\lewka\miniconda3\envs\deep_learning\Lib\tkinter\__init__.py", line 1968, in __call__
    return self.func(*args)
           ^^^^^^^^^^^^^^^^
  File "c:\Users\lewka\deep_learning\image_labelling\image_labelling\editor.py", line 1047, in on_image_select
    self.load_image(image_path)
  File "c:\Users\lewka\deep_learning\image_labelling\image_labelling\editor.py", line 1094, in load_image
    self.display_image()
  File "c:\Users\lewka\deep_learning\image_labelling\image_labelling\editor.py", line 1192, in display_image
    self.canvas.create_image(0, 0, anchor=tk.NW, image=self.tk_image)
  File "C:\Users\lewka\miniconda3\envs\deep_learning\Lib\tkinter\__init__.py", line 2877, in create_image
    return self._create('image', args, kw)
           ^^^^^^^^^^^^^^^^^^^^^^^^^^^^^^^
  File "C:\Users\lewka\miniconda3\envs\deep_learning\Lib\tkinter\__init__.py", line 2863, in _create
    return self.tk.getint(self.tk.call(
                          ^^^^^^^^^^^^^
_tkinter.TclError: image "pyimage3" doesn't exist

During handling of the above exception, another exception occurred:

Traceback (most recent call last):
  File "C:\Users\lewka\miniconda3\envs\deep_learning\Lib\tkinter\__init__.py", line 1968, in __call__
    return self.func(*args)
           ^^^^^^^^^^^^^^^^
  File "c:\Users\lewka\deep_learning\image_labelling\image_labelling\editor.py", line 1631, in on_canvas_resize
    self.display_image()
  File "c:\Users\lewka\deep_learning\image_labelling\image_labelling\editor.py", line 1192, in display_image
    self.canvas.create_image(0, 0, anchor=tk.NW, image=self.tk_image)
  File "C:\Users\lewka\miniconda3\envs\deep_learning\Lib\tkinter\__init__.py", line 2877, in create_image
    return self._create('image', args, kw)
           ^^^^^^^^^^^^^^^^^^^^^^^^^^^^^^^
  File "C:\Users\lewka\miniconda3\envs\deep_learning\Lib\tkinter\__init__.py", line 2863, in _create
    return self.tk.getint(self.tk.call(
                          ^^^^^^^^^^^^^
_tkinter.TclError: image "pyimage4" doesn't exist
2025-05-31 09:27:08,663 ERROR Error opening project 'authentic logo.json'
Traceback (most recent call last):
  File "c:\Users\lewka\deep_learning\image_labelling\image_labelling\editor.py", line 297, in __init__
    self.load_image(last_image_full_path)                   # Load the image
    ^^^^^^^^^^^^^^^^^^^^^^^^^^^^^^^^^^^^^
  File "c:\Users\lewka\deep_learning\image_labelling\image_labelling\editor.py", line 1094, in load_image
    self.display_image()
  File "c:\Users\lewka\deep_learning\image_labelling\image_labelling\editor.py", line 1175, in display_image
    self.canvas.create_image(0, 0, anchor=tk.NW, image=self.tk_image)
  File "C:\Users\lewka\miniconda3\envs\deep_learning\Lib\tkinter\__init__.py", line 2877, in create_image
    return self._create('image', args, kw)
           ^^^^^^^^^^^^^^^^^^^^^^^^^^^^^^^
  File "C:\Users\lewka\miniconda3\envs\deep_learning\Lib\tkinter\__init__.py", line 2863, in _create
    return self.tk.getint(self.tk.call(
                          ^^^^^^^^^^^^^
_tkinter.TclError: image "pyimage1" doesn't exist

During handling of the above exception, another exception occurred:

Traceback (most recent call last):
  File "c:\Users\lewka\deep_learning\image_labelling\image_labelling\project_manager.py", line 149, in _open_selected_project_action
    self.open_editor(project)
  File "c:\Users\lewka\deep_learning\image_labelling\image_labelling\project_manager.py", line 283, in open_editor
    BoundingBoxEditor(editor_root, project) # Removed splash=splash
    ^^^^^^^^^^^^^^^^^^^^^^^^^^^^^^^^^^^^^^^
  File "c:\Users\lewka\deep_learning\image_labelling\image_labelling\editor.py", line 303, in __init__
    self.load_image(os.path.join(self.folder_path, self.image_files[0]))
  File "c:\Users\lewka\deep_learning\image_labelling\image_labelling\editor.py", line 1094, in load_image
    self.display_image()
  File "c:\Users\lewka\deep_learning\image_labelling\image_labelling\editor.py", line 1175, in display_image
    self.canvas.create_image(0, 0, anchor=tk.NW, image=self.tk_image)
  File "C:\Users\lewka\miniconda3\envs\deep_learning\Lib\tkinter\__init__.py", line 2877, in create_image
    return self._create('image', args, kw)
           ^^^^^^^^^^^^^^^^^^^^^^^^^^^^^^^
  File "C:\Users\lewka\miniconda3\envs\deep_learning\Lib\tkinter\__init__.py", line 2863, in _create
    return self.tk.getint(self.tk.call(
                          ^^^^^^^^^^^^^
_tkinter.TclError: image "pyimage2" doesn't exist
2025-05-31 09:27:08,672 ERROR Exception in Tkinter callback
Traceback (most recent call last):
  File "c:\Users\lewka\deep_learning\image_labelling\image_labelling\editor.py", line 297, in __init__
    self.load_image(last_image_full_path)                   # Load the image
    ^^^^^^^^^^^^^^^^^^^^^^^^^^^^^^^^^^^^^
  File "c:\Users\lewka\deep_learning\image_labelling\image_labelling\editor.py", line 1094, in load_image
    self.display_image()
  File "c:\Users\lewka\deep_learning\image_labelling\image_labelling\editor.py", line 1175, in display_image
    self.canvas.create_image(0, 0, anchor=tk.NW, image=self.tk_image)
  File "C:\Users\lewka\miniconda3\envs\deep_learning\Lib\tkinter\__init__.py", line 2877, in create_image
    return self._create('image', args, kw)
           ^^^^^^^^^^^^^^^^^^^^^^^^^^^^^^^
  File "C:\Users\lewka\miniconda3\envs\deep_learning\Lib\tkinter\__init__.py", line 2863, in _create
    return self.tk.getint(self.tk.call(
                          ^^^^^^^^^^^^^
_tkinter.TclError: image "pyimage1" doesn't exist

During handling of the above exception, another exception occurred:

Traceback (most recent call last):
  File "c:\Users\lewka\deep_learning\image_labelling\image_labelling\project_manager.py", line 149, in _open_selected_project_action
    self.open_editor(project)
  File "c:\Users\lewka\deep_learning\image_labelling\image_labelling\project_manager.py", line 283, in open_editor
    BoundingBoxEditor(editor_root, project) # Removed splash=splash
    ^^^^^^^^^^^^^^^^^^^^^^^^^^^^^^^^^^^^^^^
  File "c:\Users\lewka\deep_learning\image_labelling\image_labelling\editor.py", line 303, in __init__
    self.load_image(os.path.join(self.folder_path, self.image_files[0]))
  File "c:\Users\lewka\deep_learning\image_labelling\image_labelling\editor.py", line 1094, in load_image
    self.display_image()
  File "c:\Users\lewka\deep_learning\image_labelling\image_labelling\editor.py", line 1175, in display_image
    self.canvas.create_image(0, 0, anchor=tk.NW, image=self.tk_image)
  File "C:\Users\lewka\miniconda3\envs\deep_learning\Lib\tkinter\__init__.py", line 2877, in create_image
    return self._create('image', args, kw)
           ^^^^^^^^^^^^^^^^^^^^^^^^^^^^^^^
  File "C:\Users\lewka\miniconda3\envs\deep_learning\Lib\tkinter\__init__.py", line 2863, in _create
    return self.tk.getint(self.tk.call(
                          ^^^^^^^^^^^^^
_tkinter.TclError: image "pyimage2" doesn't exist

During handling of the above exception, another exception occurred:

Traceback (most recent call last):
  File "C:\Users\lewka\miniconda3\envs\deep_learning\Lib\tkinter\__init__.py", line 1968, in __call__
    return self.func(*args)
           ^^^^^^^^^^^^^^^^
  File "c:\Users\lewka\deep_learning\image_labelling\image_labelling\editor.py", line 1047, in on_image_select
    self.load_image(image_path)
  File "c:\Users\lewka\deep_learning\image_labelling\image_labelling\editor.py", line 1094, in load_image
    self.display_image()
  File "c:\Users\lewka\deep_learning\image_labelling\image_labelling\editor.py", line 1175, in display_image
    self.canvas.create_image(0, 0, anchor=tk.NW, image=self.tk_image)
  File "C:\Users\lewka\miniconda3\envs\deep_learning\Lib\tkinter\__init__.py", line 2877, in create_image
    return self._create('image', args, kw)
           ^^^^^^^^^^^^^^^^^^^^^^^^^^^^^^^
  File "C:\Users\lewka\miniconda3\envs\deep_learning\Lib\tkinter\__init__.py", line 2863, in _create
    return self.tk.getint(self.tk.call(
                          ^^^^^^^^^^^^^
_tkinter.TclError: image "pyimage3" doesn't exist
2025-05-31 09:27:08,763 ERROR Exception in Tkinter callback
Traceback (most recent call last):
  File "c:\Users\lewka\deep_learning\image_labelling\image_labelling\editor.py", line 297, in __init__
    self.load_image(last_image_full_path)                   # Load the image
    ^^^^^^^^^^^^^^^^^^^^^^^^^^^^^^^^^^^^^
  File "c:\Users\lewka\deep_learning\image_labelling\image_labelling\editor.py", line 1094, in load_image
    self.display_image()
  File "c:\Users\lewka\deep_learning\image_labelling\image_labelling\editor.py", line 1175, in display_image
    self.canvas.create_image(0, 0, anchor=tk.NW, image=self.tk_image)
  File "C:\Users\lewka\miniconda3\envs\deep_learning\Lib\tkinter\__init__.py", line 2877, in create_image
    return self._create('image', args, kw)
           ^^^^^^^^^^^^^^^^^^^^^^^^^^^^^^^
  File "C:\Users\lewka\miniconda3\envs\deep_learning\Lib\tkinter\__init__.py", line 2863, in _create
    return self.tk.getint(self.tk.call(
                          ^^^^^^^^^^^^^
_tkinter.TclError: image "pyimage1" doesn't exist

During handling of the above exception, another exception occurred:

Traceback (most recent call last):
  File "c:\Users\lewka\deep_learning\image_labelling\image_labelling\project_manager.py", line 149, in _open_selected_project_action
    self.open_editor(project)
  File "c:\Users\lewka\deep_learning\image_labelling\image_labelling\project_manager.py", line 283, in open_editor
    BoundingBoxEditor(editor_root, project) # Removed splash=splash
    ^^^^^^^^^^^^^^^^^^^^^^^^^^^^^^^^^^^^^^^
  File "c:\Users\lewka\deep_learning\image_labelling\image_labelling\editor.py", line 303, in __init__
    self.load_image(os.path.join(self.folder_path, self.image_files[0]))
  File "c:\Users\lewka\deep_learning\image_labelling\image_labelling\editor.py", line 1094, in load_image
    self.display_image()
  File "c:\Users\lewka\deep_learning\image_labelling\image_labelling\editor.py", line 1175, in display_image
    self.canvas.create_image(0, 0, anchor=tk.NW, image=self.tk_image)
  File "C:\Users\lewka\miniconda3\envs\deep_learning\Lib\tkinter\__init__.py", line 2877, in create_image
    return self._create('image', args, kw)
           ^^^^^^^^^^^^^^^^^^^^^^^^^^^^^^^
  File "C:\Users\lewka\miniconda3\envs\deep_learning\Lib\tkinter\__init__.py", line 2863, in _create
    return self.tk.getint(self.tk.call(
                          ^^^^^^^^^^^^^
_tkinter.TclError: image "pyimage2" doesn't exist

During handling of the above exception, another exception occurred:

Traceback (most recent call last):
  File "C:\Users\lewka\miniconda3\envs\deep_learning\Lib\tkinter\__init__.py", line 1968, in __call__
    return self.func(*args)
           ^^^^^^^^^^^^^^^^
  File "c:\Users\lewka\deep_learning\image_labelling\image_labelling\editor.py", line 1047, in on_image_select
    self.load_image(image_path)
  File "c:\Users\lewka\deep_learning\image_labelling\image_labelling\editor.py", line 1094, in load_image
    self.display_image()
  File "c:\Users\lewka\deep_learning\image_labelling\image_labelling\editor.py", line 1175, in display_image
    self.canvas.create_image(0, 0, anchor=tk.NW, image=self.tk_image)
  File "C:\Users\lewka\miniconda3\envs\deep_learning\Lib\tkinter\__init__.py", line 2877, in create_image
    return self._create('image', args, kw)
           ^^^^^^^^^^^^^^^^^^^^^^^^^^^^^^^
  File "C:\Users\lewka\miniconda3\envs\deep_learning\Lib\tkinter\__init__.py", line 2863, in _create
    return self.tk.getint(self.tk.call(
                          ^^^^^^^^^^^^^
_tkinter.TclError: image "pyimage3" doesn't exist

During handling of the above exception, another exception occurred:

Traceback (most recent call last):
  File "C:\Users\lewka\miniconda3\envs\deep_learning\Lib\tkinter\__init__.py", line 1968, in __call__
    return self.func(*args)
           ^^^^^^^^^^^^^^^^
  File "c:\Users\lewka\deep_learning\image_labelling\image_labelling\editor.py", line 1614, in on_canvas_resize
    self.display_image()
  File "c:\Users\lewka\deep_learning\image_labelling\image_labelling\editor.py", line 1175, in display_image
    self.canvas.create_image(0, 0, anchor=tk.NW, image=self.tk_image)
  File "C:\Users\lewka\miniconda3\envs\deep_learning\Lib\tkinter\__init__.py", line 2877, in create_image
    return self._create('image', args, kw)
           ^^^^^^^^^^^^^^^^^^^^^^^^^^^^^^^
  File "C:\Users\lewka\miniconda3\envs\deep_learning\Lib\tkinter\__init__.py", line 2863, in _create
    return self.tk.getint(self.tk.call(
                          ^^^^^^^^^^^^^
_tkinter.TclError: image "pyimage4" doesn't exist
2025-05-31 09:27:27,072 ERROR Error opening project 'authentic logo.json'
Traceback (most recent call last):
  File "c:\Users\lewka\deep_learning\image_labelling\image_labelling\editor.py", line 297, in __init__
    self.load_image(last_image_full_path)                   # Load the image
    ^^^^^^^^^^^^^^^^^^^^^^^^^^^^^^^^^^^^^
  File "c:\Users\lewka\deep_learning\image_labelling\image_labelling\editor.py", line 1094, in load_image
    self.display_image()
  File "c:\Users\lewka\deep_learning\image_labelling\image_labelling\editor.py", line 1175, in display_image
    self.canvas.create_image(0, 0, anchor=tk.NW, image=self.tk_image)
  File "C:\Users\lewka\miniconda3\envs\deep_learning\Lib\tkinter\__init__.py", line 2877, in create_image
    return self._create('image', args, kw)
           ^^^^^^^^^^^^^^^^^^^^^^^^^^^^^^^
  File "C:\Users\lewka\miniconda3\envs\deep_learning\Lib\tkinter\__init__.py", line 2863, in _create
    return self.tk.getint(self.tk.call(
                          ^^^^^^^^^^^^^
_tkinter.TclError: image "pyimage1" doesn't exist

During handling of the above exception, another exception occurred:

Traceback (most recent call last):
  File "c:\Users\lewka\deep_learning\image_labelling\image_labelling\project_manager.py", line 149, in _open_selected_project_action
    self.open_editor(project)
  File "c:\Users\lewka\deep_learning\image_labelling\image_labelling\project_manager.py", line 283, in open_editor
    BoundingBoxEditor(editor_root, project) # Removed splash=splash
    ^^^^^^^^^^^^^^^^^^^^^^^^^^^^^^^^^^^^^^^
  File "c:\Users\lewka\deep_learning\image_labelling\image_labelling\editor.py", line 303, in __init__
    self.load_image(os.path.join(self.folder_path, self.image_files[0]))
  File "c:\Users\lewka\deep_learning\image_labelling\image_labelling\editor.py", line 1094, in load_image
    self.display_image()
  File "c:\Users\lewka\deep_learning\image_labelling\image_labelling\editor.py", line 1175, in display_image
    self.canvas.create_image(0, 0, anchor=tk.NW, image=self.tk_image)
  File "C:\Users\lewka\miniconda3\envs\deep_learning\Lib\tkinter\__init__.py", line 2877, in create_image
    return self._create('image', args, kw)
           ^^^^^^^^^^^^^^^^^^^^^^^^^^^^^^^
  File "C:\Users\lewka\miniconda3\envs\deep_learning\Lib\tkinter\__init__.py", line 2863, in _create
    return self.tk.getint(self.tk.call(
                          ^^^^^^^^^^^^^
_tkinter.TclError: image "pyimage2" doesn't exist
2025-05-31 09:27:27,082 ERROR Exception in Tkinter callback
Traceback (most recent call last):
  File "c:\Users\lewka\deep_learning\image_labelling\image_labelling\editor.py", line 297, in __init__
    self.load_image(last_image_full_path)                   # Load the image
    ^^^^^^^^^^^^^^^^^^^^^^^^^^^^^^^^^^^^^
  File "c:\Users\lewka\deep_learning\image_labelling\image_labelling\editor.py", line 1094, in load_image
    self.display_image()
  File "c:\Users\lewka\deep_learning\image_labelling\image_labelling\editor.py", line 1175, in display_image
    self.canvas.create_image(0, 0, anchor=tk.NW, image=self.tk_image)
  File "C:\Users\lewka\miniconda3\envs\deep_learning\Lib\tkinter\__init__.py", line 2877, in create_image
    return self._create('image', args, kw)
           ^^^^^^^^^^^^^^^^^^^^^^^^^^^^^^^
  File "C:\Users\lewka\miniconda3\envs\deep_learning\Lib\tkinter\__init__.py", line 2863, in _create
    return self.tk.getint(self.tk.call(
                          ^^^^^^^^^^^^^
_tkinter.TclError: image "pyimage1" doesn't exist

During handling of the above exception, another exception occurred:

Traceback (most recent call last):
  File "c:\Users\lewka\deep_learning\image_labelling\image_labelling\project_manager.py", line 149, in _open_selected_project_action
    self.open_editor(project)
  File "c:\Users\lewka\deep_learning\image_labelling\image_labelling\project_manager.py", line 283, in open_editor
    BoundingBoxEditor(editor_root, project) # Removed splash=splash
    ^^^^^^^^^^^^^^^^^^^^^^^^^^^^^^^^^^^^^^^
  File "c:\Users\lewka\deep_learning\image_labelling\image_labelling\editor.py", line 303, in __init__
    self.load_image(os.path.join(self.folder_path, self.image_files[0]))
  File "c:\Users\lewka\deep_learning\image_labelling\image_labelling\editor.py", line 1094, in load_image
    self.display_image()
  File "c:\Users\lewka\deep_learning\image_labelling\image_labelling\editor.py", line 1175, in display_image
    self.canvas.create_image(0, 0, anchor=tk.NW, image=self.tk_image)
  File "C:\Users\lewka\miniconda3\envs\deep_learning\Lib\tkinter\__init__.py", line 2877, in create_image
    return self._create('image', args, kw)
           ^^^^^^^^^^^^^^^^^^^^^^^^^^^^^^^
  File "C:\Users\lewka\miniconda3\envs\deep_learning\Lib\tkinter\__init__.py", line 2863, in _create
    return self.tk.getint(self.tk.call(
                          ^^^^^^^^^^^^^
_tkinter.TclError: image "pyimage2" doesn't exist

During handling of the above exception, another exception occurred:

Traceback (most recent call last):
  File "C:\Users\lewka\miniconda3\envs\deep_learning\Lib\tkinter\__init__.py", line 1968, in __call__
    return self.func(*args)
           ^^^^^^^^^^^^^^^^
  File "c:\Users\lewka\deep_learning\image_labelling\image_labelling\editor.py", line 1047, in on_image_select
    self.load_image(image_path)
  File "c:\Users\lewka\deep_learning\image_labelling\image_labelling\editor.py", line 1094, in load_image
    self.display_image()
  File "c:\Users\lewka\deep_learning\image_labelling\image_labelling\editor.py", line 1175, in display_image
    self.canvas.create_image(0, 0, anchor=tk.NW, image=self.tk_image)
  File "C:\Users\lewka\miniconda3\envs\deep_learning\Lib\tkinter\__init__.py", line 2877, in create_image
    return self._create('image', args, kw)
           ^^^^^^^^^^^^^^^^^^^^^^^^^^^^^^^
  File "C:\Users\lewka\miniconda3\envs\deep_learning\Lib\tkinter\__init__.py", line 2863, in _create
    return self.tk.getint(self.tk.call(
                          ^^^^^^^^^^^^^
_tkinter.TclError: image "pyimage3" doesn't exist
2025-05-31 09:27:27,168 ERROR Exception in Tkinter callback
Traceback (most recent call last):
  File "c:\Users\lewka\deep_learning\image_labelling\image_labelling\editor.py", line 297, in __init__
    self.load_image(last_image_full_path)                   # Load the image
    ^^^^^^^^^^^^^^^^^^^^^^^^^^^^^^^^^^^^^
  File "c:\Users\lewka\deep_learning\image_labelling\image_labelling\editor.py", line 1094, in load_image
    self.display_image()
  File "c:\Users\lewka\deep_learning\image_labelling\image_labelling\editor.py", line 1175, in display_image
    self.canvas.create_image(0, 0, anchor=tk.NW, image=self.tk_image)
  File "C:\Users\lewka\miniconda3\envs\deep_learning\Lib\tkinter\__init__.py", line 2877, in create_image
    return self._create('image', args, kw)
           ^^^^^^^^^^^^^^^^^^^^^^^^^^^^^^^
  File "C:\Users\lewka\miniconda3\envs\deep_learning\Lib\tkinter\__init__.py", line 2863, in _create
    return self.tk.getint(self.tk.call(
                          ^^^^^^^^^^^^^
_tkinter.TclError: image "pyimage1" doesn't exist

During handling of the above exception, another exception occurred:

Traceback (most recent call last):
  File "c:\Users\lewka\deep_learning\image_labelling\image_labelling\project_manager.py", line 149, in _open_selected_project_action
    self.open_editor(project)
  File "c:\Users\lewka\deep_learning\image_labelling\image_labelling\project_manager.py", line 283, in open_editor
    BoundingBoxEditor(editor_root, project) # Removed splash=splash
    ^^^^^^^^^^^^^^^^^^^^^^^^^^^^^^^^^^^^^^^
  File "c:\Users\lewka\deep_learning\image_labelling\image_labelling\editor.py", line 303, in __init__
    self.load_image(os.path.join(self.folder_path, self.image_files[0]))
  File "c:\Users\lewka\deep_learning\image_labelling\image_labelling\editor.py", line 1094, in load_image
    self.display_image()
  File "c:\Users\lewka\deep_learning\image_labelling\image_labelling\editor.py", line 1175, in display_image
    self.canvas.create_image(0, 0, anchor=tk.NW, image=self.tk_image)
  File "C:\Users\lewka\miniconda3\envs\deep_learning\Lib\tkinter\__init__.py", line 2877, in create_image
    return self._create('image', args, kw)
           ^^^^^^^^^^^^^^^^^^^^^^^^^^^^^^^
  File "C:\Users\lewka\miniconda3\envs\deep_learning\Lib\tkinter\__init__.py", line 2863, in _create
    return self.tk.getint(self.tk.call(
                          ^^^^^^^^^^^^^
_tkinter.TclError: image "pyimage2" doesn't exist

During handling of the above exception, another exception occurred:

Traceback (most recent call last):
  File "C:\Users\lewka\miniconda3\envs\deep_learning\Lib\tkinter\__init__.py", line 1968, in __call__
    return self.func(*args)
           ^^^^^^^^^^^^^^^^
  File "c:\Users\lewka\deep_learning\image_labelling\image_labelling\editor.py", line 1047, in on_image_select
    self.load_image(image_path)
  File "c:\Users\lewka\deep_learning\image_labelling\image_labelling\editor.py", line 1094, in load_image
    self.display_image()
  File "c:\Users\lewka\deep_learning\image_labelling\image_labelling\editor.py", line 1175, in display_image
    self.canvas.create_image(0, 0, anchor=tk.NW, image=self.tk_image)
  File "C:\Users\lewka\miniconda3\envs\deep_learning\Lib\tkinter\__init__.py", line 2877, in create_image
    return self._create('image', args, kw)
           ^^^^^^^^^^^^^^^^^^^^^^^^^^^^^^^
  File "C:\Users\lewka\miniconda3\envs\deep_learning\Lib\tkinter\__init__.py", line 2863, in _create
    return self.tk.getint(self.tk.call(
                          ^^^^^^^^^^^^^
_tkinter.TclError: image "pyimage3" doesn't exist

During handling of the above exception, another exception occurred:

Traceback (most recent call last):
  File "C:\Users\lewka\miniconda3\envs\deep_learning\Lib\tkinter\__init__.py", line 1968, in __call__
    return self.func(*args)
           ^^^^^^^^^^^^^^^^
  File "c:\Users\lewka\deep_learning\image_labelling\image_labelling\editor.py", line 1614, in on_canvas_resize
    self.display_image()
  File "c:\Users\lewka\deep_learning\image_labelling\image_labelling\editor.py", line 1175, in display_image
    self.canvas.create_image(0, 0, anchor=tk.NW, image=self.tk_image)
  File "C:\Users\lewka\miniconda3\envs\deep_learning\Lib\tkinter\__init__.py", line 2877, in create_image
    return self._create('image', args, kw)
           ^^^^^^^^^^^^^^^^^^^^^^^^^^^^^^^
  File "C:\Users\lewka\miniconda3\envs\deep_learning\Lib\tkinter\__init__.py", line 2863, in _create
    return self.tk.getint(self.tk.call(
                          ^^^^^^^^^^^^^
_tkinter.TclError: image "pyimage4" doesn't exist
2025-05-31 09:27:30,105 ERROR Error opening project 'authentic logo.json'
Traceback (most recent call last):
  File "c:\Users\lewka\deep_learning\image_labelling\image_labelling\editor.py", line 297, in __init__
    self.load_image(last_image_full_path)                   # Load the image
    ^^^^^^^^^^^^^^^^^^^^^^^^^^^^^^^^^^^^^
  File "c:\Users\lewka\deep_learning\image_labelling\image_labelling\editor.py", line 1094, in load_image
    self.display_image()
  File "c:\Users\lewka\deep_learning\image_labelling\image_labelling\editor.py", line 1175, in display_image
    self.canvas.create_image(0, 0, anchor=tk.NW, image=self.tk_image)
  File "C:\Users\lewka\miniconda3\envs\deep_learning\Lib\tkinter\__init__.py", line 2877, in create_image
    return self._create('image', args, kw)
           ^^^^^^^^^^^^^^^^^^^^^^^^^^^^^^^
  File "C:\Users\lewka\miniconda3\envs\deep_learning\Lib\tkinter\__init__.py", line 2863, in _create
    return self.tk.getint(self.tk.call(
                          ^^^^^^^^^^^^^
_tkinter.TclError: image "pyimage5" doesn't exist

During handling of the above exception, another exception occurred:

Traceback (most recent call last):
  File "c:\Users\lewka\deep_learning\image_labelling\image_labelling\project_manager.py", line 149, in _open_selected_project_action
    self.open_editor(project)
  File "c:\Users\lewka\deep_learning\image_labelling\image_labelling\project_manager.py", line 283, in open_editor
    BoundingBoxEditor(editor_root, project) # Removed splash=splash
    ^^^^^^^^^^^^^^^^^^^^^^^^^^^^^^^^^^^^^^^
  File "c:\Users\lewka\deep_learning\image_labelling\image_labelling\editor.py", line 303, in __init__
    self.load_image(os.path.join(self.folder_path, self.image_files[0]))
  File "c:\Users\lewka\deep_learning\image_labelling\image_labelling\editor.py", line 1094, in load_image
    self.display_image()
  File "c:\Users\lewka\deep_learning\image_labelling\image_labelling\editor.py", line 1175, in display_image
    self.canvas.create_image(0, 0, anchor=tk.NW, image=self.tk_image)
  File "C:\Users\lewka\miniconda3\envs\deep_learning\Lib\tkinter\__init__.py", line 2877, in create_image
    return self._create('image', args, kw)
           ^^^^^^^^^^^^^^^^^^^^^^^^^^^^^^^
  File "C:\Users\lewka\miniconda3\envs\deep_learning\Lib\tkinter\__init__.py", line 2863, in _create
    return self.tk.getint(self.tk.call(
                          ^^^^^^^^^^^^^
_tkinter.TclError: image "pyimage6" doesn't exist
2025-05-31 09:27:30,111 ERROR Exception in Tkinter callback
Traceback (most recent call last):
  File "c:\Users\lewka\deep_learning\image_labelling\image_labelling\editor.py", line 297, in __init__
    self.load_image(last_image_full_path)                   # Load the image
    ^^^^^^^^^^^^^^^^^^^^^^^^^^^^^^^^^^^^^
  File "c:\Users\lewka\deep_learning\image_labelling\image_labelling\editor.py", line 1094, in load_image
    self.display_image()
  File "c:\Users\lewka\deep_learning\image_labelling\image_labelling\editor.py", line 1175, in display_image
    self.canvas.create_image(0, 0, anchor=tk.NW, image=self.tk_image)
  File "C:\Users\lewka\miniconda3\envs\deep_learning\Lib\tkinter\__init__.py", line 2877, in create_image
    return self._create('image', args, kw)
           ^^^^^^^^^^^^^^^^^^^^^^^^^^^^^^^
  File "C:\Users\lewka\miniconda3\envs\deep_learning\Lib\tkinter\__init__.py", line 2863, in _create
    return self.tk.getint(self.tk.call(
                          ^^^^^^^^^^^^^
_tkinter.TclError: image "pyimage5" doesn't exist

During handling of the above exception, another exception occurred:

Traceback (most recent call last):
  File "c:\Users\lewka\deep_learning\image_labelling\image_labelling\project_manager.py", line 149, in _open_selected_project_action
    self.open_editor(project)
  File "c:\Users\lewka\deep_learning\image_labelling\image_labelling\project_manager.py", line 283, in open_editor
    BoundingBoxEditor(editor_root, project) # Removed splash=splash
    ^^^^^^^^^^^^^^^^^^^^^^^^^^^^^^^^^^^^^^^
  File "c:\Users\lewka\deep_learning\image_labelling\image_labelling\editor.py", line 303, in __init__
    self.load_image(os.path.join(self.folder_path, self.image_files[0]))
  File "c:\Users\lewka\deep_learning\image_labelling\image_labelling\editor.py", line 1094, in load_image
    self.display_image()
  File "c:\Users\lewka\deep_learning\image_labelling\image_labelling\editor.py", line 1175, in display_image
    self.canvas.create_image(0, 0, anchor=tk.NW, image=self.tk_image)
  File "C:\Users\lewka\miniconda3\envs\deep_learning\Lib\tkinter\__init__.py", line 2877, in create_image
    return self._create('image', args, kw)
           ^^^^^^^^^^^^^^^^^^^^^^^^^^^^^^^
  File "C:\Users\lewka\miniconda3\envs\deep_learning\Lib\tkinter\__init__.py", line 2863, in _create
    return self.tk.getint(self.tk.call(
                          ^^^^^^^^^^^^^
_tkinter.TclError: image "pyimage6" doesn't exist

During handling of the above exception, another exception occurred:

Traceback (most recent call last):
  File "C:\Users\lewka\miniconda3\envs\deep_learning\Lib\tkinter\__init__.py", line 1968, in __call__
    return self.func(*args)
           ^^^^^^^^^^^^^^^^
  File "c:\Users\lewka\deep_learning\image_labelling\image_labelling\editor.py", line 1047, in on_image_select
    self.load_image(image_path)
  File "c:\Users\lewka\deep_learning\image_labelling\image_labelling\editor.py", line 1094, in load_image
    self.display_image()
  File "c:\Users\lewka\deep_learning\image_labelling\image_labelling\editor.py", line 1175, in display_image
    self.canvas.create_image(0, 0, anchor=tk.NW, image=self.tk_image)
  File "C:\Users\lewka\miniconda3\envs\deep_learning\Lib\tkinter\__init__.py", line 2877, in create_image
    return self._create('image', args, kw)
           ^^^^^^^^^^^^^^^^^^^^^^^^^^^^^^^
  File "C:\Users\lewka\miniconda3\envs\deep_learning\Lib\tkinter\__init__.py", line 2863, in _create
    return self.tk.getint(self.tk.call(
                          ^^^^^^^^^^^^^
_tkinter.TclError: image "pyimage7" doesn't exist
2025-05-31 09:27:30,166 ERROR Exception in Tkinter callback
Traceback (most recent call last):
  File "c:\Users\lewka\deep_learning\image_labelling\image_labelling\editor.py", line 297, in __init__
    self.load_image(last_image_full_path)                   # Load the image
    ^^^^^^^^^^^^^^^^^^^^^^^^^^^^^^^^^^^^^
  File "c:\Users\lewka\deep_learning\image_labelling\image_labelling\editor.py", line 1094, in load_image
    self.display_image()
  File "c:\Users\lewka\deep_learning\image_labelling\image_labelling\editor.py", line 1175, in display_image
    self.canvas.create_image(0, 0, anchor=tk.NW, image=self.tk_image)
  File "C:\Users\lewka\miniconda3\envs\deep_learning\Lib\tkinter\__init__.py", line 2877, in create_image
    return self._create('image', args, kw)
           ^^^^^^^^^^^^^^^^^^^^^^^^^^^^^^^
  File "C:\Users\lewka\miniconda3\envs\deep_learning\Lib\tkinter\__init__.py", line 2863, in _create
    return self.tk.getint(self.tk.call(
                          ^^^^^^^^^^^^^
_tkinter.TclError: image "pyimage5" doesn't exist

During handling of the above exception, another exception occurred:

Traceback (most recent call last):
  File "c:\Users\lewka\deep_learning\image_labelling\image_labelling\project_manager.py", line 149, in _open_selected_project_action
    self.open_editor(project)
  File "c:\Users\lewka\deep_learning\image_labelling\image_labelling\project_manager.py", line 283, in open_editor
    BoundingBoxEditor(editor_root, project) # Removed splash=splash
    ^^^^^^^^^^^^^^^^^^^^^^^^^^^^^^^^^^^^^^^
  File "c:\Users\lewka\deep_learning\image_labelling\image_labelling\editor.py", line 303, in __init__
    self.load_image(os.path.join(self.folder_path, self.image_files[0]))
  File "c:\Users\lewka\deep_learning\image_labelling\image_labelling\editor.py", line 1094, in load_image
    self.display_image()
  File "c:\Users\lewka\deep_learning\image_labelling\image_labelling\editor.py", line 1175, in display_image
    self.canvas.create_image(0, 0, anchor=tk.NW, image=self.tk_image)
  File "C:\Users\lewka\miniconda3\envs\deep_learning\Lib\tkinter\__init__.py", line 2877, in create_image
    return self._create('image', args, kw)
           ^^^^^^^^^^^^^^^^^^^^^^^^^^^^^^^
  File "C:\Users\lewka\miniconda3\envs\deep_learning\Lib\tkinter\__init__.py", line 2863, in _create
    return self.tk.getint(self.tk.call(
                          ^^^^^^^^^^^^^
_tkinter.TclError: image "pyimage6" doesn't exist

During handling of the above exception, another exception occurred:

Traceback (most recent call last):
  File "C:\Users\lewka\miniconda3\envs\deep_learning\Lib\tkinter\__init__.py", line 1968, in __call__
    return self.func(*args)
           ^^^^^^^^^^^^^^^^
  File "c:\Users\lewka\deep_learning\image_labelling\image_labelling\editor.py", line 1047, in on_image_select
    self.load_image(image_path)
  File "c:\Users\lewka\deep_learning\image_labelling\image_labelling\editor.py", line 1094, in load_image
    self.display_image()
  File "c:\Users\lewka\deep_learning\image_labelling\image_labelling\editor.py", line 1175, in display_image
    self.canvas.create_image(0, 0, anchor=tk.NW, image=self.tk_image)
  File "C:\Users\lewka\miniconda3\envs\deep_learning\Lib\tkinter\__init__.py", line 2877, in create_image
    return self._create('image', args, kw)
           ^^^^^^^^^^^^^^^^^^^^^^^^^^^^^^^
  File "C:\Users\lewka\miniconda3\envs\deep_learning\Lib\tkinter\__init__.py", line 2863, in _create
    return self.tk.getint(self.tk.call(
                          ^^^^^^^^^^^^^
_tkinter.TclError: image "pyimage7" doesn't exist

During handling of the above exception, another exception occurred:

Traceback (most recent call last):
  File "C:\Users\lewka\miniconda3\envs\deep_learning\Lib\tkinter\__init__.py", line 1968, in __call__
    return self.func(*args)
           ^^^^^^^^^^^^^^^^
  File "c:\Users\lewka\deep_learning\image_labelling\image_labelling\editor.py", line 1614, in on_canvas_resize
    self.display_image()
  File "c:\Users\lewka\deep_learning\image_labelling\image_labelling\editor.py", line 1175, in display_image
    self.canvas.create_image(0, 0, anchor=tk.NW, image=self.tk_image)
  File "C:\Users\lewka\miniconda3\envs\deep_learning\Lib\tkinter\__init__.py", line 2877, in create_image
    return self._create('image', args, kw)
           ^^^^^^^^^^^^^^^^^^^^^^^^^^^^^^^
  File "C:\Users\lewka\miniconda3\envs\deep_learning\Lib\tkinter\__init__.py", line 2863, in _create
    return self.tk.getint(self.tk.call(
                          ^^^^^^^^^^^^^
_tkinter.TclError: image "pyimage8" doesn't exist
2025-05-31 09:27:34,492 ERROR Exception in Tkinter callback
Traceback (most recent call last):
  File "C:\Users\lewka\miniconda3\envs\deep_learning\Lib\tkinter\__init__.py", line 1968, in __call__
    return self.func(*args)
           ^^^^^^^^^^^^^^^^
  File "c:\Users\lewka\deep_learning\image_labelling\image_labelling\editor.py", line 1614, in on_canvas_resize
    self.display_image()
  File "c:\Users\lewka\deep_learning\image_labelling\image_labelling\editor.py", line 1174, in display_image
    self.tk_image = ImageTk.PhotoImage(image=Image.fromarray(self.image))
                    ^^^^^^^^^^^^^^^^^^^^^^^^^^^^^^^^^^^^^^^^^^^^^^^^^^^^^
  File "C:\Users\lewka\miniconda3\envs\deep_learning\Lib\site-packages\PIL\ImageTk.py", line 128, in __init__
    self.__photo = tkinter.PhotoImage(**kw)
                   ^^^^^^^^^^^^^^^^^^^^^^^^
  File "C:\Users\lewka\miniconda3\envs\deep_learning\Lib\tkinter\__init__.py", line 4164, in __init__
    Image.__init__(self, 'photo', name, cnf, master, **kw)
  File "C:\Users\lewka\miniconda3\envs\deep_learning\Lib\tkinter\__init__.py", line 4101, in __init__
    master = _get_default_root('create image')
             ^^^^^^^^^^^^^^^^^^^^^^^^^^^^^^^^^
  File "C:\Users\lewka\miniconda3\envs\deep_learning\Lib\tkinter\__init__.py", line 323, in _get_default_root
    raise RuntimeError(f"Too early to {what}: no default root window")
RuntimeError: Too early to create image: no default root window
2025-05-31 09:36:28,501 ERROR Exception in Tkinter callback
Traceback (most recent call last):
  File "c:\Users\lewka\deep_learning\image_labelling\image_labelling\editor.py", line 2809, in _load_initial_image
    self.load_image(last_image_full_path)                   # Load the image
    ^^^^^^^^^^^^^^^^^^^^^^^^^^^^^^^^^^^^^
  File "c:\Users\lewka\deep_learning\image_labelling\image_labelling\editor.py", line 1071, in load_image
    self.display_image()
  File "c:\Users\lewka\deep_learning\image_labelling\image_labelling\editor.py", line 1152, in display_image
    self.canvas.create_image(0, 0, anchor=tk.NW, image=self.tk_image)
  File "C:\Users\lewka\miniconda3\envs\deep_learning\Lib\tkinter\__init__.py", line 2877, in create_image
    return self._create('image', args, kw)
           ^^^^^^^^^^^^^^^^^^^^^^^^^^^^^^^
  File "C:\Users\lewka\miniconda3\envs\deep_learning\Lib\tkinter\__init__.py", line 2863, in _create
    return self.tk.getint(self.tk.call(
                          ^^^^^^^^^^^^^
_tkinter.TclError: image "pyimage1" doesn't exist

During handling of the above exception, another exception occurred:

Traceback (most recent call last):
  File "C:\Users\lewka\miniconda3\envs\deep_learning\Lib\tkinter\__init__.py", line 1968, in __call__
    return self.func(*args)
           ^^^^^^^^^^^^^^^^
  File "C:\Users\lewka\miniconda3\envs\deep_learning\Lib\tkinter\__init__.py", line 862, in callit
    func(*args)
  File "c:\Users\lewka\deep_learning\image_labelling\image_labelling\editor.py", line 2816, in _load_initial_image
    self.load_image(os.path.join(self.folder_path, self.image_files[0]))
  File "c:\Users\lewka\deep_learning\image_labelling\image_labelling\editor.py", line 1071, in load_image
    self.display_image()
  File "c:\Users\lewka\deep_learning\image_labelling\image_labelling\editor.py", line 1152, in display_image
    self.canvas.create_image(0, 0, anchor=tk.NW, image=self.tk_image)
  File "C:\Users\lewka\miniconda3\envs\deep_learning\Lib\tkinter\__init__.py", line 2877, in create_image
    return self._create('image', args, kw)
           ^^^^^^^^^^^^^^^^^^^^^^^^^^^^^^^
  File "C:\Users\lewka\miniconda3\envs\deep_learning\Lib\tkinter\__init__.py", line 2863, in _create
    return self.tk.getint(self.tk.call(
                          ^^^^^^^^^^^^^
_tkinter.TclError: image "pyimage2" doesn't exist
2025-05-31 09:36:28,509 ERROR Exception in Tkinter callback
Traceback (most recent call last):
  File "c:\Users\lewka\deep_learning\image_labelling\image_labelling\editor.py", line 2809, in _load_initial_image
    self.load_image(last_image_full_path)                   # Load the image
    ^^^^^^^^^^^^^^^^^^^^^^^^^^^^^^^^^^^^^
  File "c:\Users\lewka\deep_learning\image_labelling\image_labelling\editor.py", line 1071, in load_image
    self.display_image()
  File "c:\Users\lewka\deep_learning\image_labelling\image_labelling\editor.py", line 1152, in display_image
    self.canvas.create_image(0, 0, anchor=tk.NW, image=self.tk_image)
  File "C:\Users\lewka\miniconda3\envs\deep_learning\Lib\tkinter\__init__.py", line 2877, in create_image
    return self._create('image', args, kw)
           ^^^^^^^^^^^^^^^^^^^^^^^^^^^^^^^
  File "C:\Users\lewka\miniconda3\envs\deep_learning\Lib\tkinter\__init__.py", line 2863, in _create
    return self.tk.getint(self.tk.call(
                          ^^^^^^^^^^^^^
_tkinter.TclError: image "pyimage1" doesn't exist

During handling of the above exception, another exception occurred:

Traceback (most recent call last):
  File "C:\Users\lewka\miniconda3\envs\deep_learning\Lib\tkinter\__init__.py", line 1968, in __call__
    return self.func(*args)
           ^^^^^^^^^^^^^^^^
  File "C:\Users\lewka\miniconda3\envs\deep_learning\Lib\tkinter\__init__.py", line 862, in callit
    func(*args)
  File "c:\Users\lewka\deep_learning\image_labelling\image_labelling\editor.py", line 2816, in _load_initial_image
    self.load_image(os.path.join(self.folder_path, self.image_files[0]))
  File "c:\Users\lewka\deep_learning\image_labelling\image_labelling\editor.py", line 1071, in load_image
    self.display_image()
  File "c:\Users\lewka\deep_learning\image_labelling\image_labelling\editor.py", line 1152, in display_image
    self.canvas.create_image(0, 0, anchor=tk.NW, image=self.tk_image)
  File "C:\Users\lewka\miniconda3\envs\deep_learning\Lib\tkinter\__init__.py", line 2877, in create_image
    return self._create('image', args, kw)
           ^^^^^^^^^^^^^^^^^^^^^^^^^^^^^^^
  File "C:\Users\lewka\miniconda3\envs\deep_learning\Lib\tkinter\__init__.py", line 2863, in _create
    return self.tk.getint(self.tk.call(
                          ^^^^^^^^^^^^^
_tkinter.TclError: image "pyimage2" doesn't exist

During handling of the above exception, another exception occurred:

Traceback (most recent call last):
  File "C:\Users\lewka\miniconda3\envs\deep_learning\Lib\tkinter\__init__.py", line 1968, in __call__
    return self.func(*args)
           ^^^^^^^^^^^^^^^^
  File "c:\Users\lewka\deep_learning\image_labelling\image_labelling\editor.py", line 1024, in on_image_select
    self.load_image(image_path)
  File "c:\Users\lewka\deep_learning\image_labelling\image_labelling\editor.py", line 1071, in load_image
    self.display_image()
  File "c:\Users\lewka\deep_learning\image_labelling\image_labelling\editor.py", line 1152, in display_image
    self.canvas.create_image(0, 0, anchor=tk.NW, image=self.tk_image)
  File "C:\Users\lewka\miniconda3\envs\deep_learning\Lib\tkinter\__init__.py", line 2877, in create_image
    return self._create('image', args, kw)
           ^^^^^^^^^^^^^^^^^^^^^^^^^^^^^^^
  File "C:\Users\lewka\miniconda3\envs\deep_learning\Lib\tkinter\__init__.py", line 2863, in _create
    return self.tk.getint(self.tk.call(
                          ^^^^^^^^^^^^^
_tkinter.TclError: image "pyimage3" doesn't exist
2025-05-31 09:36:28,632 ERROR Exception in Tkinter callback
Traceback (most recent call last):
  File "c:\Users\lewka\deep_learning\image_labelling\image_labelling\editor.py", line 2809, in _load_initial_image
    self.load_image(last_image_full_path)                   # Load the image
    ^^^^^^^^^^^^^^^^^^^^^^^^^^^^^^^^^^^^^
  File "c:\Users\lewka\deep_learning\image_labelling\image_labelling\editor.py", line 1071, in load_image
    self.display_image()
  File "c:\Users\lewka\deep_learning\image_labelling\image_labelling\editor.py", line 1152, in display_image
    self.canvas.create_image(0, 0, anchor=tk.NW, image=self.tk_image)
  File "C:\Users\lewka\miniconda3\envs\deep_learning\Lib\tkinter\__init__.py", line 2877, in create_image
    return self._create('image', args, kw)
           ^^^^^^^^^^^^^^^^^^^^^^^^^^^^^^^
  File "C:\Users\lewka\miniconda3\envs\deep_learning\Lib\tkinter\__init__.py", line 2863, in _create
    return self.tk.getint(self.tk.call(
                          ^^^^^^^^^^^^^
_tkinter.TclError: image "pyimage1" doesn't exist

During handling of the above exception, another exception occurred:

Traceback (most recent call last):
  File "C:\Users\lewka\miniconda3\envs\deep_learning\Lib\tkinter\__init__.py", line 1968, in __call__
    return self.func(*args)
           ^^^^^^^^^^^^^^^^
  File "C:\Users\lewka\miniconda3\envs\deep_learning\Lib\tkinter\__init__.py", line 862, in callit
    func(*args)
  File "c:\Users\lewka\deep_learning\image_labelling\image_labelling\editor.py", line 2816, in _load_initial_image
    self.load_image(os.path.join(self.folder_path, self.image_files[0]))
  File "c:\Users\lewka\deep_learning\image_labelling\image_labelling\editor.py", line 1071, in load_image
    self.display_image()
  File "c:\Users\lewka\deep_learning\image_labelling\image_labelling\editor.py", line 1152, in display_image
    self.canvas.create_image(0, 0, anchor=tk.NW, image=self.tk_image)
  File "C:\Users\lewka\miniconda3\envs\deep_learning\Lib\tkinter\__init__.py", line 2877, in create_image
    return self._create('image', args, kw)
           ^^^^^^^^^^^^^^^^^^^^^^^^^^^^^^^
  File "C:\Users\lewka\miniconda3\envs\deep_learning\Lib\tkinter\__init__.py", line 2863, in _create
    return self.tk.getint(self.tk.call(
                          ^^^^^^^^^^^^^
_tkinter.TclError: image "pyimage2" doesn't exist

During handling of the above exception, another exception occurred:

Traceback (most recent call last):
  File "C:\Users\lewka\miniconda3\envs\deep_learning\Lib\tkinter\__init__.py", line 1968, in __call__
    return self.func(*args)
           ^^^^^^^^^^^^^^^^
  File "c:\Users\lewka\deep_learning\image_labelling\image_labelling\editor.py", line 1024, in on_image_select
    self.load_image(image_path)
  File "c:\Users\lewka\deep_learning\image_labelling\image_labelling\editor.py", line 1071, in load_image
    self.display_image()
  File "c:\Users\lewka\deep_learning\image_labelling\image_labelling\editor.py", line 1152, in display_image
    self.canvas.create_image(0, 0, anchor=tk.NW, image=self.tk_image)
  File "C:\Users\lewka\miniconda3\envs\deep_learning\Lib\tkinter\__init__.py", line 2877, in create_image
    return self._create('image', args, kw)
           ^^^^^^^^^^^^^^^^^^^^^^^^^^^^^^^
  File "C:\Users\lewka\miniconda3\envs\deep_learning\Lib\tkinter\__init__.py", line 2863, in _create
    return self.tk.getint(self.tk.call(
                          ^^^^^^^^^^^^^
_tkinter.TclError: image "pyimage3" doesn't exist

During handling of the above exception, another exception occurred:

Traceback (most recent call last):
  File "C:\Users\lewka\miniconda3\envs\deep_learning\Lib\tkinter\__init__.py", line 1968, in __call__
    return self.func(*args)
           ^^^^^^^^^^^^^^^^
  File "c:\Users\lewka\deep_learning\image_labelling\image_labelling\editor.py", line 1591, in on_canvas_resize
    self.display_image()
  File "c:\Users\lewka\deep_learning\image_labelling\image_labelling\editor.py", line 1152, in display_image
    self.canvas.create_image(0, 0, anchor=tk.NW, image=self.tk_image)
  File "C:\Users\lewka\miniconda3\envs\deep_learning\Lib\tkinter\__init__.py", line 2877, in create_image
    return self._create('image', args, kw)
           ^^^^^^^^^^^^^^^^^^^^^^^^^^^^^^^
  File "C:\Users\lewka\miniconda3\envs\deep_learning\Lib\tkinter\__init__.py", line 2863, in _create
    return self.tk.getint(self.tk.call(
                          ^^^^^^^^^^^^^
_tkinter.TclError: image "pyimage4" doesn't exist
2025-05-31 09:36:31,813 ERROR Exception in Tkinter callback
Traceback (most recent call last):
  File "C:\Users\lewka\miniconda3\envs\deep_learning\Lib\tkinter\__init__.py", line 1968, in __call__
    return self.func(*args)
           ^^^^^^^^^^^^^^^^
  File "c:\Users\lewka\deep_learning\image_labelling\image_labelling\editor.py", line 1024, in on_image_select
    self.load_image(image_path)
  File "c:\Users\lewka\deep_learning\image_labelling\image_labelling\editor.py", line 1071, in load_image
    self.display_image()
  File "c:\Users\lewka\deep_learning\image_labelling\image_labelling\editor.py", line 1152, in display_image
    self.canvas.create_image(0, 0, anchor=tk.NW, image=self.tk_image)
  File "C:\Users\lewka\miniconda3\envs\deep_learning\Lib\tkinter\__init__.py", line 2877, in create_image
    return self._create('image', args, kw)
           ^^^^^^^^^^^^^^^^^^^^^^^^^^^^^^^
  File "C:\Users\lewka\miniconda3\envs\deep_learning\Lib\tkinter\__init__.py", line 2863, in _create
    return self.tk.getint(self.tk.call(
                          ^^^^^^^^^^^^^
_tkinter.TclError: image "pyimage5" doesn't exist
2025-05-31 09:36:32,774 ERROR Exception in Tkinter callback
Traceback (most recent call last):
  File "C:\Users\lewka\miniconda3\envs\deep_learning\Lib\tkinter\__init__.py", line 1968, in __call__
    return self.func(*args)
           ^^^^^^^^^^^^^^^^
  File "c:\Users\lewka\deep_learning\image_labelling\image_labelling\editor.py", line 1024, in on_image_select
    self.load_image(image_path)
  File "c:\Users\lewka\deep_learning\image_labelling\image_labelling\editor.py", line 1071, in load_image
    self.display_image()
  File "c:\Users\lewka\deep_learning\image_labelling\image_labelling\editor.py", line 1152, in display_image
    self.canvas.create_image(0, 0, anchor=tk.NW, image=self.tk_image)
  File "C:\Users\lewka\miniconda3\envs\deep_learning\Lib\tkinter\__init__.py", line 2877, in create_image
    return self._create('image', args, kw)
           ^^^^^^^^^^^^^^^^^^^^^^^^^^^^^^^
  File "C:\Users\lewka\miniconda3\envs\deep_learning\Lib\tkinter\__init__.py", line 2863, in _create
    return self.tk.getint(self.tk.call(
                          ^^^^^^^^^^^^^
_tkinter.TclError: image "pyimage6" doesn't exist
2025-05-31 09:37:15,219 ERROR Exception in Tkinter callback
Traceback (most recent call last):
  File "C:\Users\lewka\miniconda3\envs\deep_learning\Lib\tkinter\__init__.py", line 1968, in __call__
    return self.func(*args)
           ^^^^^^^^^^^^^^^^
  File "c:\Users\lewka\deep_learning\image_labelling\image_labelling\project_manager.py", line 149, in _open_selected_project_action
    self.open_editor(project)
  File "c:\Users\lewka\deep_learning\image_labelling\image_labelling\project_manager.py", line 284, in open_editor
    editor_root.mainloop()
  File "C:\Users\lewka\miniconda3\envs\deep_learning\Lib\tkinter\__init__.py", line 1505, in mainloop
    self.tk.mainloop(n)
KeyboardInterrupt
2025-05-31 09:40:29,146 ERROR Error opening project 'authentic logo.json'
Traceback (most recent call last):
  File "c:\Users\lewka\deep_learning\image_labelling\image_labelling\editor.py", line 297, in __init__
    self.load_image(last_image_full_path)                   # Load the image
    ^^^^^^^^^^^^^^^^^^^^^^^^^^^^^^^^^^^^^
  File "c:\Users\lewka\deep_learning\image_labelling\image_labelling\editor.py", line 1094, in load_image
    self.display_image()
  File "c:\Users\lewka\deep_learning\image_labelling\image_labelling\editor.py", line 1175, in display_image
    self.canvas.create_image(0, 0, anchor=tk.NW, image=self.tk_image)
  File "C:\Users\lewka\miniconda3\envs\deep_learning\Lib\tkinter\__init__.py", line 2877, in create_image
    return self._create('image', args, kw)
           ^^^^^^^^^^^^^^^^^^^^^^^^^^^^^^^
  File "C:\Users\lewka\miniconda3\envs\deep_learning\Lib\tkinter\__init__.py", line 2863, in _create
    return self.tk.getint(self.tk.call(
                          ^^^^^^^^^^^^^
_tkinter.TclError: image "pyimage1" doesn't exist

During handling of the above exception, another exception occurred:

Traceback (most recent call last):
  File "c:\Users\lewka\deep_learning\image_labelling\image_labelling\project_manager.py", line 149, in _open_selected_project_action
    self.open_editor(project)
  File "c:\Users\lewka\deep_learning\image_labelling\image_labelling\project_manager.py", line 283, in open_editor
    BoundingBoxEditor(editor_root, project) # Removed splash=splash
    ^^^^^^^^^^^^^^^^^^^^^^^^^^^^^^^^^^^^^^^
  File "c:\Users\lewka\deep_learning\image_labelling\image_labelling\editor.py", line 303, in __init__
    self.load_image(os.path.join(self.folder_path, self.image_files[0]))
  File "c:\Users\lewka\deep_learning\image_labelling\image_labelling\editor.py", line 1094, in load_image
    self.display_image()
  File "c:\Users\lewka\deep_learning\image_labelling\image_labelling\editor.py", line 1175, in display_image
    self.canvas.create_image(0, 0, anchor=tk.NW, image=self.tk_image)
  File "C:\Users\lewka\miniconda3\envs\deep_learning\Lib\tkinter\__init__.py", line 2877, in create_image
    return self._create('image', args, kw)
           ^^^^^^^^^^^^^^^^^^^^^^^^^^^^^^^
  File "C:\Users\lewka\miniconda3\envs\deep_learning\Lib\tkinter\__init__.py", line 2863, in _create
    return self.tk.getint(self.tk.call(
                          ^^^^^^^^^^^^^
_tkinter.TclError: image "pyimage2" doesn't exist
2025-05-31 09:40:29,156 ERROR Exception in Tkinter callback
Traceback (most recent call last):
  File "c:\Users\lewka\deep_learning\image_labelling\image_labelling\editor.py", line 297, in __init__
    self.load_image(last_image_full_path)                   # Load the image
    ^^^^^^^^^^^^^^^^^^^^^^^^^^^^^^^^^^^^^
  File "c:\Users\lewka\deep_learning\image_labelling\image_labelling\editor.py", line 1094, in load_image
    self.display_image()
  File "c:\Users\lewka\deep_learning\image_labelling\image_labelling\editor.py", line 1175, in display_image
    self.canvas.create_image(0, 0, anchor=tk.NW, image=self.tk_image)
  File "C:\Users\lewka\miniconda3\envs\deep_learning\Lib\tkinter\__init__.py", line 2877, in create_image
    return self._create('image', args, kw)
           ^^^^^^^^^^^^^^^^^^^^^^^^^^^^^^^
  File "C:\Users\lewka\miniconda3\envs\deep_learning\Lib\tkinter\__init__.py", line 2863, in _create
    return self.tk.getint(self.tk.call(
                          ^^^^^^^^^^^^^
_tkinter.TclError: image "pyimage1" doesn't exist

During handling of the above exception, another exception occurred:

Traceback (most recent call last):
  File "c:\Users\lewka\deep_learning\image_labelling\image_labelling\project_manager.py", line 149, in _open_selected_project_action
    self.open_editor(project)
  File "c:\Users\lewka\deep_learning\image_labelling\image_labelling\project_manager.py", line 283, in open_editor
    BoundingBoxEditor(editor_root, project) # Removed splash=splash
    ^^^^^^^^^^^^^^^^^^^^^^^^^^^^^^^^^^^^^^^
  File "c:\Users\lewka\deep_learning\image_labelling\image_labelling\editor.py", line 303, in __init__
    self.load_image(os.path.join(self.folder_path, self.image_files[0]))
  File "c:\Users\lewka\deep_learning\image_labelling\image_labelling\editor.py", line 1094, in load_image
    self.display_image()
  File "c:\Users\lewka\deep_learning\image_labelling\image_labelling\editor.py", line 1175, in display_image
    self.canvas.create_image(0, 0, anchor=tk.NW, image=self.tk_image)
  File "C:\Users\lewka\miniconda3\envs\deep_learning\Lib\tkinter\__init__.py", line 2877, in create_image
    return self._create('image', args, kw)
           ^^^^^^^^^^^^^^^^^^^^^^^^^^^^^^^
  File "C:\Users\lewka\miniconda3\envs\deep_learning\Lib\tkinter\__init__.py", line 2863, in _create
    return self.tk.getint(self.tk.call(
                          ^^^^^^^^^^^^^
_tkinter.TclError: image "pyimage2" doesn't exist

During handling of the above exception, another exception occurred:

Traceback (most recent call last):
  File "C:\Users\lewka\miniconda3\envs\deep_learning\Lib\tkinter\__init__.py", line 1968, in __call__
    return self.func(*args)
           ^^^^^^^^^^^^^^^^
  File "c:\Users\lewka\deep_learning\image_labelling\image_labelling\editor.py", line 1047, in on_image_select
    self.load_image(image_path)
  File "c:\Users\lewka\deep_learning\image_labelling\image_labelling\editor.py", line 1094, in load_image
    self.display_image()
  File "c:\Users\lewka\deep_learning\image_labelling\image_labelling\editor.py", line 1175, in display_image
    self.canvas.create_image(0, 0, anchor=tk.NW, image=self.tk_image)
  File "C:\Users\lewka\miniconda3\envs\deep_learning\Lib\tkinter\__init__.py", line 2877, in create_image
    return self._create('image', args, kw)
           ^^^^^^^^^^^^^^^^^^^^^^^^^^^^^^^
  File "C:\Users\lewka\miniconda3\envs\deep_learning\Lib\tkinter\__init__.py", line 2863, in _create
    return self.tk.getint(self.tk.call(
                          ^^^^^^^^^^^^^
_tkinter.TclError: image "pyimage3" doesn't exist
2025-05-31 09:40:29,252 ERROR Exception in Tkinter callback
Traceback (most recent call last):
  File "c:\Users\lewka\deep_learning\image_labelling\image_labelling\editor.py", line 297, in __init__
    self.load_image(last_image_full_path)                   # Load the image
    ^^^^^^^^^^^^^^^^^^^^^^^^^^^^^^^^^^^^^
  File "c:\Users\lewka\deep_learning\image_labelling\image_labelling\editor.py", line 1094, in load_image
    self.display_image()
  File "c:\Users\lewka\deep_learning\image_labelling\image_labelling\editor.py", line 1175, in display_image
    self.canvas.create_image(0, 0, anchor=tk.NW, image=self.tk_image)
  File "C:\Users\lewka\miniconda3\envs\deep_learning\Lib\tkinter\__init__.py", line 2877, in create_image
    return self._create('image', args, kw)
           ^^^^^^^^^^^^^^^^^^^^^^^^^^^^^^^
  File "C:\Users\lewka\miniconda3\envs\deep_learning\Lib\tkinter\__init__.py", line 2863, in _create
    return self.tk.getint(self.tk.call(
                          ^^^^^^^^^^^^^
_tkinter.TclError: image "pyimage1" doesn't exist

During handling of the above exception, another exception occurred:

Traceback (most recent call last):
  File "c:\Users\lewka\deep_learning\image_labelling\image_labelling\project_manager.py", line 149, in _open_selected_project_action
    self.open_editor(project)
  File "c:\Users\lewka\deep_learning\image_labelling\image_labelling\project_manager.py", line 283, in open_editor
    BoundingBoxEditor(editor_root, project) # Removed splash=splash
    ^^^^^^^^^^^^^^^^^^^^^^^^^^^^^^^^^^^^^^^
  File "c:\Users\lewka\deep_learning\image_labelling\image_labelling\editor.py", line 303, in __init__
    self.load_image(os.path.join(self.folder_path, self.image_files[0]))
  File "c:\Users\lewka\deep_learning\image_labelling\image_labelling\editor.py", line 1094, in load_image
    self.display_image()
  File "c:\Users\lewka\deep_learning\image_labelling\image_labelling\editor.py", line 1175, in display_image
    self.canvas.create_image(0, 0, anchor=tk.NW, image=self.tk_image)
  File "C:\Users\lewka\miniconda3\envs\deep_learning\Lib\tkinter\__init__.py", line 2877, in create_image
    return self._create('image', args, kw)
           ^^^^^^^^^^^^^^^^^^^^^^^^^^^^^^^
  File "C:\Users\lewka\miniconda3\envs\deep_learning\Lib\tkinter\__init__.py", line 2863, in _create
    return self.tk.getint(self.tk.call(
                          ^^^^^^^^^^^^^
_tkinter.TclError: image "pyimage2" doesn't exist

During handling of the above exception, another exception occurred:

Traceback (most recent call last):
  File "C:\Users\lewka\miniconda3\envs\deep_learning\Lib\tkinter\__init__.py", line 1968, in __call__
    return self.func(*args)
           ^^^^^^^^^^^^^^^^
  File "c:\Users\lewka\deep_learning\image_labelling\image_labelling\editor.py", line 1047, in on_image_select
    self.load_image(image_path)
  File "c:\Users\lewka\deep_learning\image_labelling\image_labelling\editor.py", line 1094, in load_image
    self.display_image()
  File "c:\Users\lewka\deep_learning\image_labelling\image_labelling\editor.py", line 1175, in display_image
    self.canvas.create_image(0, 0, anchor=tk.NW, image=self.tk_image)
  File "C:\Users\lewka\miniconda3\envs\deep_learning\Lib\tkinter\__init__.py", line 2877, in create_image
    return self._create('image', args, kw)
           ^^^^^^^^^^^^^^^^^^^^^^^^^^^^^^^
  File "C:\Users\lewka\miniconda3\envs\deep_learning\Lib\tkinter\__init__.py", line 2863, in _create
    return self.tk.getint(self.tk.call(
                          ^^^^^^^^^^^^^
_tkinter.TclError: image "pyimage3" doesn't exist

During handling of the above exception, another exception occurred:

Traceback (most recent call last):
  File "C:\Users\lewka\miniconda3\envs\deep_learning\Lib\tkinter\__init__.py", line 1968, in __call__
    return self.func(*args)
           ^^^^^^^^^^^^^^^^
  File "c:\Users\lewka\deep_learning\image_labelling\image_labelling\editor.py", line 1614, in on_canvas_resize
    self.display_image()
  File "c:\Users\lewka\deep_learning\image_labelling\image_labelling\editor.py", line 1175, in display_image
    self.canvas.create_image(0, 0, anchor=tk.NW, image=self.tk_image)
  File "C:\Users\lewka\miniconda3\envs\deep_learning\Lib\tkinter\__init__.py", line 2877, in create_image
    return self._create('image', args, kw)
           ^^^^^^^^^^^^^^^^^^^^^^^^^^^^^^^
  File "C:\Users\lewka\miniconda3\envs\deep_learning\Lib\tkinter\__init__.py", line 2863, in _create
    return self.tk.getint(self.tk.call(
                          ^^^^^^^^^^^^^
_tkinter.TclError: image "pyimage4" doesn't exist
2025-05-31 09:41:40,748 ERROR Error opening project 'authentic logo.json'
Traceback (most recent call last):
  File "c:\Users\lewka\deep_learning\image_labelling\image_labelling\editor.py", line 297, in __init__
    self.load_image(last_image_full_path)                   # Load the image
    ^^^^^^^^^^^^^^^^^^^^^^^^^^^^^^^^^^^^^
  File "c:\Users\lewka\deep_learning\image_labelling\image_labelling\editor.py", line 1094, in load_image
    self.display_image()
  File "c:\Users\lewka\deep_learning\image_labelling\image_labelling\editor.py", line 1175, in display_image
    self.canvas.create_image(0, 0, anchor=tk.NW, image=self.tk_image)
  File "C:\Users\lewka\miniconda3\envs\deep_learning\Lib\tkinter\__init__.py", line 2877, in create_image
    return self._create('image', args, kw)
           ^^^^^^^^^^^^^^^^^^^^^^^^^^^^^^^
  File "C:\Users\lewka\miniconda3\envs\deep_learning\Lib\tkinter\__init__.py", line 2863, in _create
    return self.tk.getint(self.tk.call(
                          ^^^^^^^^^^^^^
_tkinter.TclError: image "pyimage1" doesn't exist

During handling of the above exception, another exception occurred:

Traceback (most recent call last):
  File "c:\Users\lewka\deep_learning\image_labelling\image_labelling\project_manager.py", line 149, in _open_selected_project_action
    self.open_editor(project)
  File "c:\Users\lewka\deep_learning\image_labelling\image_labelling\project_manager.py", line 283, in open_editor
    BoundingBoxEditor(editor_root, project) # Removed splash=splash
    ^^^^^^^^^^^^^^^^^^^^^^^^^^^^^^^^^^^^^^^
  File "c:\Users\lewka\deep_learning\image_labelling\image_labelling\editor.py", line 303, in __init__
    self.load_image(os.path.join(self.folder_path, self.image_files[0]))
  File "c:\Users\lewka\deep_learning\image_labelling\image_labelling\editor.py", line 1094, in load_image
    self.display_image()
  File "c:\Users\lewka\deep_learning\image_labelling\image_labelling\editor.py", line 1175, in display_image
    self.canvas.create_image(0, 0, anchor=tk.NW, image=self.tk_image)
  File "C:\Users\lewka\miniconda3\envs\deep_learning\Lib\tkinter\__init__.py", line 2877, in create_image
    return self._create('image', args, kw)
           ^^^^^^^^^^^^^^^^^^^^^^^^^^^^^^^
  File "C:\Users\lewka\miniconda3\envs\deep_learning\Lib\tkinter\__init__.py", line 2863, in _create
    return self.tk.getint(self.tk.call(
                          ^^^^^^^^^^^^^
_tkinter.TclError: image "pyimage2" doesn't exist
2025-05-31 09:41:40,756 ERROR Exception in Tkinter callback
Traceback (most recent call last):
  File "c:\Users\lewka\deep_learning\image_labelling\image_labelling\editor.py", line 297, in __init__
    self.load_image(last_image_full_path)                   # Load the image
    ^^^^^^^^^^^^^^^^^^^^^^^^^^^^^^^^^^^^^
  File "c:\Users\lewka\deep_learning\image_labelling\image_labelling\editor.py", line 1094, in load_image
    self.display_image()
  File "c:\Users\lewka\deep_learning\image_labelling\image_labelling\editor.py", line 1175, in display_image
    self.canvas.create_image(0, 0, anchor=tk.NW, image=self.tk_image)
  File "C:\Users\lewka\miniconda3\envs\deep_learning\Lib\tkinter\__init__.py", line 2877, in create_image
    return self._create('image', args, kw)
           ^^^^^^^^^^^^^^^^^^^^^^^^^^^^^^^
  File "C:\Users\lewka\miniconda3\envs\deep_learning\Lib\tkinter\__init__.py", line 2863, in _create
    return self.tk.getint(self.tk.call(
                          ^^^^^^^^^^^^^
_tkinter.TclError: image "pyimage1" doesn't exist

During handling of the above exception, another exception occurred:

Traceback (most recent call last):
  File "c:\Users\lewka\deep_learning\image_labelling\image_labelling\project_manager.py", line 149, in _open_selected_project_action
    self.open_editor(project)
  File "c:\Users\lewka\deep_learning\image_labelling\image_labelling\project_manager.py", line 283, in open_editor
    BoundingBoxEditor(editor_root, project) # Removed splash=splash
    ^^^^^^^^^^^^^^^^^^^^^^^^^^^^^^^^^^^^^^^
  File "c:\Users\lewka\deep_learning\image_labelling\image_labelling\editor.py", line 303, in __init__
    self.load_image(os.path.join(self.folder_path, self.image_files[0]))
  File "c:\Users\lewka\deep_learning\image_labelling\image_labelling\editor.py", line 1094, in load_image
    self.display_image()
  File "c:\Users\lewka\deep_learning\image_labelling\image_labelling\editor.py", line 1175, in display_image
    self.canvas.create_image(0, 0, anchor=tk.NW, image=self.tk_image)
  File "C:\Users\lewka\miniconda3\envs\deep_learning\Lib\tkinter\__init__.py", line 2877, in create_image
    return self._create('image', args, kw)
           ^^^^^^^^^^^^^^^^^^^^^^^^^^^^^^^
  File "C:\Users\lewka\miniconda3\envs\deep_learning\Lib\tkinter\__init__.py", line 2863, in _create
    return self.tk.getint(self.tk.call(
                          ^^^^^^^^^^^^^
_tkinter.TclError: image "pyimage2" doesn't exist

During handling of the above exception, another exception occurred:

Traceback (most recent call last):
  File "C:\Users\lewka\miniconda3\envs\deep_learning\Lib\tkinter\__init__.py", line 1968, in __call__
    return self.func(*args)
           ^^^^^^^^^^^^^^^^
  File "c:\Users\lewka\deep_learning\image_labelling\image_labelling\editor.py", line 1047, in on_image_select
    self.load_image(image_path)
  File "c:\Users\lewka\deep_learning\image_labelling\image_labelling\editor.py", line 1094, in load_image
    self.display_image()
  File "c:\Users\lewka\deep_learning\image_labelling\image_labelling\editor.py", line 1175, in display_image
    self.canvas.create_image(0, 0, anchor=tk.NW, image=self.tk_image)
  File "C:\Users\lewka\miniconda3\envs\deep_learning\Lib\tkinter\__init__.py", line 2877, in create_image
    return self._create('image', args, kw)
           ^^^^^^^^^^^^^^^^^^^^^^^^^^^^^^^
  File "C:\Users\lewka\miniconda3\envs\deep_learning\Lib\tkinter\__init__.py", line 2863, in _create
    return self.tk.getint(self.tk.call(
                          ^^^^^^^^^^^^^
_tkinter.TclError: image "pyimage3" doesn't exist
2025-05-31 09:41:40,828 ERROR Exception in Tkinter callback
Traceback (most recent call last):
  File "c:\Users\lewka\deep_learning\image_labelling\image_labelling\editor.py", line 297, in __init__
    self.load_image(last_image_full_path)                   # Load the image
    ^^^^^^^^^^^^^^^^^^^^^^^^^^^^^^^^^^^^^
  File "c:\Users\lewka\deep_learning\image_labelling\image_labelling\editor.py", line 1094, in load_image
    self.display_image()
  File "c:\Users\lewka\deep_learning\image_labelling\image_labelling\editor.py", line 1175, in display_image
    self.canvas.create_image(0, 0, anchor=tk.NW, image=self.tk_image)
  File "C:\Users\lewka\miniconda3\envs\deep_learning\Lib\tkinter\__init__.py", line 2877, in create_image
    return self._create('image', args, kw)
           ^^^^^^^^^^^^^^^^^^^^^^^^^^^^^^^
  File "C:\Users\lewka\miniconda3\envs\deep_learning\Lib\tkinter\__init__.py", line 2863, in _create
    return self.tk.getint(self.tk.call(
                          ^^^^^^^^^^^^^
_tkinter.TclError: image "pyimage1" doesn't exist

During handling of the above exception, another exception occurred:

Traceback (most recent call last):
  File "c:\Users\lewka\deep_learning\image_labelling\image_labelling\project_manager.py", line 149, in _open_selected_project_action
    self.open_editor(project)
  File "c:\Users\lewka\deep_learning\image_labelling\image_labelling\project_manager.py", line 283, in open_editor
    BoundingBoxEditor(editor_root, project) # Removed splash=splash
    ^^^^^^^^^^^^^^^^^^^^^^^^^^^^^^^^^^^^^^^
  File "c:\Users\lewka\deep_learning\image_labelling\image_labelling\editor.py", line 303, in __init__
    self.load_image(os.path.join(self.folder_path, self.image_files[0]))
  File "c:\Users\lewka\deep_learning\image_labelling\image_labelling\editor.py", line 1094, in load_image
    self.display_image()
  File "c:\Users\lewka\deep_learning\image_labelling\image_labelling\editor.py", line 1175, in display_image
    self.canvas.create_image(0, 0, anchor=tk.NW, image=self.tk_image)
  File "C:\Users\lewka\miniconda3\envs\deep_learning\Lib\tkinter\__init__.py", line 2877, in create_image
    return self._create('image', args, kw)
           ^^^^^^^^^^^^^^^^^^^^^^^^^^^^^^^
  File "C:\Users\lewka\miniconda3\envs\deep_learning\Lib\tkinter\__init__.py", line 2863, in _create
    return self.tk.getint(self.tk.call(
                          ^^^^^^^^^^^^^
_tkinter.TclError: image "pyimage2" doesn't exist

During handling of the above exception, another exception occurred:

Traceback (most recent call last):
  File "C:\Users\lewka\miniconda3\envs\deep_learning\Lib\tkinter\__init__.py", line 1968, in __call__
    return self.func(*args)
           ^^^^^^^^^^^^^^^^
  File "c:\Users\lewka\deep_learning\image_labelling\image_labelling\editor.py", line 1047, in on_image_select
    self.load_image(image_path)
  File "c:\Users\lewka\deep_learning\image_labelling\image_labelling\editor.py", line 1094, in load_image
    self.display_image()
  File "c:\Users\lewka\deep_learning\image_labelling\image_labelling\editor.py", line 1175, in display_image
    self.canvas.create_image(0, 0, anchor=tk.NW, image=self.tk_image)
  File "C:\Users\lewka\miniconda3\envs\deep_learning\Lib\tkinter\__init__.py", line 2877, in create_image
    return self._create('image', args, kw)
           ^^^^^^^^^^^^^^^^^^^^^^^^^^^^^^^
  File "C:\Users\lewka\miniconda3\envs\deep_learning\Lib\tkinter\__init__.py", line 2863, in _create
    return self.tk.getint(self.tk.call(
                          ^^^^^^^^^^^^^
_tkinter.TclError: image "pyimage3" doesn't exist

During handling of the above exception, another exception occurred:

Traceback (most recent call last):
  File "C:\Users\lewka\miniconda3\envs\deep_learning\Lib\tkinter\__init__.py", line 1968, in __call__
    return self.func(*args)
           ^^^^^^^^^^^^^^^^
  File "c:\Users\lewka\deep_learning\image_labelling\image_labelling\editor.py", line 1614, in on_canvas_resize
    self.display_image()
  File "c:\Users\lewka\deep_learning\image_labelling\image_labelling\editor.py", line 1175, in display_image
    self.canvas.create_image(0, 0, anchor=tk.NW, image=self.tk_image)
  File "C:\Users\lewka\miniconda3\envs\deep_learning\Lib\tkinter\__init__.py", line 2877, in create_image
    return self._create('image', args, kw)
           ^^^^^^^^^^^^^^^^^^^^^^^^^^^^^^^
  File "C:\Users\lewka\miniconda3\envs\deep_learning\Lib\tkinter\__init__.py", line 2863, in _create
    return self.tk.getint(self.tk.call(
                          ^^^^^^^^^^^^^
_tkinter.TclError: image "pyimage4" doesn't exist
2025-05-31 09:52:09,504 ERROR Failed to create BoundingBoxEditor
Traceback (most recent call last):
  File "c:\Users\lewka\deep_learning\image_labelling\image_labelling\editor.py", line 297, in __init__
    self.load_image(last_image_full_path)                   # Load the image
    ^^^^^^^^^^^^^^^^^^^^^^^^^^^^^^^^^^^^^
  File "c:\Users\lewka\deep_learning\image_labelling\image_labelling\editor.py", line 1094, in load_image
    self.display_image()
  File "c:\Users\lewka\deep_learning\image_labelling\image_labelling\editor.py", line 1175, in display_image
    self.canvas.create_image(0, 0, anchor=tk.NW, image=self.tk_image)
  File "C:\Users\lewka\miniconda3\envs\deep_learning\Lib\tkinter\__init__.py", line 2877, in create_image
    return self._create('image', args, kw)
           ^^^^^^^^^^^^^^^^^^^^^^^^^^^^^^^
  File "C:\Users\lewka\miniconda3\envs\deep_learning\Lib\tkinter\__init__.py", line 2863, in _create
    return self.tk.getint(self.tk.call(
                          ^^^^^^^^^^^^^
_tkinter.TclError: image "pyimage1" doesn't exist

During handling of the above exception, another exception occurred:

Traceback (most recent call last):
  File "c:\Users\lewka\deep_learning\image_labelling\image_labelling\project_manager.py", line 268, in open_editor
    editor = BoundingBoxEditor(editor_root, project)
             ^^^^^^^^^^^^^^^^^^^^^^^^^^^^^^^^^^^^^^^
  File "c:\Users\lewka\deep_learning\image_labelling\image_labelling\editor.py", line 303, in __init__
    self.load_image(os.path.join(self.folder_path, self.image_files[0]))
  File "c:\Users\lewka\deep_learning\image_labelling\image_labelling\editor.py", line 1094, in load_image
    self.display_image()
  File "c:\Users\lewka\deep_learning\image_labelling\image_labelling\editor.py", line 1175, in display_image
    self.canvas.create_image(0, 0, anchor=tk.NW, image=self.tk_image)
  File "C:\Users\lewka\miniconda3\envs\deep_learning\Lib\tkinter\__init__.py", line 2877, in create_image
    return self._create('image', args, kw)
           ^^^^^^^^^^^^^^^^^^^^^^^^^^^^^^^
  File "C:\Users\lewka\miniconda3\envs\deep_learning\Lib\tkinter\__init__.py", line 2863, in _create
    return self.tk.getint(self.tk.call(
                          ^^^^^^^^^^^^^
_tkinter.TclError: image "pyimage2" doesn't exist
2025-05-31 09:52:26,955 ERROR Failed to create BoundingBoxEditor
Traceback (most recent call last):
  File "c:\Users\lewka\deep_learning\image_labelling\image_labelling\editor.py", line 297, in __init__
    self.load_image(last_image_full_path)                   # Load the image
    ^^^^^^^^^^^^^^^^^^^^^^^^^^^^^^^^^^^^^
  File "c:\Users\lewka\deep_learning\image_labelling\image_labelling\editor.py", line 1094, in load_image
    self.display_image()
  File "c:\Users\lewka\deep_learning\image_labelling\image_labelling\editor.py", line 1175, in display_image
    self.canvas.create_image(0, 0, anchor=tk.NW, image=self.tk_image)
  File "C:\Users\lewka\miniconda3\envs\deep_learning\Lib\tkinter\__init__.py", line 2877, in create_image
    return self._create('image', args, kw)
           ^^^^^^^^^^^^^^^^^^^^^^^^^^^^^^^
  File "C:\Users\lewka\miniconda3\envs\deep_learning\Lib\tkinter\__init__.py", line 2863, in _create
    return self.tk.getint(self.tk.call(
                          ^^^^^^^^^^^^^
_tkinter.TclError: image "pyimage1" doesn't exist

During handling of the above exception, another exception occurred:

Traceback (most recent call last):
  File "c:\Users\lewka\deep_learning\image_labelling\image_labelling\project_manager.py", line 268, in open_editor
    editor = BoundingBoxEditor(editor_root, project)
             ^^^^^^^^^^^^^^^^^^^^^^^^^^^^^^^^^^^^^^^
  File "c:\Users\lewka\deep_learning\image_labelling\image_labelling\editor.py", line 303, in __init__
    self.load_image(os.path.join(self.folder_path, self.image_files[0]))
  File "c:\Users\lewka\deep_learning\image_labelling\image_labelling\editor.py", line 1094, in load_image
    self.display_image()
  File "c:\Users\lewka\deep_learning\image_labelling\image_labelling\editor.py", line 1175, in display_image
    self.canvas.create_image(0, 0, anchor=tk.NW, image=self.tk_image)
  File "C:\Users\lewka\miniconda3\envs\deep_learning\Lib\tkinter\__init__.py", line 2877, in create_image
    return self._create('image', args, kw)
           ^^^^^^^^^^^^^^^^^^^^^^^^^^^^^^^
  File "C:\Users\lewka\miniconda3\envs\deep_learning\Lib\tkinter\__init__.py", line 2863, in _create
    return self.tk.getint(self.tk.call(
                          ^^^^^^^^^^^^^
_tkinter.TclError: image "pyimage2" doesn't exist
2025-05-31 18:49:58,680 ERROR Failed to create BoundingBoxEditor
Traceback (most recent call last):
  File "c:\Users\lewka\deep_learning\image_labelling\image_labelling\editor.py", line 152, in __init__
    self.load_image(last_image_full_path)                   # Load the image
    ^^^^^^^^^^^^^^^^^^^^^^^^^^^^^^^^^^^^^
  File "c:\Users\lewka\deep_learning\image_labelling\image_labelling\editor.py", line 950, in load_image
    self.display_image()
  File "c:\Users\lewka\deep_learning\image_labelling\image_labelling\editor.py", line 1033, in display_image
    self.canvas.create_image(0, 0, anchor=tk.NW, image=self.tk_image)
  File "C:\Users\lewka\miniconda3\envs\deep_learning\Lib\tkinter\__init__.py", line 2877, in create_image
    return self._create('image', args, kw)
           ^^^^^^^^^^^^^^^^^^^^^^^^^^^^^^^
  File "C:\Users\lewka\miniconda3\envs\deep_learning\Lib\tkinter\__init__.py", line 2863, in _create
    return self.tk.getint(self.tk.call(
                          ^^^^^^^^^^^^^
_tkinter.TclError: image "pyimage1" doesn't exist

During handling of the above exception, another exception occurred:

Traceback (most recent call last):
  File "c:\Users\lewka\deep_learning\image_labelling\image_labelling\project_manager.py", line 268, in open_editor
    editor = BoundingBoxEditor(editor_root, project)
             ^^^^^^^^^^^^^^^^^^^^^^^^^^^^^^^^^^^^^^^
  File "c:\Users\lewka\deep_learning\image_labelling\image_labelling\editor.py", line 158, in __init__
    self.load_image(os.path.join(self.folder_path, self.image_files[0]))
  File "c:\Users\lewka\deep_learning\image_labelling\image_labelling\editor.py", line 950, in load_image
    self.display_image()
  File "c:\Users\lewka\deep_learning\image_labelling\image_labelling\editor.py", line 1033, in display_image
    self.canvas.create_image(0, 0, anchor=tk.NW, image=self.tk_image)
  File "C:\Users\lewka\miniconda3\envs\deep_learning\Lib\tkinter\__init__.py", line 2877, in create_image
    return self._create('image', args, kw)
           ^^^^^^^^^^^^^^^^^^^^^^^^^^^^^^^
  File "C:\Users\lewka\miniconda3\envs\deep_learning\Lib\tkinter\__init__.py", line 2863, in _create
    return self.tk.getint(self.tk.call(
                          ^^^^^^^^^^^^^
_tkinter.TclError: image "pyimage2" doesn't exist
2025-05-31 18:50:01,959 ERROR Failed to create BoundingBoxEditor
Traceback (most recent call last):
  File "c:\Users\lewka\deep_learning\image_labelling\image_labelling\editor.py", line 152, in __init__
    self.load_image(last_image_full_path)                   # Load the image
    ^^^^^^^^^^^^^^^^^^^^^^^^^^^^^^^^^^^^^
  File "c:\Users\lewka\deep_learning\image_labelling\image_labelling\editor.py", line 950, in load_image
    self.display_image()
  File "c:\Users\lewka\deep_learning\image_labelling\image_labelling\editor.py", line 1033, in display_image
    self.canvas.create_image(0, 0, anchor=tk.NW, image=self.tk_image)
  File "C:\Users\lewka\miniconda3\envs\deep_learning\Lib\tkinter\__init__.py", line 2877, in create_image
    return self._create('image', args, kw)
           ^^^^^^^^^^^^^^^^^^^^^^^^^^^^^^^
  File "C:\Users\lewka\miniconda3\envs\deep_learning\Lib\tkinter\__init__.py", line 2863, in _create
    return self.tk.getint(self.tk.call(
                          ^^^^^^^^^^^^^
_tkinter.TclError: image "pyimage3" doesn't exist

During handling of the above exception, another exception occurred:

Traceback (most recent call last):
  File "c:\Users\lewka\deep_learning\image_labelling\image_labelling\project_manager.py", line 268, in open_editor
    editor = BoundingBoxEditor(editor_root, project)
             ^^^^^^^^^^^^^^^^^^^^^^^^^^^^^^^^^^^^^^^
  File "c:\Users\lewka\deep_learning\image_labelling\image_labelling\editor.py", line 158, in __init__
    self.load_image(os.path.join(self.folder_path, self.image_files[0]))
  File "c:\Users\lewka\deep_learning\image_labelling\image_labelling\editor.py", line 950, in load_image
    self.display_image()
  File "c:\Users\lewka\deep_learning\image_labelling\image_labelling\editor.py", line 1033, in display_image
    self.canvas.create_image(0, 0, anchor=tk.NW, image=self.tk_image)
  File "C:\Users\lewka\miniconda3\envs\deep_learning\Lib\tkinter\__init__.py", line 2877, in create_image
    return self._create('image', args, kw)
           ^^^^^^^^^^^^^^^^^^^^^^^^^^^^^^^
  File "C:\Users\lewka\miniconda3\envs\deep_learning\Lib\tkinter\__init__.py", line 2863, in _create
    return self.tk.getint(self.tk.call(
                          ^^^^^^^^^^^^^
_tkinter.TclError: image "pyimage4" doesn't exist
2025-05-31 18:51:58,202 ERROR Failed to create or run BoundingBoxEditor
Traceback (most recent call last):
  File "c:\Users\lewka\deep_learning\image_labelling\image_labelling\editor.py", line 152, in __init__
    self.load_image(last_image_full_path)                   # Load the image
    ^^^^^^^^^^^^^^^^^^^^^^^^^^^^^^^^^^^^^
  File "c:\Users\lewka\deep_learning\image_labelling\image_labelling\editor.py", line 950, in load_image
    self.display_image()
  File "c:\Users\lewka\deep_learning\image_labelling\image_labelling\editor.py", line 1033, in display_image
    self.canvas.create_image(0, 0, anchor=tk.NW, image=self.tk_image)
  File "C:\Users\lewka\miniconda3\envs\deep_learning\Lib\tkinter\__init__.py", line 2877, in create_image
    return self._create('image', args, kw)
           ^^^^^^^^^^^^^^^^^^^^^^^^^^^^^^^
  File "C:\Users\lewka\miniconda3\envs\deep_learning\Lib\tkinter\__init__.py", line 2863, in _create
    return self.tk.getint(self.tk.call(
                          ^^^^^^^^^^^^^
_tkinter.TclError: image "pyimage1" doesn't exist

During handling of the above exception, another exception occurred:

Traceback (most recent call last):
  File "c:\Users\lewka\deep_learning\image_labelling\image_labelling\project_manager.py", line 274, in open_editor
    editor = BoundingBoxEditor(editor_root, project)
            ^^^^^^^^^^^^^^^^^^^^^^^^^^^^^^^^^^^^^^^
  File "c:\Users\lewka\deep_learning\image_labelling\image_labelling\editor.py", line 158, in __init__
    self.load_image(os.path.join(self.folder_path, self.image_files[0]))
  File "c:\Users\lewka\deep_learning\image_labelling\image_labelling\editor.py", line 950, in load_image
    self.display_image()
  File "c:\Users\lewka\deep_learning\image_labelling\image_labelling\editor.py", line 1033, in display_image
    self.canvas.create_image(0, 0, anchor=tk.NW, image=self.tk_image)
  File "C:\Users\lewka\miniconda3\envs\deep_learning\Lib\tkinter\__init__.py", line 2877, in create_image
    return self._create('image', args, kw)
           ^^^^^^^^^^^^^^^^^^^^^^^^^^^^^^^
  File "C:\Users\lewka\miniconda3\envs\deep_learning\Lib\tkinter\__init__.py", line 2863, in _create
    return self.tk.getint(self.tk.call(
                          ^^^^^^^^^^^^^
_tkinter.TclError: image "pyimage2" doesn't exist
2025-05-31 18:55:46,786 ERROR Exception in Tkinter callback
Traceback (most recent call last):
  File "C:\Users\lewka\miniconda3\envs\deep_learning\Lib\tkinter\__init__.py", line 1968, in __call__
    return self.func(*args)
           ^^^^^^^^^^^^^^^^
  File "c:\Users\lewka\deep_learning\image_labelling\image_labelling\editor.py", line 920, in on_image_select
    self.load_image(image_path)
  File "c:\Users\lewka\deep_learning\image_labelling\image_labelling\editor.py", line 968, in load_image
    self.display_image()
  File "c:\Users\lewka\deep_learning\image_labelling\image_labelling\editor.py", line 1051, in display_image
    self.canvas.create_image(0, 0, anchor=tk.NW, image=self.tk_image)
  File "C:\Users\lewka\miniconda3\envs\deep_learning\Lib\tkinter\__init__.py", line 2877, in create_image
    return self._create('image', args, kw)
           ^^^^^^^^^^^^^^^^^^^^^^^^^^^^^^^
  File "C:\Users\lewka\miniconda3\envs\deep_learning\Lib\tkinter\__init__.py", line 2863, in _create
    return self.tk.getint(self.tk.call(
                          ^^^^^^^^^^^^^
_tkinter.TclError: image "pyimage3" doesn't exist
2025-05-31 18:55:46,796 ERROR Exception in Tkinter callback
Traceback (most recent call last):
  File "C:\Users\lewka\miniconda3\envs\deep_learning\Lib\tkinter\__init__.py", line 1968, in __call__
    return self.func(*args)
           ^^^^^^^^^^^^^^^^
  File "c:\Users\lewka\deep_learning\image_labelling\image_labelling\editor.py", line 920, in on_image_select
    self.load_image(image_path)
  File "c:\Users\lewka\deep_learning\image_labelling\image_labelling\editor.py", line 968, in load_image
    self.display_image()
  File "c:\Users\lewka\deep_learning\image_labelling\image_labelling\editor.py", line 1051, in display_image
    self.canvas.create_image(0, 0, anchor=tk.NW, image=self.tk_image)
  File "C:\Users\lewka\miniconda3\envs\deep_learning\Lib\tkinter\__init__.py", line 2877, in create_image
    return self._create('image', args, kw)
           ^^^^^^^^^^^^^^^^^^^^^^^^^^^^^^^
  File "C:\Users\lewka\miniconda3\envs\deep_learning\Lib\tkinter\__init__.py", line 2863, in _create
    return self.tk.getint(self.tk.call(
                          ^^^^^^^^^^^^^
_tkinter.TclError: image "pyimage3" doesn't exist

During handling of the above exception, another exception occurred:

Traceback (most recent call last):
  File "C:\Users\lewka\miniconda3\envs\deep_learning\Lib\tkinter\__init__.py", line 1968, in __call__
    return self.func(*args)
           ^^^^^^^^^^^^^^^^
  File "c:\Users\lewka\deep_learning\image_labelling\image_labelling\editor.py", line 920, in on_image_select
    self.load_image(image_path)
  File "c:\Users\lewka\deep_learning\image_labelling\image_labelling\editor.py", line 968, in load_image
    self.display_image()
  File "c:\Users\lewka\deep_learning\image_labelling\image_labelling\editor.py", line 1051, in display_image
    self.canvas.create_image(0, 0, anchor=tk.NW, image=self.tk_image)
  File "C:\Users\lewka\miniconda3\envs\deep_learning\Lib\tkinter\__init__.py", line 2877, in create_image
    return self._create('image', args, kw)
           ^^^^^^^^^^^^^^^^^^^^^^^^^^^^^^^
  File "C:\Users\lewka\miniconda3\envs\deep_learning\Lib\tkinter\__init__.py", line 2863, in _create
    return self.tk.getint(self.tk.call(
                          ^^^^^^^^^^^^^
_tkinter.TclError: image "pyimage4" doesn't exist
2025-05-31 18:55:46,866 ERROR Exception in Tkinter callback
Traceback (most recent call last):
  File "C:\Users\lewka\miniconda3\envs\deep_learning\Lib\tkinter\__init__.py", line 1968, in __call__
    return self.func(*args)
           ^^^^^^^^^^^^^^^^
  File "c:\Users\lewka\deep_learning\image_labelling\image_labelling\editor.py", line 920, in on_image_select
    self.load_image(image_path)
  File "c:\Users\lewka\deep_learning\image_labelling\image_labelling\editor.py", line 968, in load_image
    self.display_image()
  File "c:\Users\lewka\deep_learning\image_labelling\image_labelling\editor.py", line 1051, in display_image
    self.canvas.create_image(0, 0, anchor=tk.NW, image=self.tk_image)
  File "C:\Users\lewka\miniconda3\envs\deep_learning\Lib\tkinter\__init__.py", line 2877, in create_image
    return self._create('image', args, kw)
           ^^^^^^^^^^^^^^^^^^^^^^^^^^^^^^^
  File "C:\Users\lewka\miniconda3\envs\deep_learning\Lib\tkinter\__init__.py", line 2863, in _create
    return self.tk.getint(self.tk.call(
                          ^^^^^^^^^^^^^
_tkinter.TclError: image "pyimage3" doesn't exist

During handling of the above exception, another exception occurred:

Traceback (most recent call last):
  File "C:\Users\lewka\miniconda3\envs\deep_learning\Lib\tkinter\__init__.py", line 1968, in __call__
    return self.func(*args)
           ^^^^^^^^^^^^^^^^
  File "c:\Users\lewka\deep_learning\image_labelling\image_labelling\editor.py", line 920, in on_image_select
    self.load_image(image_path)
  File "c:\Users\lewka\deep_learning\image_labelling\image_labelling\editor.py", line 968, in load_image
    self.display_image()
  File "c:\Users\lewka\deep_learning\image_labelling\image_labelling\editor.py", line 1051, in display_image
    self.canvas.create_image(0, 0, anchor=tk.NW, image=self.tk_image)
  File "C:\Users\lewka\miniconda3\envs\deep_learning\Lib\tkinter\__init__.py", line 2877, in create_image
    return self._create('image', args, kw)
           ^^^^^^^^^^^^^^^^^^^^^^^^^^^^^^^
  File "C:\Users\lewka\miniconda3\envs\deep_learning\Lib\tkinter\__init__.py", line 2863, in _create
    return self.tk.getint(self.tk.call(
                          ^^^^^^^^^^^^^
_tkinter.TclError: image "pyimage4" doesn't exist

During handling of the above exception, another exception occurred:

Traceback (most recent call last):
  File "C:\Users\lewka\miniconda3\envs\deep_learning\Lib\tkinter\__init__.py", line 1968, in __call__
    return self.func(*args)
           ^^^^^^^^^^^^^^^^
  File "c:\Users\lewka\deep_learning\image_labelling\image_labelling\editor.py", line 1491, in on_canvas_resize
    self.display_image()
  File "c:\Users\lewka\deep_learning\image_labelling\image_labelling\editor.py", line 1051, in display_image
    self.canvas.create_image(0, 0, anchor=tk.NW, image=self.tk_image)
  File "C:\Users\lewka\miniconda3\envs\deep_learning\Lib\tkinter\__init__.py", line 2877, in create_image
    return self._create('image', args, kw)
           ^^^^^^^^^^^^^^^^^^^^^^^^^^^^^^^
  File "C:\Users\lewka\miniconda3\envs\deep_learning\Lib\tkinter\__init__.py", line 2863, in _create
    return self.tk.getint(self.tk.call(
                          ^^^^^^^^^^^^^
_tkinter.TclError: image "pyimage5" doesn't exist
2025-05-31 18:56:10,535 ERROR Error opening project authentic logo.json
Traceback (most recent call last):
  File "c:\Users\lewka\deep_learning\image_labelling\image_labelling\project_manager.py", line 146, in _open_selected_project_action
    self.root.destroy()
  File "C:\Users\lewka\miniconda3\envs\deep_learning\Lib\tkinter\__init__.py", line 2390, in destroy
    self.tk.call('destroy', self._w)
_tkinter.TclError: can't invoke "destroy" command: application has been destroyed
2025-05-31 20:35:00,484 ERROR Exception in Tkinter callback
Traceback (most recent call last):
  File "C:\Users\lewka\miniconda3\envs\deep_learning\Lib\tkinter\__init__.py", line 1968, in __call__
    return self.func(*args)
           ^^^^^^^^^^^^^^^^
  File "c:\Users\lewka\deep_learning\image_labelling\image_labelling\editor.py", line 1253, in on_click
    self.draw_current_polygon_drawing()
  File "c:\Users\lewka\deep_learning\image_labelling\image_labelling\editor.py", line 1448, in draw_current_polygon_drawing
    line_id = self.canvas.create_line(coords, fill="red", width=2, tags="current_polygon_line")
              ^^^^^^^^^^^^^^^^^^^^^^^^^^^^^^^^^^^^^^^^^^^^^^^^^^^^^^^^^^^^^^^^^^^^^^^^^^^^^^^^^
  File "C:\Users\lewka\miniconda3\envs\deep_learning\Lib\tkinter\__init__.py", line 2881, in create_line
    return self._create('line', args, kw)
           ^^^^^^^^^^^^^^^^^^^^^^^^^^^^^^
  File "C:\Users\lewka\miniconda3\envs\deep_learning\Lib\tkinter\__init__.py", line 2863, in _create
    return self.tk.getint(self.tk.call(
                          ^^^^^^^^^^^^^
_tkinter.TclError: wrong # coordinates: expected at least 4, got 2
2025-05-31 20:35:04,741 ERROR Exception in Tkinter callback
Traceback (most recent call last):
  File "C:\Users\lewka\miniconda3\envs\deep_learning\Lib\tkinter\__init__.py", line 1968, in __call__
    return self.func(*args)
           ^^^^^^^^^^^^^^^^
  File "c:\Users\lewka\deep_learning\image_labelling\image_labelling\editor.py", line 1253, in on_click
    self.draw_current_polygon_drawing()
  File "c:\Users\lewka\deep_learning\image_labelling\image_labelling\editor.py", line 1448, in draw_current_polygon_drawing
    line_id = self.canvas.create_line(coords, fill="red", width=2, tags="current_polygon_line")
              ^^^^^^^^^^^^^^^^^^^^^^^^^^^^^^^^^^^^^^^^^^^^^^^^^^^^^^^^^^^^^^^^^^^^^^^^^^^^^^^^^
  File "C:\Users\lewka\miniconda3\envs\deep_learning\Lib\tkinter\__init__.py", line 2881, in create_line
    return self._create('line', args, kw)
           ^^^^^^^^^^^^^^^^^^^^^^^^^^^^^^
  File "C:\Users\lewka\miniconda3\envs\deep_learning\Lib\tkinter\__init__.py", line 2863, in _create
    return self.tk.getint(self.tk.call(
                          ^^^^^^^^^^^^^
_tkinter.TclError: wrong # coordinates: expected at least 4, got 2
2025-05-31 20:35:11,197 ERROR Exception in Tkinter callback
Traceback (most recent call last):
  File "C:\Users\lewka\miniconda3\envs\deep_learning\Lib\tkinter\__init__.py", line 1968, in __call__
    return self.func(*args)
           ^^^^^^^^^^^^^^^^
  File "c:\Users\lewka\deep_learning\image_labelling\image_labelling\editor.py", line 1253, in on_click
    self.draw_current_polygon_drawing()
  File "c:\Users\lewka\deep_learning\image_labelling\image_labelling\editor.py", line 1448, in draw_current_polygon_drawing
    line_id = self.canvas.create_line(coords, fill="red", width=2, tags="current_polygon_line")
              ^^^^^^^^^^^^^^^^^^^^^^^^^^^^^^^^^^^^^^^^^^^^^^^^^^^^^^^^^^^^^^^^^^^^^^^^^^^^^^^^^
  File "C:\Users\lewka\miniconda3\envs\deep_learning\Lib\tkinter\__init__.py", line 2881, in create_line
    return self._create('line', args, kw)
           ^^^^^^^^^^^^^^^^^^^^^^^^^^^^^^
  File "C:\Users\lewka\miniconda3\envs\deep_learning\Lib\tkinter\__init__.py", line 2863, in _create
    return self.tk.getint(self.tk.call(
                          ^^^^^^^^^^^^^
_tkinter.TclError: wrong # coordinates: expected at least 4, got 2
2025-05-31 20:35:12,001 ERROR Exception in Tkinter callback
Traceback (most recent call last):
  File "C:\Users\lewka\miniconda3\envs\deep_learning\Lib\tkinter\__init__.py", line 1968, in __call__
    return self.func(*args)
           ^^^^^^^^^^^^^^^^
  File "c:\Users\lewka\deep_learning\image_labelling\image_labelling\editor.py", line 1253, in on_click
    self.draw_current_polygon_drawing()
  File "c:\Users\lewka\deep_learning\image_labelling\image_labelling\editor.py", line 1448, in draw_current_polygon_drawing
    line_id = self.canvas.create_line(coords, fill="red", width=2, tags="current_polygon_line")
              ^^^^^^^^^^^^^^^^^^^^^^^^^^^^^^^^^^^^^^^^^^^^^^^^^^^^^^^^^^^^^^^^^^^^^^^^^^^^^^^^^
  File "C:\Users\lewka\miniconda3\envs\deep_learning\Lib\tkinter\__init__.py", line 2881, in create_line
    return self._create('line', args, kw)
           ^^^^^^^^^^^^^^^^^^^^^^^^^^^^^^
  File "C:\Users\lewka\miniconda3\envs\deep_learning\Lib\tkinter\__init__.py", line 2863, in _create
    return self.tk.getint(self.tk.call(
                          ^^^^^^^^^^^^^
_tkinter.TclError: wrong # coordinates: expected at least 4, got 2
2025-05-31 20:53:23,452 ERROR Failed to create or run BoundingBoxEditor
Traceback (most recent call last):
  File "c:\Users\lewka\deep_learning\image_labelling\image_labelling\project_manager.py", line 281, in open_editor
    editor = BoundingBoxEditor(editor_root, project)
            ^^^^^^^^^^^^^^^^^^^^^^^^^^^^^^^^^^^^^^^
  File "c:\Users\lewka\deep_learning\image_labelling\image_labelling\editor.py", line 86, in __init__
    self.setup_canvas()
  File "c:\Users\lewka\deep_learning\image_labelling\image_labelling\editor.py", line 241, in setup_canvas
    self.canvas.bind("<MouseWheel>", self.on_mouse_wheel)
                                     ^^^^^^^^^^^^^^^^^^^
AttributeError: 'BoundingBoxEditor' object has no attribute 'on_mouse_wheel'
2025-05-31 20:59:57,652 ERROR Failed to create or run BoundingBoxEditor
Traceback (most recent call last):
  File "c:\Users\lewka\deep_learning\image_labelling\image_labelling\project_manager.py", line 281, in open_editor
    editor = BoundingBoxEditor(editor_root, project)
            ^^^^^^^^^^^^^^^^^^^^^^^^^^^^^^^^^^^^^^^
  File "c:\Users\lewka\deep_learning\image_labelling\image_labelling\editor.py", line 86, in __init__
    self.setup_canvas()
  File "c:\Users\lewka\deep_learning\image_labelling\image_labelling\editor.py", line 246, in setup_canvas
    self.canvas.bind("<Button-1>", self.on_click)
                                   ^^^^^^^^^^^^^
AttributeError: 'BoundingBoxEditor' object has no attribute 'on_click'
2025-05-31 21:10:17,482 ERROR Failed to create or run BoundingBoxEditor
Traceback (most recent call last):
  File "c:\Users\lewka\deep_learning\image_labelling\image_labelling\project_manager.py", line 281, in open_editor
    editor = BoundingBoxEditor(editor_root, project)
            ^^^^^^^^^^^^^^^^^^^^^^^^^^^^^^^^^^^^^^^
  File "c:\Users\lewka\deep_learning\image_labelling\image_labelling\editor.py", line 90, in __init__
    self.setup_canvas()
  File "c:\Users\lewka\deep_learning\image_labelling\image_labelling\editor.py", line 243, in setup_canvas
    self.canvas.bind("<Configure>", self.on_canvas_resize)
                                    ^^^^^^^^^^^^^^^^^^^^^
AttributeError: 'BoundingBoxEditor' object has no attribute 'on_canvas_resize'
2025-05-31 21:20:12,602 ERROR Exception in Tkinter callback
Traceback (most recent call last):
  File "C:\Users\lewka\miniconda3\envs\deep_learning\Lib\tkinter\__init__.py", line 1968, in __call__
    return self.func(*args)
           ^^^^^^^^^^^^^^^^
  File "C:\Users\lewka\miniconda3\envs\deep_learning\Lib\tkinter\__init__.py", line 862, in callit
    func(*args)
  File "C:\Users\lewka\deep_learning\image_labelling\image_labelling\editor.py", line 177, in _attempt_load_initial_image
    self.load_image(last_image_full_path)
  File "C:\Users\lewka\deep_learning\image_labelling\image_labelling\editor.py", line 1067, in load_image
    self.display_image()
  File "C:\Users\lewka\deep_learning\image_labelling\image_labelling\editor.py", line 1137, in display_image
    zoomed_img_width = int(self.original_image.width * self.zoom_level)
                           ^^^^^^^^^^^^^^^^^^^^^^^^^
AttributeError: 'numpy.ndarray' object has no attribute 'width'
2025-05-31 21:20:12,609 ERROR Exception in Tkinter callback
Traceback (most recent call last):
  File "C:\Users\lewka\miniconda3\envs\deep_learning\Lib\tkinter\__init__.py", line 1968, in __call__
    return self.func(*args)
           ^^^^^^^^^^^^^^^^
  File "C:\Users\lewka\miniconda3\envs\deep_learning\Lib\tkinter\__init__.py", line 862, in callit
    func(*args)
  File "C:\Users\lewka\deep_learning\image_labelling\image_labelling\editor.py", line 177, in _attempt_load_initial_image
    self.load_image(last_image_full_path)
  File "C:\Users\lewka\deep_learning\image_labelling\image_labelling\editor.py", line 1067, in load_image
    self.display_image()
  File "C:\Users\lewka\deep_learning\image_labelling\image_labelling\editor.py", line 1137, in display_image
    zoomed_img_width = int(self.original_image.width * self.zoom_level)
                           ^^^^^^^^^^^^^^^^^^^^^^^^^
AttributeError: 'numpy.ndarray' object has no attribute 'width'

During handling of the above exception, another exception occurred:

Traceback (most recent call last):
  File "C:\Users\lewka\miniconda3\envs\deep_learning\Lib\tkinter\__init__.py", line 1968, in __call__
    return self.func(*args)
           ^^^^^^^^^^^^^^^^
  File "C:\Users\lewka\deep_learning\image_labelling\image_labelling\editor.py", line 1019, in on_image_select
    self.load_image(image_path)
  File "C:\Users\lewka\deep_learning\image_labelling\image_labelling\editor.py", line 1067, in load_image
    self.display_image()
  File "C:\Users\lewka\deep_learning\image_labelling\image_labelling\editor.py", line 1137, in display_image
    zoomed_img_width = int(self.original_image.width * self.zoom_level)
                           ^^^^^^^^^^^^^^^^^^^^^^^^^
AttributeError: 'numpy.ndarray' object has no attribute 'width'
2025-05-31 21:20:12,680 ERROR Exception in Tkinter callback
Traceback (most recent call last):
  File "C:\Users\lewka\miniconda3\envs\deep_learning\Lib\tkinter\__init__.py", line 1968, in __call__
    return self.func(*args)
           ^^^^^^^^^^^^^^^^
  File "C:\Users\lewka\miniconda3\envs\deep_learning\Lib\tkinter\__init__.py", line 862, in callit
    func(*args)
  File "C:\Users\lewka\deep_learning\image_labelling\image_labelling\editor.py", line 177, in _attempt_load_initial_image
    self.load_image(last_image_full_path)
  File "C:\Users\lewka\deep_learning\image_labelling\image_labelling\editor.py", line 1067, in load_image
    self.display_image()
  File "C:\Users\lewka\deep_learning\image_labelling\image_labelling\editor.py", line 1137, in display_image
    zoomed_img_width = int(self.original_image.width * self.zoom_level)
                           ^^^^^^^^^^^^^^^^^^^^^^^^^
AttributeError: 'numpy.ndarray' object has no attribute 'width'

During handling of the above exception, another exception occurred:

Traceback (most recent call last):
  File "C:\Users\lewka\miniconda3\envs\deep_learning\Lib\tkinter\__init__.py", line 1968, in __call__
    return self.func(*args)
           ^^^^^^^^^^^^^^^^
  File "C:\Users\lewka\deep_learning\image_labelling\image_labelling\editor.py", line 1019, in on_image_select
    self.load_image(image_path)
  File "C:\Users\lewka\deep_learning\image_labelling\image_labelling\editor.py", line 1067, in load_image
    self.display_image()
  File "C:\Users\lewka\deep_learning\image_labelling\image_labelling\editor.py", line 1137, in display_image
    zoomed_img_width = int(self.original_image.width * self.zoom_level)
                           ^^^^^^^^^^^^^^^^^^^^^^^^^
AttributeError: 'numpy.ndarray' object has no attribute 'width'

During handling of the above exception, another exception occurred:

Traceback (most recent call last):
  File "C:\Users\lewka\miniconda3\envs\deep_learning\Lib\tkinter\__init__.py", line 1968, in __call__
    return self.func(*args)
           ^^^^^^^^^^^^^^^^
  File "C:\Users\lewka\deep_learning\image_labelling\image_labelling\editor.py", line 1448, in on_canvas_resize
    Navigates the image list in the given direction (1 for next, -1 for previous).
                                           ^^^^^^^^^^^^^^^^^^^
ValueError: The truth value of an array with more than one element is ambiguous. Use a.any() or a.all()
2025-05-31 21:20:20,654 ERROR Exception in Tkinter callback
Traceback (most recent call last):
  File "C:\Users\lewka\miniconda3\envs\deep_learning\Lib\tkinter\__init__.py", line 1968, in __call__
    return self.func(*args)
           ^^^^^^^^^^^^^^^^
  File "C:\Users\lewka\miniconda3\envs\deep_learning\Lib\tkinter\__init__.py", line 862, in callit
    func(*args)
  File "C:\Users\lewka\deep_learning\image_labelling\image_labelling\editor.py", line 177, in _attempt_load_initial_image
    self.load_image(last_image_full_path)
  File "C:\Users\lewka\deep_learning\image_labelling\image_labelling\editor.py", line 1067, in load_image
    self.display_image()
  File "C:\Users\lewka\deep_learning\image_labelling\image_labelling\editor.py", line 1137, in display_image
    zoomed_img_width = int(self.original_image.width * self.zoom_level)
                           ^^^^^^^^^^^^^^^^^^^^^^^^^
AttributeError: 'numpy.ndarray' object has no attribute 'width'
2025-05-31 21:20:20,667 ERROR Exception in Tkinter callback
Traceback (most recent call last):
  File "C:\Users\lewka\miniconda3\envs\deep_learning\Lib\tkinter\__init__.py", line 1968, in __call__
    return self.func(*args)
           ^^^^^^^^^^^^^^^^
  File "C:\Users\lewka\miniconda3\envs\deep_learning\Lib\tkinter\__init__.py", line 862, in callit
    func(*args)
  File "C:\Users\lewka\deep_learning\image_labelling\image_labelling\editor.py", line 177, in _attempt_load_initial_image
    self.load_image(last_image_full_path)
  File "C:\Users\lewka\deep_learning\image_labelling\image_labelling\editor.py", line 1067, in load_image
    self.display_image()
  File "C:\Users\lewka\deep_learning\image_labelling\image_labelling\editor.py", line 1137, in display_image
    zoomed_img_width = int(self.original_image.width * self.zoom_level)
                           ^^^^^^^^^^^^^^^^^^^^^^^^^
AttributeError: 'numpy.ndarray' object has no attribute 'width'

During handling of the above exception, another exception occurred:

Traceback (most recent call last):
  File "C:\Users\lewka\miniconda3\envs\deep_learning\Lib\tkinter\__init__.py", line 1968, in __call__
    return self.func(*args)
           ^^^^^^^^^^^^^^^^
  File "C:\Users\lewka\deep_learning\image_labelling\image_labelling\editor.py", line 1019, in on_image_select
    self.load_image(image_path)
  File "C:\Users\lewka\deep_learning\image_labelling\image_labelling\editor.py", line 1067, in load_image
    self.display_image()
  File "C:\Users\lewka\deep_learning\image_labelling\image_labelling\editor.py", line 1137, in display_image
    zoomed_img_width = int(self.original_image.width * self.zoom_level)
                           ^^^^^^^^^^^^^^^^^^^^^^^^^
AttributeError: 'numpy.ndarray' object has no attribute 'width'
2025-05-31 21:20:20,771 ERROR Exception in Tkinter callback
Traceback (most recent call last):
  File "C:\Users\lewka\miniconda3\envs\deep_learning\Lib\tkinter\__init__.py", line 1968, in __call__
    return self.func(*args)
           ^^^^^^^^^^^^^^^^
  File "C:\Users\lewka\miniconda3\envs\deep_learning\Lib\tkinter\__init__.py", line 862, in callit
    func(*args)
  File "C:\Users\lewka\deep_learning\image_labelling\image_labelling\editor.py", line 177, in _attempt_load_initial_image
    self.load_image(last_image_full_path)
  File "C:\Users\lewka\deep_learning\image_labelling\image_labelling\editor.py", line 1067, in load_image
    self.display_image()
  File "C:\Users\lewka\deep_learning\image_labelling\image_labelling\editor.py", line 1137, in display_image
    zoomed_img_width = int(self.original_image.width * self.zoom_level)
                           ^^^^^^^^^^^^^^^^^^^^^^^^^
AttributeError: 'numpy.ndarray' object has no attribute 'width'

During handling of the above exception, another exception occurred:

Traceback (most recent call last):
  File "C:\Users\lewka\miniconda3\envs\deep_learning\Lib\tkinter\__init__.py", line 1968, in __call__
    return self.func(*args)
           ^^^^^^^^^^^^^^^^
  File "C:\Users\lewka\deep_learning\image_labelling\image_labelling\editor.py", line 1019, in on_image_select
    self.load_image(image_path)
  File "C:\Users\lewka\deep_learning\image_labelling\image_labelling\editor.py", line 1067, in load_image
    self.display_image()
  File "C:\Users\lewka\deep_learning\image_labelling\image_labelling\editor.py", line 1137, in display_image
    zoomed_img_width = int(self.original_image.width * self.zoom_level)
                           ^^^^^^^^^^^^^^^^^^^^^^^^^
AttributeError: 'numpy.ndarray' object has no attribute 'width'

During handling of the above exception, another exception occurred:

Traceback (most recent call last):
  File "C:\Users\lewka\miniconda3\envs\deep_learning\Lib\tkinter\__init__.py", line 1968, in __call__
    return self.func(*args)
           ^^^^^^^^^^^^^^^^
  File "C:\Users\lewka\deep_learning\image_labelling\image_labelling\editor.py", line 603, in on_canvas_resize
    if hasattr(self, 'original_image') and self.original_image:
                                           ^^^^^^^^^^^^^^^^^^^
ValueError: The truth value of an array with more than one element is ambiguous. Use a.any() or a.all()
2025-05-31 21:20:47,590 ERROR Exception in Tkinter callback
Traceback (most recent call last):
  File "C:\Users\lewka\miniconda3\envs\deep_learning\Lib\tkinter\__init__.py", line 1968, in __call__
    return self.func(*args)
           ^^^^^^^^^^^^^^^^
  File "C:\Users\lewka\miniconda3\envs\deep_learning\Lib\tkinter\__init__.py", line 862, in callit
    func(*args)
  File "c:\Users\lewka\deep_learning\image_labelling\image_labelling\editor.py", line 177, in _attempt_load_initial_image
    self.load_image(last_image_full_path)
  File "c:\Users\lewka\deep_learning\image_labelling\image_labelling\editor.py", line 1067, in load_image
    self.display_image()
  File "c:\Users\lewka\deep_learning\image_labelling\image_labelling\editor.py", line 1137, in display_image
    zoomed_img_width = int(self.original_image.width * self.zoom_level)
                           ^^^^^^^^^^^^^^^^^^^^^^^^^
AttributeError: 'numpy.ndarray' object has no attribute 'width'
2025-05-31 21:20:47,600 ERROR Exception in Tkinter callback
Traceback (most recent call last):
  File "C:\Users\lewka\miniconda3\envs\deep_learning\Lib\tkinter\__init__.py", line 1968, in __call__
    return self.func(*args)
           ^^^^^^^^^^^^^^^^
  File "C:\Users\lewka\miniconda3\envs\deep_learning\Lib\tkinter\__init__.py", line 862, in callit
    func(*args)
  File "c:\Users\lewka\deep_learning\image_labelling\image_labelling\editor.py", line 177, in _attempt_load_initial_image
    self.load_image(last_image_full_path)
  File "c:\Users\lewka\deep_learning\image_labelling\image_labelling\editor.py", line 1067, in load_image
    self.display_image()
  File "c:\Users\lewka\deep_learning\image_labelling\image_labelling\editor.py", line 1137, in display_image
    zoomed_img_width = int(self.original_image.width * self.zoom_level)
                           ^^^^^^^^^^^^^^^^^^^^^^^^^
AttributeError: 'numpy.ndarray' object has no attribute 'width'

During handling of the above exception, another exception occurred:

Traceback (most recent call last):
  File "C:\Users\lewka\miniconda3\envs\deep_learning\Lib\tkinter\__init__.py", line 1968, in __call__
    return self.func(*args)
           ^^^^^^^^^^^^^^^^
  File "c:\Users\lewka\deep_learning\image_labelling\image_labelling\editor.py", line 1019, in on_image_select
    self.load_image(image_path)
  File "c:\Users\lewka\deep_learning\image_labelling\image_labelling\editor.py", line 1067, in load_image
    self.display_image()
  File "c:\Users\lewka\deep_learning\image_labelling\image_labelling\editor.py", line 1137, in display_image
    zoomed_img_width = int(self.original_image.width * self.zoom_level)
                           ^^^^^^^^^^^^^^^^^^^^^^^^^
AttributeError: 'numpy.ndarray' object has no attribute 'width'
2025-05-31 21:20:47,768 ERROR Exception in Tkinter callback
Traceback (most recent call last):
  File "C:\Users\lewka\miniconda3\envs\deep_learning\Lib\tkinter\__init__.py", line 1968, in __call__
    return self.func(*args)
           ^^^^^^^^^^^^^^^^
  File "C:\Users\lewka\miniconda3\envs\deep_learning\Lib\tkinter\__init__.py", line 862, in callit
    func(*args)
  File "c:\Users\lewka\deep_learning\image_labelling\image_labelling\editor.py", line 177, in _attempt_load_initial_image
    self.load_image(last_image_full_path)
  File "c:\Users\lewka\deep_learning\image_labelling\image_labelling\editor.py", line 1067, in load_image
    self.display_image()
  File "c:\Users\lewka\deep_learning\image_labelling\image_labelling\editor.py", line 1137, in display_image
    zoomed_img_width = int(self.original_image.width * self.zoom_level)
                           ^^^^^^^^^^^^^^^^^^^^^^^^^
AttributeError: 'numpy.ndarray' object has no attribute 'width'

During handling of the above exception, another exception occurred:

Traceback (most recent call last):
  File "C:\Users\lewka\miniconda3\envs\deep_learning\Lib\tkinter\__init__.py", line 1968, in __call__
    return self.func(*args)
           ^^^^^^^^^^^^^^^^
  File "c:\Users\lewka\deep_learning\image_labelling\image_labelling\editor.py", line 1019, in on_image_select
    self.load_image(image_path)
  File "c:\Users\lewka\deep_learning\image_labelling\image_labelling\editor.py", line 1067, in load_image
    self.display_image()
  File "c:\Users\lewka\deep_learning\image_labelling\image_labelling\editor.py", line 1137, in display_image
    zoomed_img_width = int(self.original_image.width * self.zoom_level)
                           ^^^^^^^^^^^^^^^^^^^^^^^^^
AttributeError: 'numpy.ndarray' object has no attribute 'width'

During handling of the above exception, another exception occurred:

Traceback (most recent call last):
  File "C:\Users\lewka\miniconda3\envs\deep_learning\Lib\tkinter\__init__.py", line 1968, in __call__
    return self.func(*args)
           ^^^^^^^^^^^^^^^^
  File "c:\Users\lewka\deep_learning\image_labelling\image_labelling\editor.py", line 603, in on_canvas_resize
    if hasattr(self, 'original_image') and self.original_image:
                                           ^^^^^^^^^^^^^^^^^^^
ValueError: The truth value of an array with more than one element is ambiguous. Use a.any() or a.all()
2025-05-31 21:23:35,419 ERROR Exception in Tkinter callback
Traceback (most recent call last):
  File "C:\Users\lewka\miniconda3\envs\deep_learning\Lib\tkinter\__init__.py", line 1968, in __call__
    return self.func(*args)
           ^^^^^^^^^^^^^^^^
  File "C:\Users\lewka\miniconda3\envs\deep_learning\Lib\tkinter\__init__.py", line 862, in callit
    func(*args)
  File "C:\Users\lewka\deep_learning\image_labelling\image_labelling\editor.py", line 177, in _attempt_load_initial_image
    self.load_image(last_image_full_path)
  File "C:\Users\lewka\deep_learning\image_labelling\image_labelling\editor.py", line 1060, in load_image
    self.image = cv2.resize(self.original_image, (self.canvas_width, self.canvas_height))
                 ^^^^^^^^^^^^^^^^^^^^^^^^^^^^^^^^^^^^^^^^^^^^^^^^^^^^^^^^^^^^^^^^^^^^^^^^
cv2.error: OpenCV(4.11.0) :-1: error: (-5:Bad argument) in function 'resize'
> Overload resolution failed:
>  - src is not a numpy array, neither a scalar
>  - Expected Ptr<cv::UMat> for argument 'src'

2025-05-31 21:23:35,433 ERROR Exception in Tkinter callback
Traceback (most recent call last):
  File "C:\Users\lewka\miniconda3\envs\deep_learning\Lib\tkinter\__init__.py", line 1968, in __call__
    return self.func(*args)
           ^^^^^^^^^^^^^^^^
  File "C:\Users\lewka\miniconda3\envs\deep_learning\Lib\tkinter\__init__.py", line 862, in callit
    func(*args)
  File "C:\Users\lewka\deep_learning\image_labelling\image_labelling\editor.py", line 177, in _attempt_load_initial_image
    self.load_image(last_image_full_path)
  File "C:\Users\lewka\deep_learning\image_labelling\image_labelling\editor.py", line 1060, in load_image
    self.image = cv2.resize(self.original_image, (self.canvas_width, self.canvas_height))
                 ^^^^^^^^^^^^^^^^^^^^^^^^^^^^^^^^^^^^^^^^^^^^^^^^^^^^^^^^^^^^^^^^^^^^^^^^
cv2.error: OpenCV(4.11.0) :-1: error: (-5:Bad argument) in function 'resize'
> Overload resolution failed:
>  - src is not a numpy array, neither a scalar
>  - Expected Ptr<cv::UMat> for argument 'src'


During handling of the above exception, another exception occurred:

Traceback (most recent call last):
  File "C:\Users\lewka\miniconda3\envs\deep_learning\Lib\tkinter\__init__.py", line 1968, in __call__
    return self.func(*args)
           ^^^^^^^^^^^^^^^^
  File "C:\Users\lewka\deep_learning\image_labelling\image_labelling\editor.py", line 1019, in on_image_select
    self.load_image(image_path)
  File "C:\Users\lewka\deep_learning\image_labelling\image_labelling\editor.py", line 1060, in load_image
    self.image = cv2.resize(self.original_image, (self.canvas_width, self.canvas_height))
                 ^^^^^^^^^^^^^^^^^^^^^^^^^^^^^^^^^^^^^^^^^^^^^^^^^^^^^^^^^^^^^^^^^^^^^^^^
cv2.error: OpenCV(4.11.0) :-1: error: (-5:Bad argument) in function 'resize'
> Overload resolution failed:
>  - src is not a numpy array, neither a scalar
>  - Expected Ptr<cv::UMat> for argument 'src'

2025-05-31 21:23:35,763 ERROR Exception in Tkinter callback
Traceback (most recent call last):
  File "C:\Users\lewka\miniconda3\envs\deep_learning\Lib\tkinter\__init__.py", line 1968, in __call__
    return self.func(*args)
           ^^^^^^^^^^^^^^^^
  File "C:\Users\lewka\miniconda3\envs\deep_learning\Lib\tkinter\__init__.py", line 862, in callit
    func(*args)
  File "C:\Users\lewka\deep_learning\image_labelling\image_labelling\editor.py", line 177, in _attempt_load_initial_image
    self.load_image(last_image_full_path)
  File "C:\Users\lewka\deep_learning\image_labelling\image_labelling\editor.py", line 1060, in load_image
    self.image = cv2.resize(self.original_image, (self.canvas_width, self.canvas_height))
                 ^^^^^^^^^^^^^^^^^^^^^^^^^^^^^^^^^^^^^^^^^^^^^^^^^^^^^^^^^^^^^^^^^^^^^^^^
cv2.error: OpenCV(4.11.0) :-1: error: (-5:Bad argument) in function 'resize'
> Overload resolution failed:
>  - src is not a numpy array, neither a scalar
>  - Expected Ptr<cv::UMat> for argument 'src'


During handling of the above exception, another exception occurred:

Traceback (most recent call last):
  File "C:\Users\lewka\miniconda3\envs\deep_learning\Lib\tkinter\__init__.py", line 1968, in __call__
    return self.func(*args)
           ^^^^^^^^^^^^^^^^
  File "C:\Users\lewka\deep_learning\image_labelling\image_labelling\editor.py", line 1019, in on_image_select
    self.load_image(image_path)
  File "C:\Users\lewka\deep_learning\image_labelling\image_labelling\editor.py", line 1060, in load_image
    self.image = cv2.resize(self.original_image, (self.canvas_width, self.canvas_height))
                 ^^^^^^^^^^^^^^^^^^^^^^^^^^^^^^^^^^^^^^^^^^^^^^^^^^^^^^^^^^^^^^^^^^^^^^^^
cv2.error: OpenCV(4.11.0) :-1: error: (-5:Bad argument) in function 'resize'
> Overload resolution failed:
>  - src is not a numpy array, neither a scalar
>  - Expected Ptr<cv::UMat> for argument 'src'


During handling of the above exception, another exception occurred:

Traceback (most recent call last):
  File "C:\Users\lewka\miniconda3\envs\deep_learning\Lib\tkinter\__init__.py", line 1968, in __call__
    return self.func(*args)
           ^^^^^^^^^^^^^^^^
  File "C:\Users\lewka\deep_learning\image_labelling\image_labelling\editor.py", line 604, in on_canvas_resize
    self.display_image()
  File "C:\Users\lewka\deep_learning\image_labelling\image_labelling\editor.py", line 1189, in display_image
    self.display_annotations() # Refresh annotations based on new view
    ^^^^^^^^^^^^^^^^^^^^^^^^^^
  File "C:\Users\lewka\deep_learning\image_labelling\image_labelling\editor.py", line 1198, in display_annotations
    for ann_idx, annotation in enumerate(self.annotations):
                                         ^^^^^^^^^^^^^^^^
AttributeError: 'BoundingBoxEditor' object has no attribute 'annotations'
2025-05-31 21:36:09,668 ERROR Exception in Tkinter callback
Traceback (most recent call last):
  File "C:\Users\lewka\miniconda3\envs\deep_learning\Lib\tkinter\__init__.py", line 1968, in __call__
    return self.func(*args)
           ^^^^^^^^^^^^^^^^
  File "C:\Users\lewka\deep_learning\image_labelling\image_labelling\editor.py", line 1378, in on_click
    self.display_annotations()
  File "C:\Users\lewka\deep_learning\image_labelling\image_labelling\editor.py", line 1214, in display_annotations
    text=self.class_names[class_id],
         ~~~~~~~~~~~~~~~~^^^^^^^^^^
TypeError: list indices must be integers or slices, not NoneType
2025-05-31 21:36:11,245 ERROR Exception in Tkinter callback
Traceback (most recent call last):
  File "C:\Users\lewka\miniconda3\envs\deep_learning\Lib\tkinter\__init__.py", line 1968, in __call__
    return self.func(*args)
           ^^^^^^^^^^^^^^^^
  File "C:\Users\lewka\deep_learning\image_labelling\image_labelling\editor.py", line 563, in on_zoom
    self.on_canvas_resize(e)
  File "C:\Users\lewka\deep_learning\image_labelling\image_labelling\editor.py", line 605, in on_canvas_resize
    self.display_image()
  File "C:\Users\lewka\deep_learning\image_labelling\image_labelling\editor.py", line 1192, in display_image
    self.display_annotations() # Refresh annotations based on new view
    ^^^^^^^^^^^^^^^^^^^^^^^^^^
  File "C:\Users\lewka\deep_learning\image_labelling\image_labelling\editor.py", line 1214, in display_annotations
    text=self.class_names[class_id],
         ~~~~~~~~~~~~~~~~^^^^^^^^^^
TypeError: list indices must be integers or slices, not NoneType
2025-05-31 21:36:12,415 ERROR Exception in Tkinter callback
Traceback (most recent call last):
  File "C:\Users\lewka\miniconda3\envs\deep_learning\Lib\tkinter\__init__.py", line 1968, in __call__
    return self.func(*args)
           ^^^^^^^^^^^^^^^^
  File "C:\Users\lewka\deep_learning\image_labelling\image_labelling\editor.py", line 563, in on_zoom
    self.on_canvas_resize(e)
  File "C:\Users\lewka\deep_learning\image_labelling\image_labelling\editor.py", line 605, in on_canvas_resize
    self.display_image()
  File "C:\Users\lewka\deep_learning\image_labelling\image_labelling\editor.py", line 1192, in display_image
    self.display_annotations() # Refresh annotations based on new view
    ^^^^^^^^^^^^^^^^^^^^^^^^^^
  File "C:\Users\lewka\deep_learning\image_labelling\image_labelling\editor.py", line 1214, in display_annotations
    text=self.class_names[class_id],
         ~~~~~~~~~~~~~~~~^^^^^^^^^^
TypeError: list indices must be integers or slices, not NoneType
2025-05-31 21:36:14,765 ERROR Exception in Tkinter callback
Traceback (most recent call last):
  File "C:\Users\lewka\miniconda3\envs\deep_learning\Lib\tkinter\__init__.py", line 1968, in __call__
    return self.func(*args)
           ^^^^^^^^^^^^^^^^
  File "C:\Users\lewka\deep_learning\image_labelling\image_labelling\editor.py", line 1020, in on_image_select
    self.load_image(image_path)
  File "C:\Users\lewka\deep_learning\image_labelling\image_labelling\editor.py", line 1070, in load_image
    self.display_image()
  File "C:\Users\lewka\deep_learning\image_labelling\image_labelling\editor.py", line 1192, in display_image
    self.display_annotations() # Refresh annotations based on new view
    ^^^^^^^^^^^^^^^^^^^^^^^^^^
  File "C:\Users\lewka\deep_learning\image_labelling\image_labelling\editor.py", line 1214, in display_annotations
    text=self.class_names[class_id],
         ~~~~~~~~~~~~~~~~^^^^^^^^^^
TypeError: list indices must be integers or slices, not NoneType
2025-05-31 21:36:15,705 ERROR Exception in Tkinter callback
Traceback (most recent call last):
  File "C:\Users\lewka\miniconda3\envs\deep_learning\Lib\tkinter\__init__.py", line 1968, in __call__
    return self.func(*args)
           ^^^^^^^^^^^^^^^^
  File "C:\Users\lewka\deep_learning\image_labelling\image_labelling\editor.py", line 1020, in on_image_select
    self.load_image(image_path)
  File "C:\Users\lewka\deep_learning\image_labelling\image_labelling\editor.py", line 1070, in load_image
    self.display_image()
  File "C:\Users\lewka\deep_learning\image_labelling\image_labelling\editor.py", line 1192, in display_image
    self.display_annotations() # Refresh annotations based on new view
    ^^^^^^^^^^^^^^^^^^^^^^^^^^
  File "C:\Users\lewka\deep_learning\image_labelling\image_labelling\editor.py", line 1214, in display_annotations
    text=self.class_names[class_id],
         ~~~~~~~~~~~~~~~~^^^^^^^^^^
TypeError: list indices must be integers or slices, not NoneType
2025-05-31 21:38:46,392 ERROR Exception in Tkinter callback
Traceback (most recent call last):
  File "C:\Users\lewka\miniconda3\envs\deep_learning\Lib\tkinter\__init__.py", line 1968, in __call__
    return self.func(*args)
           ^^^^^^^^^^^^^^^^
  File "C:\Users\lewka\deep_learning\image_labelling\image_labelling\editor.py", line 1400, in on_click
    self.display_annotations()
  File "C:\Users\lewka\deep_learning\image_labelling\image_labelling\editor.py", line 1236, in display_annotations
    text=self.class_names[class_id],
         ~~~~~~~~~~~~~~~~^^^^^^^^^^
TypeError: list indices must be integers or slices, not NoneType
2025-05-31 21:55:34,891 ERROR Exception in Tkinter callback
Traceback (most recent call last):
  File "C:\Users\lewka\miniconda3\envs\deep_learning\Lib\tkinter\__init__.py", line 1968, in __call__
    return self.func(*args)
           ^^^^^^^^^^^^^^^^
  File "c:\Users\lewka\deep_learning\image_labelling\image_labelling\editor.py", line 707, in on_right_click
    self.cancel_current_polygon()
    ^^^^^^^^^^^^^^^^^^^^^^^^^^^
AttributeError: 'BoundingBoxEditor' object has no attribute 'cancel_current_polygon'
2025-05-31 21:55:36,406 ERROR Exception in Tkinter callback
Traceback (most recent call last):
  File "C:\Users\lewka\miniconda3\envs\deep_learning\Lib\tkinter\__init__.py", line 1968, in __call__
    return self.func(*args)
           ^^^^^^^^^^^^^^^^
  File "c:\Users\lewka\deep_learning\image_labelling\image_labelling\editor.py", line 707, in on_right_click
    self.cancel_current_polygon()
    ^^^^^^^^^^^^^^^^^^^^^^^^^^^
AttributeError: 'BoundingBoxEditor' object has no attribute 'cancel_current_polygon'
2025-05-31 21:55:37,560 ERROR Exception in Tkinter callback
Traceback (most recent call last):
  File "C:\Users\lewka\miniconda3\envs\deep_learning\Lib\tkinter\__init__.py", line 1968, in __call__
    return self.func(*args)
           ^^^^^^^^^^^^^^^^
  File "c:\Users\lewka\deep_learning\image_labelling\image_labelling\editor.py", line 698, in on_escape_key
    self.cancel_current_polygon()
    ^^^^^^^^^^^^^^^^^^^^^^^^^^^
AttributeError: 'BoundingBoxEditor' object has no attribute 'cancel_current_polygon'
2025-05-31 21:57:19,059 ERROR Exception in Tkinter callback
Traceback (most recent call last):
  File "C:\Users\lewka\miniconda3\envs\deep_learning\Lib\tkinter\__init__.py", line 1968, in __call__
    return self.func(*args)
           ^^^^^^^^^^^^^^^^
  File "c:\Users\lewka\deep_learning\image_labelling\image_labelling\editor.py", line 1457, in on_click
    self.display_annotations()
  File "c:\Users\lewka\deep_learning\image_labelling\image_labelling\editor.py", line 1289, in display_annotations
    text=self.class_names[class_id],
         ~~~~~~~~~~~~~~~~^^^^^^^^^^
TypeError: list indices must be integers or slices, not NoneType
2025-05-31 22:04:44,429 ERROR Exception in Tkinter callback
Traceback (most recent call last):
  File "C:\Users\lewka\miniconda3\envs\deep_learning\Lib\tkinter\__init__.py", line 1968, in __call__
    return self.func(*args)
           ^^^^^^^^^^^^^^^^
  File "c:\Users\lewka\deep_learning\image_labelling\image_labelling\editor.py", line 1562, in on_double_click
    self.display_annotations()
  File "c:\Users\lewka\deep_learning\image_labelling\image_labelling\editor.py", line 1347, in display_annotations
    text=self.class_names[class_id],
         ~~~~~~~~~~~~~~~~^^^^^^^^^^
TypeError: list indices must be integers or slices, not NoneType
2025-05-31 22:41:56,267 ERROR Failed to create or run BoundingBoxEditor
Traceback (most recent call last):
  File "c:\Users\lewka\deep_learning\image_labelling\image_labelling\project_manager.py", line 281, in open_editor
    editor = BoundingBoxEditor(editor_root, project)
            ^^^^^^^^^^^^^^^^^^^^^^^^^^^^^^^^^^^^^^^
  File "c:\Users\lewka\deep_learning\image_labelling\image_labelling\editor.py", line 149, in __init__
    self.setup_bindings()
  File "c:\Users\lewka\deep_learning\image_labelling\image_labelling\editor.py", line 345, in setup_bindings
    self.canvas.bind("<ButtonRelease-2>", self.on_pan_end)
                                          ^^^^^^^^^^^^^^^
AttributeError: 'BoundingBoxEditor' object has no attribute 'on_pan_end'. Did you mean: 'on_pan_drag'?
2025-05-31 22:44:05,298 ERROR Exception in Tkinter callback
Traceback (most recent call last):
  File "C:\Users\lewka\miniconda3\envs\deep_learning\Lib\tkinter\__init__.py", line 1968, in __call__
    return self.func(*args)
           ^^^^^^^^^^^^^^^^
  File "c:\Users\lewka\deep_learning\image_labelling\image_labelling\editor.py", line 796, in <lambda>
    tk.Button(bbox_info_row, text="Delete", command=lambda i=i, type='bbox': self.delete_annotation(i, type), font=("Arial",8)).grid(row=1,column=1,padx=2,sticky="e")
                                                                             ^^^^^^^^^^^^^^^^^^^^^^
AttributeError: 'BoundingBoxEditor' object has no attribute 'delete_annotation'. Did you mean: 'cancel_annotation'?
2025-05-31 22:44:30,657 ERROR Exception in Tkinter callback
Traceback (most recent call last):
  File "C:\Users\lewka\miniconda3\envs\deep_learning\Lib\tkinter\__init__.py", line 1968, in __call__
    return self.func(*args)
           ^^^^^^^^^^^^^^^^
  File "c:\Users\lewka\deep_learning\image_labelling\image_labelling\editor.py", line 796, in <lambda>
    tk.Button(bbox_info_row, text="Delete", command=lambda i=i, type='bbox': self.delete_annotation(i, type), font=("Arial",8)).grid(row=1,column=1,padx=2,sticky="e")
                                                                             ^^^^^^^^^^^^^^^^^^^^^^
AttributeError: 'BoundingBoxEditor' object has no attribute 'delete_annotation'. Did you mean: 'cancel_annotation'?
2025-05-31 22:49:25,616 ERROR Exception in Tkinter callback
Traceback (most recent call last):
  File "C:\Users\lewka\miniconda3\envs\deep_learning\Lib\tkinter\__init__.py", line 1968, in __call__
    return self.func(*args)
           ^^^^^^^^^^^^^^^^
  File "c:\Users\lewka\deep_learning\image_labelling\image_labelling\editor.py", line 797, in <lambda>
    tk.Button(bbox_info_row, text="Delete", command=lambda i=i, type='bbox': self.delete_annotation(i, type), font=("Arial",8)).grid(row=1,column=1,padx=2,sticky="e")
                                                                             ^^^^^^^^^^^^^^^^^^^^^^
AttributeError: 'BoundingBoxEditor' object has no attribute 'delete_annotation'. Did you mean: 'cancel_annotation'?
2025-06-01 10:11:59,770 ERROR Failed to create or run BoundingBoxEditor
Traceback (most recent call last):
  File "c:\Users\lewka\deep_learning\image_labelling\image_labelling\project_manager.py", line 281, in open_editor
    editor = BoundingBoxEditor(editor_root, project)
            ^^^^^^^^^^^^^^^^^^^^^^^^^^^^^^^^^^^^^^^
  File "c:\Users\lewka\deep_learning\image_labelling\image_labelling\editor.py", line 91, in __init__
    self.setup_canvas()
  File "c:\Users\lewka\deep_learning\image_labelling\image_labelling\editor.py", line 232, in setup_canvas
    self.canvas.bind("<Button-1>", self.on_click)
                                   ^^^^^^^^^^^^^
AttributeError: 'BoundingBoxEditor' object has no attribute 'on_click'
2025-06-01 10:13:37,092 ERROR Failed to create or run BoundingBoxEditor
Traceback (most recent call last):
  File "C:\Users\lewka\deep_learning\image_labelling\image_labelling\project_manager.py", line 281, in open_editor
    editor = BoundingBoxEditor(editor_root, project)
            ^^^^^^^^^^^^^^^^^^^^^^^^^^^^^^^^^^^^^^^
  File "C:\Users\lewka\deep_learning\image_labelling\image_labelling\editor.py", line 91, in __init__
    self.setup_canvas()
  File "C:\Users\lewka\deep_learning\image_labelling\image_labelling\editor.py", line 232, in setup_canvas
    self.canvas.bind("<Button-1>", self.on_click)
                                   ^^^^^^^^^^^^^
AttributeError: 'BoundingBoxEditor' object has no attribute 'on_click'
2025-06-01 10:13:42,552 ERROR Failed to create or run BoundingBoxEditor
Traceback (most recent call last):
  File "C:\Users\lewka\deep_learning\image_labelling\image_labelling\project_manager.py", line 281, in open_editor
    editor = BoundingBoxEditor(editor_root, project)
            ^^^^^^^^^^^^^^^^^^^^^^^^^^^^^^^^^^^^^^^
  File "C:\Users\lewka\deep_learning\image_labelling\image_labelling\editor.py", line 91, in __init__
    self.setup_canvas()
  File "C:\Users\lewka\deep_learning\image_labelling\image_labelling\editor.py", line 232, in setup_canvas
    self.canvas.bind("<Button-1>", self.on_click)
                                   ^^^^^^^^^^^^^
AttributeError: 'BoundingBoxEditor' object has no attribute 'on_click'
v